Workbook

Sheet 🧮 TÍNH NHANH
A1: 🧮 BẢNG TÍNH NHANH — CÔNG CỤ KINH DOANH
A2: Phụ tùng động cơ diesel • Báo giá · Tính kênh giá · Phiếu VAT 8% | H2: Ngày: | I2: =TODAY() -> 46183
A3: 🧭 Nhảy tới: | C3: ① MÁY TÍNH GIÁ | E3: ② TÍNH KÊNH GIÁ | G3: ③ PHIẾU ĐẶT HÀNG VAT | I3: 🟡 Ô vàng = nhập
A5: ① MÁY TÍNH GIÁ GỢI Ý — Nhập GIÁ VỐN, tự tính 5 mức giá để báo khách (Copy → Paste vào sheet kho)
A6: Ngày: | B6: =TODAY() -> 46183 | C6: Người lập: | D6: Luân Nguyễn | E6: Khách hàng: | I6: Số phiếu:
A7: STT | B7: MÃ SP | C7: TÊN SẢN PHẨM | D7: ĐVT | E7: SL | F7: 💰 GIÁ VỐN (VNĐ) | G7: 🟢 VIP (+20%) | H7: 🟡 Ư.ĐÃI (+25%) | I7: 🔵 ĐẠI LÝ (+20%) | J7: 🟣 GARA (+25%) | K7: 🔴 BÁN LẺ (+30%)
A8: 1 | D8: Cái | E8: 1 | F8: 840000 | G8: =IFERROR(IF(F8="","",ROUND(F8*1.2*IF(E8="",1,E8),0)),"") -> 1008000 | H8: =IFERROR(IF(F8="","",ROUND(F8*1.25*IF(E8="",1,E8),0)),"") -> 1050000 | I8: =IFERROR(IF(F8="","",ROUND(F8*1.2*IF(E8="",1,E8),0)),"") -> 1008000 | J8: =IFERROR(IF(F8="","",ROUND(F8*1.25*IF(E8="",1,E8),0)),"") -> 1050000 | K8: =IFERROR(IF(F8="","",ROUND(F8*1.3*IF(E8="",1,E8),0)),"") -> 1092000
A9: 2 | G9: =IFERROR(IF(F9="","",ROUND(F9*1.2*IF(E9="",1,E9),0)),"") | H9: =IFERROR(IF(F9="","",ROUND(F9*1.25*IF(E9="",1,E9),0)),"") | I9: =IFERROR(IF(F9="","",ROUND(F9*1.2*IF(E9="",1,E9),0)),"") | J9: =IFERROR(IF(F9="","",ROUND(F9*1.25*IF(E9="",1,E9),0)),"") | K9: =IFERROR(IF(F9="","",ROUND(F9*1.3*IF(E9="",1,E9),0)),"")
A10: 3 | G10: =IFERROR(IF(F10="","",ROUND(F10*1.2*IF(E10="",1,E10),0)),"") | H10: =IFERROR(IF(F10="","",ROUND(F10*1.25*IF(E10="",1,E10),0)),"") | I10: =IFERROR(IF(F10="","",ROUND(F10*1.2*IF(E10="",1,E10),0)),"") | J10: =IFERROR(IF(F10="","",ROUND(F10*1.25*IF(E10="",1,E10),0)),"") | K10: =IFERROR(IF(F10="","",ROUND(F10*1.3*IF(E10="",1,E10),0)),"")
A11: 4 | G11: =IFERROR(IF(F11="","",ROUND(F11*1.2*IF(E11="",1,E11),0)),"") | H11: =IFERROR(IF(F11="","",ROUND(F11*1.25*IF(E11="",1,E11),0)),"") | I11: =IFERROR(IF(F11="","",ROUND(F11*1.2*IF(E11="",1,E11),0)),"") | J11: =IFERROR(IF(F11="","",ROUND(F11*1.25*IF(E11="",1,E11),0)),"") | K11: =IFERROR(IF(F11="","",ROUND(F11*1.3*IF(E11="",1,E11),0)),"")
A12: 5 | G12: =IFERROR(IF(F12="","",ROUND(F12*1.2*IF(E12="",1,E12),0)),"") | H12: =IFERROR(IF(F12="","",ROUND(F12*1.25*IF(E12="",1,E12),0)),"") | I12: =IFERROR(IF(F12="","",ROUND(F12*1.2*IF(E12="",1,E12),0)),"") | J12: =IFERROR(IF(F12="","",ROUND(F12*1.25*IF(E12="",1,E12),0)),"") | K12: =IFERROR(IF(F12="","",ROUND(F12*1.3*IF(E12="",1,E12),0)),"")
A13: TỔNG CỘNG | F13: =SUM(F8:F12) -> 840000 | G13: =SUM(G8:G12) -> 1008000 | H13: =SUM(H8:H12) -> 1050000 | I13: =SUM(I8:I12) -> 1008000 | J13: =SUM(J8:J12) -> 1050000 | K13: =SUM(K8:K12) -> 1092000
A14: 💡 Chỉ nhập GIÁ VỐN (cột F) — 5 mức giá tự nhảy. Copy số → Paste vào sheet kho (PISTON, SÉC MĂNG, ...)
A16: ② TÍNH TIỀN KÊNH GIÁ — Khi khách chuyển cao hơn giá thực (VAT 8%, công ty giữ 20%, trả khách 80%)
A17: 💡 Chỉ nhập 2 cột VÀNG: [Tiền khách chuyển] và [Tiền hàng thực xuất] — Các cột còn lại tự động tính
A18: STT | B18: KHÁCH HÀNG | C18: MÔ TẢ GIAO DỊCH | D18: NGÀY | E18: KHÁCH CHUYỂN (có VAT) | F18: HÀNG THỰC (chưa VAT) | G18: GIÁ HÀNG ÷ 1.08 | H18: VAT 8% | I18: PHẦN KÊNH | K18: TRẢ KHÁCH (80%)
A19: 1 | E19: 15000000 | F19: 10000000 | G19: =IFERROR(IF(E19="","",E19/1.08),"") -> 13888889 | H19: =IFERROR(IF(E19="","",E19-G19),"") -> 1111111.1 | I19: =IFERROR(IF(OR(E19="",F19=""),"",MAX(0,G19-F19)),"") -> 3888888.9 | K19: =IFERROR(IF(I19="","",I19*0.8),"") -> 3111111.1
A20: 2 | G20: =IFERROR(IF(E20="","",E20/1.08),"") | H20: =IFERROR(IF(E20="","",E20-G20),"") | I20: =IFERROR(IF(OR(E20="",F20=""),"",MAX(0,G20-F20)),"") | K20: =IFERROR(IF(I20="","",I20*0.8),"")
A21: 3 | G21: =IFERROR(IF(E21="","",E21/1.08),"") | H21: =IFERROR(IF(E21="","",E21-G21),"") | I21: =IFERROR(IF(OR(E21="",F21=""),"",MAX(0,G21-F21)),"") | K21: =IFERROR(IF(I21="","",I21*0.8),"")
A22: 4 | G22: =IFERROR(IF(E22="","",E22/1.08),"") | H22: =IFERROR(IF(E22="","",E22-G22),"") | I22: =IFERROR(IF(OR(E22="",F22=""),"",MAX(0,G22-F22)),"") | K22: =IFERROR(IF(I22="","",I22*0.8),"")
A23: TỔNG CỘNG 4 GIAO DỊCH | E23: =IFERROR(SUM(E19:E22),0) -> 15000000 | F23: =IFERROR(SUM(F19:F22),0) -> 10000000 | G23: =IFERROR(SUM(G19:G22),0) -> 13888889 | H23: =IFERROR(SUM(H19:H22),0) -> 1111111.1 | I23: =IFERROR(SUM(I19:I22),0) -> 3888888.9 | K23: =IFERROR(SUM(J19:J22),0) -> 0
A24: 🧾 Công thức: VAT = Tiền chuyển × 8/108 • Phần kênh = Giá chưa VAT − Giá thực • Trả khách = Phần kênh × 80%
A26: ③ PHIẾU ĐẶT HÀNG CÓ VAT 8% — Xuất hóa đơn cho khách
A27: Khách hàng: | G27: Số phiếu:
A28: Địa chỉ: | G28: Ngày: | H28: =TODAY() -> 46183
A29: STT | B29: MÃ SP | C29: TÊN SẢN PHẨM | D29: ĐVT | E29: SỐ LƯỢNG | F29: ĐƠN GIÁ (VNĐ) | G29: THÀNH TIỀN (VNĐ) | H29: VAT 8% (VNĐ) | I29: TỔNG CỘNG (VNĐ) | K29: GHI CHÚ
A30: 1 | E30: 1 | F30: 5150000 | G30: =IFERROR(E30*F30,0) -> 5150000 | H30: =IFERROR(G30*0.08,0) -> 412000 | I30: =IFERROR(G30+H30,0) -> 5562000
A31: 2 | G31: =IFERROR(E31*F31,0) -> 0 | H31: =IFERROR(G31*0.08,0) -> 0 | I31: =IFERROR(G31+H31,0) -> 0
A32: 3 | G32: =IFERROR(E32*F32,0) -> 0 | H32: =IFERROR(G32*0.08,0) -> 0 | I32: =IFERROR(G32+H32,0) -> 0
A33: 4 | G33: =IFERROR(E33*F33,0) -> 0 | H33: =IFERROR(G33*0.08,0) -> 0 | I33: =IFERROR(G33+H33,0) -> 0
A34: 5 | G34: =IFERROR(E34*F34,0) -> 0 | H34: =IFERROR(G34*0.08,0) -> 0 | I34: =IFERROR(G34+H34,0) -> 0
A35: 6 | G35: =IFERROR(E35*F35,0) -> 0 | H35: =IFERROR(G35*0.08,0) -> 0 | I35: =IFERROR(G35+H35,0) -> 0
A36: 7 | G36: =IFERROR(E36*F36,0) -> 0 | H36: =IFERROR(G36*0.08,0) -> 0 | I36: =IFERROR(G36+H36,0) -> 0
A37: 8 | G37: =IFERROR(E37*F37,0) -> 0 | H37: =IFERROR(G37*0.08,0) -> 0 | I37: =IFERROR(G37+H37,0) -> 0
A38: 9 | G38: =IFERROR(E38*F38,0) -> 0 | H38: =IFERROR(G38*0.08,0) -> 0 | I38: =IFERROR(G38+H38,0) -> 0
A39: 10 | G39: =IFERROR(E39*F39,0) -> 0 | H39: =IFERROR(G39*0.08,0) -> 0 | I39: =IFERROR(G39+H39,0) -> 0
A40: TỔNG CỘNG | G40: =SUM(G30:G39) -> 5150000 | H40: =SUM(H30:H39) -> 412000 | I40: =SUM(I30:I39) -> 5562000
A41: Tổng tiền hàng (chưa VAT): | I41: =G40 -> 5150000
A42: Tổng VAT 8%: | I42: =H40 -> 412000
A43: 💰 TỔNG THANH TOÁN: | I43: =I40 -> 5562000
...

Sheet 💰 BÁO GIÁ
B1: CÔNG TY TNHH MÁY CÔNG TRÌNH MIỀN NAM | N1: =MATCH($C$9,{"Giá vốn";"Giá VIP";"Giá ưu đãi";"Giá đại lý";"Giá gara"},0)+4 -> 6
B2: Địa chỉ: ………………… | ĐT: ………………… | MST: …………………
B4: PHIẾU BÁO GIÁ
B5: Số: | C5: BG-001 | G5: Ngày: | H5: =TODAY() -> 46183 | I5: VAT (%): | J5: 0.08
B6: Khách hàng: | G6: Điện thoại: | H6: =IFERROR(VLOOKUP($C$6,'👥 KHÁCH HÀNG'!$A:$E,2,0),"")
B7: Địa chỉ: | C7: =IFERROR(VLOOKUP($C$6,'👥 KHÁCH HÀNG'!$A:$E,3,0),"") | G7: MST: | H7: =IFERROR(VLOOKUP($C$6,'👥 KHÁCH HÀNG'!$A:$E,4,0),"")
B8: Nhà xe: | C8: =IFERROR(VLOOKUP($C$6,'👥 KHÁCH HÀNG'!$A:$I,9,0),"") | G8: Giờ nhận: | H8: =IFERROR(VLOOKUP($C$8,'🚛 NHÀ XE'!$A:$F,2,0)&" · "&VLOOKUP($C$8,'🚛 NHÀ XE'!$A:$F,3,0),"")
B9: Bảng giá áp dụng: | C9: Giá VIP
B10: STT | C10: Mã HH | D10: Tên vật tư sản phẩm | E10: ĐVT | F10: Số lượng | G10: Đơn giá (chưa VAT) | H10: Thành tiền (chưa VAT) | I10: Thuế VAT (8%) | J10: Tổng tiền (gồm VAT) | K10: 🎚️ Cấp giá
B11: 1 | D11: =IFERROR(VLOOKUP($C11,'📂 DATA'!$A:$I,2,0),"") | E11: =IFERROR(VLOOKUP($C11,'📂 DATA'!$A:$I,4,0),"") | G11: =IFERROR(VLOOKUP($C11,'📂 DATA'!$A:$J,MATCH(IF($K11="",$C$9,$K11),{"Giá vốn";"Giá VIP";"Giá ưu đãi";"Giá đại lý";"Giá gara"},0)+4,0),"") | H11: =IF($C11="","",N($F11)*N($G11)) | I11: =IF($C11="","",$H11*$J$5) | J11: =IF($C11="","",$H11+$I11)
B12: 2 | D12: =IFERROR(VLOOKUP($C12,'📂 DATA'!$A:$I,2,0),"") | E12: =IFERROR(VLOOKUP($C12,'📂 DATA'!$A:$I,4,0),"") | G12: =IFERROR(VLOOKUP($C12,'📂 DATA'!$A:$J,MATCH(IF($K12="",$C$9,$K12),{"Giá vốn";"Giá VIP";"Giá ưu đãi";"Giá đại lý";"Giá gara"},0)+4,0),"") | H12: =IF($C12="","",N($F12)*N($G12)) | I12: =IF($C12="","",$H12*$J$5) | J12: =IF($C12="","",$H12+$I12)
B13: 3 | D13: =IFERROR(VLOOKUP($C13,'📂 DATA'!$A:$I,2,0),"") | E13: =IFERROR(VLOOKUP($C13,'📂 DATA'!$A:$I,4,0),"") | G13: =IFERROR(VLOOKUP($C13,'📂 DATA'!$A:$J,MATCH(IF($K13="",$C$9,$K13),{"Giá vốn";"Giá VIP";"Giá ưu đãi";"Giá đại lý";"Giá gara"},0)+4,0),"") | H13: =IF($C13="","",N($F13)*N($G13)) | I13: =IF($C13="","",$H13*$J$5) | J13: =IF($C13="","",$H13+$I13)
B14: 4 | D14: =IFERROR(VLOOKUP($C14,'📂 DATA'!$A:$I,2,0),"") | E14: =IFERROR(VLOOKUP($C14,'📂 DATA'!$A:$I,4,0),"") | G14: =IFERROR(VLOOKUP($C14,'📂 DATA'!$A:$J,MATCH(IF($K14="",$C$9,$K14),{"Giá vốn";"Giá VIP";"Giá ưu đãi";"Giá đại lý";"Giá gara"},0)+4,0),"") | H14: =IF($C14="","",N($F14)*N($G14)) | I14: =IF($C14="","",$H14*$J$5) | J14: =IF($C14="","",$H14+$I14)
B15: 5 | D15: =IFERROR(VLOOKUP($C15,'📂 DATA'!$A:$I,2,0),"") | E15: =IFERROR(VLOOKUP($C15,'📂 DATA'!$A:$I,4,0),"") | G15: =IFERROR(VLOOKUP($C15,'📂 DATA'!$A:$J,MATCH(IF($K15="",$C$9,$K15),{"Giá vốn";"Giá VIP";"Giá ưu đãi";"Giá đại lý";"Giá gara"},0)+4,0),"") | H15: =IF($C15="","",N($F15)*N($G15)) | I15: =IF($C15="","",$H15*$J$5) | J15: =IF($C15="","",$H15+$I15)
B16: 6 | D16: =IFERROR(VLOOKUP($C16,'📂 DATA'!$A:$I,2,0),"") | E16: =IFERROR(VLOOKUP($C16,'📂 DATA'!$A:$I,4,0),"") | G16: =IFERROR(VLOOKUP($C16,'📂 DATA'!$A:$J,MATCH(IF($K16="",$C$9,$K16),{"Giá vốn";"Giá VIP";"Giá ưu đãi";"Giá đại lý";"Giá gara"},0)+4,0),"") | H16: =IF($C16="","",N($F16)*N($G16)) | I16: =IF($C16="","",$H16*$J$5) | J16: =IF($C16="","",$H16+$I16)
B17: 7 | D17: =IFERROR(VLOOKUP($C17,'📂 DATA'!$A:$I,2,0),"") | E17: =IFERROR(VLOOKUP($C17,'📂 DATA'!$A:$I,4,0),"") | G17: =IFERROR(VLOOKUP($C17,'📂 DATA'!$A:$J,MATCH(IF($K17="",$C$9,$K17),{"Giá vốn";"Giá VIP";"Giá ưu đãi";"Giá đại lý";"Giá gara"},0)+4,0),"") | H17: =IF($C17="","",N($F17)*N($G17)) | I17: =IF($C17="","",$H17*$J$5) | J17: =IF($C17="","",$H17+$I17)
B18: 8 | D18: =IFERROR(VLOOKUP($C18,'📂 DATA'!$A:$I,2,0),"") | E18: =IFERROR(VLOOKUP($C18,'📂 DATA'!$A:$I,4,0),"") | G18: =IFERROR(VLOOKUP($C18,'📂 DATA'!$A:$J,MATCH(IF($K18="",$C$9,$K18),{"Giá vốn";"Giá VIP";"Giá ưu đãi";"Giá đại lý";"Giá gara"},0)+4,0),"") | H18: =IF($C18="","",N($F18)*N($G18)) | I18: =IF($C18="","",$H18*$J$5) | J18: =IF($C18="","",$H18+$I18)
B19: Tổng cộng | F19: =SUM($F$11:$F$18) -> 0 | H19: =SUM($H$11:$H$18) -> 0 | I19: =SUM($I$11:$I$18) -> 0 | J19: =SUM($J$11:$J$18) -> 0
B20: ="Bằng chữ: "&IFERROR(IF(OR($J$19="",$J$19=0),"Không đồng./.",UPPER(LEFT(TRIM(IF(INT($J$19/1000000000)>0,VLOOKUP(INT($J$19/1000000000),_LOOKUP_VND!A:C,3,FALSE())&" tỷ ","")&IF(MOD(INT($J$19/1000000),1000)>0,IF(INT($J$19/1000000000)>0,VLOOKUP(MOD(INT($J$19/1000000),1000),_LOOKUP_VND!A:C,2,FALSE()),VLOOKUP(MOD(INT($J$19/1000000),1000),_LOOKUP_VND!A:C,3,FALSE()))&" triệu ","")&IF(MOD(INT($J$19/1000),1000)>0,IF(OR(INT($J$19/1000000000)>0,MOD(INT($J$19/1000000),1000)>0),VLOOKUP(MOD(INT($J$19/1000),1000),_LOOKUP_VND!A:C,2,FALSE()),VLOOKUP(MOD(INT($J$19/1000),1000),_LOOKUP_VND!A:C,3,FALSE()))&" nghìn ","")&IF(MOD($J$19,1000)>0,IF(OR(INT($J$19/1000000000)>0,MOD(INT($J$19/1000000),1000)>0,MOD(INT($J$19/1000),1000)>0),VLOOKUP(MOD($J$19,1000),_LOOKUP_VND!A:C,2,FALSE()),VLOOKUP(MOD($J$19,1000),_LOOKUP_VND!A:C,3,FALSE()))&" ","")),1))&MID(TRIM(IF(INT($J$19/1000000000)>0,VLOOKUP(INT($J$19/1000000000),_LOOKUP_VND!A:C,3,FALSE())&" tỷ ","")&IF(MOD(INT($J$19/1000000),1000)>0,IF(INT($J$19/1000000000)>0,VLOOKUP(MOD(INT($J$19/1000000),1000),_LOOKUP_VND!A:C,2,FALSE()),VLOOKUP(MOD(INT($J$19/1000000),1000),_LOOKUP_VND!A:C,3,FALSE()))&" triệu ","")&IF(MOD(INT($J$19/1000),1000)>0,IF(OR(INT($J$19/1000000000)>0,MOD(INT($J$19/1000000),1000)>0),VLOOKUP(MOD(INT($J$19/1000),1000),_LOOKUP_VND!A:C,2,FALSE()),VLOOKUP(MOD(INT($J$19/1000),1000),_LOOKUP_VND!A:C,3,FALSE()))&" nghìn ","")&IF(MOD($J$19,1000)>0,IF(OR(INT($J$19/1000000000)>0,MOD(INT($J$19/1000000),1000)>0,MOD(INT($J$19/1000),1000)>0),VLOOKUP(MOD($J$19,1000),_LOOKUP_VND!A:C,2,FALSE()),VLOOKUP(MOD($J$19,1000),_LOOKUP_VND!A:C,3,FALSE()))&" ","")),2,LEN(TRIM(IF(INT($J$19/1000000000)>0,VLOOKUP(INT($J$19/1000000000),_LOOKUP_VND!A:C,3,FALSE())&" tỷ ","")&IF(MOD(INT($J$19/1000000),1000)>0,IF(INT($J$19/1000000000)>0,VLOOKUP(MOD(INT($J$19/1000000),1000),_LOOKUP_VND!A:C,2,FALSE()),VLOOKUP(MOD(INT($J$19/1000000),1000),_LOOKUP_VND!A:C,3,FALSE()))&" triệu ","")&IF(MOD(INT($J$19/1000),1000)>0,IF(OR(INT($J$19/1000000000)>0,MOD(INT($J$19/1000000),1000)>0),VLOOKUP(MOD(INT($J$19/1000),1000),_LOOKUP_VND!A:C,2,FALSE()),VLOOKUP(MOD(INT($J$19/1000),1000),_LOOKUP_VND!A:C,3,FALSE()))&" nghìn ","")&IF(MOD($J$19,1000)>0,IF(OR(INT($J$19/1000000000)>0,MOD(INT($J$19/1000000),1000)>0,MOD(INT($J$19/1000),1000)>0),VLOOKUP(MOD($J$19,1000),_LOOKUP_VND!A:C,2,FALSE()),VLOOKUP(MOD($J$19,1000),_LOOKUP_VND!A:C,3,FALSE()))&" ",""))))&" đồng chẵn./."),"⚠ Lỗi đọc số") -> Bằng chữ: Không đồng./.
C22: KHÁCH HÀNG | H22: NGƯỜI BÁO GIÁ
H23: Luân Nguyễn
B26: ──────── 🔎 TÌM NHANH (không in ra) ────────
B27: 🔎 Gõ:
C28: Mã HH | D28: Tên hàng | E28: ĐVT | F28: ĐK | G28: Giá vốn | H28: Giá VIP | I28: Giá ưu đãi | J28: Giá đại lý | K28: Giá gara
C29: =IF(M29="","",INDEX('📂 DATA'!$A$2:$A$6086,M29)) | D29: =IF(M29="","",INDEX('📂 DATA'!$B$2:$B$6086,M29)) | E29: =IF(M29="","",INDEX('📂 DATA'!$D$2:$D$6086,M29)) | F29: =IF(M29="","",INDEX('📂 DATA'!$J$2:$J$6086,M29)) | G29: =IF(M29="","",INDEX('📂 DATA'!$E$2:$E$6086,M29)) | H29: =IF(M29="","",INDEX('📂 DATA'!$F$2:$F$6086,M29)) | I29: =IF(M29="","",INDEX('📂 DATA'!$G$2:$G$6086,M29)) | J29: =IF(M29="","",INDEX('📂 DATA'!$H$2:$H$6086,M29)) | K29: =IF(M29="","",INDEX('📂 DATA'!$I$2:$I$6086,M29)) | M29: =IFERROR(MATCH(1,'📂 DATA'!$O$2:$O$6086,0),"")
C30: =IF(M30="","",INDEX('📂 DATA'!$A$2:$A$6086,M30)) | D30: =IF(M30="","",INDEX('📂 DATA'!$B$2:$B$6086,M30)) | E30: =IF(M30="","",INDEX('📂 DATA'!$D$2:$D$6086,M30)) | F30: =IF(M30="","",INDEX('📂 DATA'!$J$2:$J$6086,M30)) | G30: =IF(M30="","",INDEX('📂 DATA'!$E$2:$E$6086,M30)) | H30: =IF(M30="","",INDEX('📂 DATA'!$F$2:$F$6086,M30)) | I30: =IF(M30="","",INDEX('📂 DATA'!$G$2:$G$6086,M30)) | J30: =IF(M30="","",INDEX('📂 DATA'!$H$2:$H$6086,M30)) | K30: =IF(M30="","",INDEX('📂 DATA'!$I$2:$I$6086,M30)) | M30: =IFERROR(MATCH(2,'📂 DATA'!$O$2:$O$6086,0),"")
C31: =IF(M31="","",INDEX('📂 DATA'!$A$2:$A$6086,M31)) | D31: =IF(M31="","",INDEX('📂 DATA'!$B$2:$B$6086,M31)) | E31: =IF(M31="","",INDEX('📂 DATA'!$D$2:$D$6086,M31)) | F31: =IF(M31="","",INDEX('📂 DATA'!$J$2:$J$6086,M31)) | G31: =IF(M31="","",INDEX('📂 DATA'!$E$2:$E$6086,M31)) | H31: =IF(M31="","",INDEX('📂 DATA'!$F$2:$F$6086,M31)) | I31: =IF(M31="","",INDEX('📂 DATA'!$G$2:$G$6086,M31)) | J31: =IF(M31="","",INDEX('📂 DATA'!$H$2:$H$6086,M31)) | K31: =IF(M31="","",INDEX('📂 DATA'!$I$2:$I$6086,M31)) | M31: =IFERROR(MATCH(3,'📂 DATA'!$O$2:$O$6086,0),"")
C32: =IF(M32="","",INDEX('📂 DATA'!$A$2:$A$6086,M32)) | D32: =IF(M32="","",INDEX('📂 DATA'!$B$2:$B$6086,M32)) | E32: =IF(M32="","",INDEX('📂 DATA'!$D$2:$D$6086,M32)) | F32: =IF(M32="","",INDEX('📂 DATA'!$J$2:$J$6086,M32)) | G32: =IF(M32="","",INDEX('📂 DATA'!$E$2:$E$6086,M32)) | H32: =IF(M32="","",INDEX('📂 DATA'!$F$2:$F$6086,M32)) | I32: =IF(M32="","",INDEX('📂 DATA'!$G$2:$G$6086,M32)) | J32: =IF(M32="","",INDEX('📂 DATA'!$H$2:$H$6086,M32)) | K32: =IF(M32="","",INDEX('📂 DATA'!$I$2:$I$6086,M32)) | M32: =IFERROR(MATCH(4,'📂 DATA'!$O$2:$O$6086,0),"")
C33: =IF(M33="","",INDEX('📂 DATA'!$A$2:$A$6086,M33)) | D33: =IF(M33="","",INDEX('📂 DATA'!$B$2:$B$6086,M33)) | E33: =IF(M33="","",INDEX('📂 DATA'!$D$2:$D$6086,M33)) | F33: =IF(M33="","",INDEX('📂 DATA'!$J$2:$J$6086,M33)) | G33: =IF(M33="","",INDEX('📂 DATA'!$E$2:$E$6086,M33)) | H33: =IF(M33="","",INDEX('📂 DATA'!$F$2:$F$6086,M33)) | I33: =IF(M33="","",INDEX('📂 DATA'!$G$2:$G$6086,M33)) | J33: =IF(M33="","",INDEX('📂 DATA'!$H$2:$H$6086,M33)) | K33: =IF(M33="","",INDEX('📂 DATA'!$I$2:$I$6086,M33)) | M33: =IFERROR(MATCH(5,'📂 DATA'!$O$2:$O$6086,0),"")
C34: =IF(M34="","",INDEX('📂 DATA'!$A$2:$A$6086,M34)) | D34: =IF(M34="","",INDEX('📂 DATA'!$B$2:$B$6086,M34)) | E34: =IF(M34="","",INDEX('📂 DATA'!$D$2:$D$6086,M34)) | F34: =IF(M34="","",INDEX('📂 DATA'!$J$2:$J$6086,M34)) | G34: =IF(M34="","",INDEX('📂 DATA'!$E$2:$E$6086,M34)) | H34: =IF(M34="","",INDEX('📂 DATA'!$F$2:$F$6086,M34)) | I34: =IF(M34="","",INDEX('📂 DATA'!$G$2:$G$6086,M34)) | J34: =IF(M34="","",INDEX('📂 DATA'!$H$2:$H$6086,M34)) | K34: =IF(M34="","",INDEX('📂 DATA'!$I$2:$I$6086,M34)) | M34: =IFERROR(MATCH(6,'📂 DATA'!$O$2:$O$6086,0),"")
C35: =IF(M35="","",INDEX('📂 DATA'!$A$2:$A$6086,M35)) | D35: =IF(M35="","",INDEX('📂 DATA'!$B$2:$B$6086,M35)) | E35: =IF(M35="","",INDEX('📂 DATA'!$D$2:$D$6086,M35)) | F35: =IF(M35="","",INDEX('📂 DATA'!$J$2:$J$6086,M35)) | G35: =IF(M35="","",INDEX('📂 DATA'!$E$2:$E$6086,M35)) | H35: =IF(M35="","",INDEX('📂 DATA'!$F$2:$F$6086,M35)) | I35: =IF(M35="","",INDEX('📂 DATA'!$G$2:$G$6086,M35)) | J35: =IF(M35="","",INDEX('📂 DATA'!$H$2:$H$6086,M35)) | K35: =IF(M35="","",INDEX('📂 DATA'!$I$2:$I$6086,M35)) | M35: =IFERROR(MATCH(7,'📂 DATA'!$O$2:$O$6086,0),"")
C36: =IF(M36="","",INDEX('📂 DATA'!$A$2:$A$6086,M36)) | D36: =IF(M36="","",INDEX('📂 DATA'!$B$2:$B$6086,M36)) | E36: =IF(M36="","",INDEX('📂 DATA'!$D$2:$D$6086,M36)) | F36: =IF(M36="","",INDEX('📂 DATA'!$J$2:$J$6086,M36)) | G36: =IF(M36="","",INDEX('📂 DATA'!$E$2:$E$6086,M36)) | H36: =IF(M36="","",INDEX('📂 DATA'!$F$2:$F$6086,M36)) | I36: =IF(M36="","",INDEX('📂 DATA'!$G$2:$G$6086,M36)) | J36: =IF(M36="","",INDEX('📂 DATA'!$H$2:$H$6086,M36)) | K36: =IF(M36="","",INDEX('📂 DATA'!$I$2:$I$6086,M36)) | M36: =IFERROR(MATCH(8,'📂 DATA'!$O$2:$O$6086,0),"")
C37: =IF(M37="","",INDEX('📂 DATA'!$A$2:$A$6086,M37)) | D37: =IF(M37="","",INDEX('📂 DATA'!$B$2:$B$6086,M37)) | E37: =IF(M37="","",INDEX('📂 DATA'!$D$2:$D$6086,M37)) | F37: =IF(M37="","",INDEX('📂 DATA'!$J$2:$J$6086,M37)) | G37: =IF(M37="","",INDEX('📂 DATA'!$E$2:$E$6086,M37)) | H37: =IF(M37="","",INDEX('📂 DATA'!$F$2:$F$6086,M37)) | I37: =IF(M37="","",INDEX('📂 DATA'!$G$2:$G$6086,M37)) | J37: =IF(M37="","",INDEX('📂 DATA'!$H$2:$H$6086,M37)) | K37: =IF(M37="","",INDEX('📂 DATA'!$I$2:$I$6086,M37)) | M37: =IFERROR(MATCH(9,'📂 DATA'!$O$2:$O$6086,0),"")
C38: =IF(M38="","",INDEX('📂 DATA'!$A$2:$A$6086,M38)) | D38: =IF(M38="","",INDEX('📂 DATA'!$B$2:$B$6086,M38)) | E38: =IF(M38="","",INDEX('📂 DATA'!$D$2:$D$6086,M38)) | F38: =IF(M38="","",INDEX('📂 DATA'!$J$2:$J$6086,M38)) | G38: =IF(M38="","",INDEX('📂 DATA'!$E$2:$E$6086,M38)) | H38: =IF(M38="","",INDEX('📂 DATA'!$F$2:$F$6086,M38)) | I38: =IF(M38="","",INDEX('📂 DATA'!$G$2:$G$6086,M38)) | J38: =IF(M38="","",INDEX('📂 DATA'!$H$2:$H$6086,M38)) | K38: =IF(M38="","",INDEX('📂 DATA'!$I$2:$I$6086,M38)) | M38: =IFERROR(MATCH(10,'📂 DATA'!$O$2:$O$6086,0),"")
C39: =IF(M39="","",INDEX('📂 DATA'!$A$2:$A$6086,M39)) | D39: =IF(M39="","",INDEX('📂 DATA'!$B$2:$B$6086,M39)) | E39: =IF(M39="","",INDEX('📂 DATA'!$D$2:$D$6086,M39)) | F39: =IF(M39="","",INDEX('📂 DATA'!$J$2:$J$6086,M39)) | G39: =IF(M39="","",INDEX('📂 DATA'!$E$2:$E$6086,M39)) | H39: =IF(M39="","",INDEX('📂 DATA'!$F$2:$F$6086,M39)) | I39: =IF(M39="","",INDEX('📂 DATA'!$G$2:$G$6086,M39)) | J39: =IF(M39="","",INDEX('📂 DATA'!$H$2:$H$6086,M39)) | K39: =IF(M39="","",INDEX('📂 DATA'!$I$2:$I$6086,M39)) | M39: =IFERROR(MATCH(11,'📂 DATA'!$O$2:$O$6086,0),"")
C40: =IF(M40="","",INDEX('📂 DATA'!$A$2:$A$6086,M40)) | D40: =IF(M40="","",INDEX('📂 DATA'!$B$2:$B$6086,M40)) | E40: =IF(M40="","",INDEX('📂 DATA'!$D$2:$D$6086,M40)) | F40: =IF(M40="","",INDEX('📂 DATA'!$J$2:$J$6086,M40)) | G40: =IF(M40="","",INDEX('📂 DATA'!$E$2:$E$6086,M40)) | H40: =IF(M40="","",INDEX('📂 DATA'!$F$2:$F$6086,M40)) | I40: =IF(M40="","",INDEX('📂 DATA'!$G$2:$G$6086,M40)) | J40: =IF(M40="","",INDEX('📂 DATA'!$H$2:$H$6086,M40)) | K40: =IF(M40="","",INDEX('📂 DATA'!$I$2:$I$6086,M40)) | M40: =IFERROR(MATCH(12,'📂 DATA'!$O$2:$O$6086,0),"")

Sheet ⚙️ BỘ HƠI
B1: ⚙️ GOM BỘ HƠI (Piston + Séc măng + Xy lanh)
B2: Chọn Piston → Xy lanh → Séc măng. Báo theo BỘ; SL = số máy. Cảnh báo nếu lệch đời máy / sai mạ. | H2: =IF($H$40=0,"",IFERROR(IF(INDEX('🔩 PISTON'!$C$3:$C$1143,$H$40)=0,"",INDEX('🔩 PISTON'!$C$3:$C$1143,$H$40)),""))
H3: =IF($H$40=0,"",IFERROR(IF(INDEX('🔩 PISTON'!$D$3:$D$1143,$H$40)=0,"",INDEX('🔩 PISTON'!$D$3:$D$1143,$H$40)),""))
B4: ① Chọn Piston: | E4: Mã HH: | H4: =IF($H$40=0,0,IFERROR(INDEX('🔩 PISTON'!$N$3:$N$1143,$H$40),0)) -> 0
B5: ② Chọn Xy lanh: | E5: Mã HH: | H5: =IF($H$6="kiếng","Không mạ",IF($H$6="gang","Có mạ","—")) -> —
B6: ③ Chọn Séc măng: | E6: Mã HH: | H6: =IF($H$41=0,"",IFERROR(IF(INDEX('🔧 XY LANH'!$E$3:$E$1100,$H$41)=0,"",INDEX('🔧 XY LANH'!$E$3:$E$1100,$H$41)),""))
H7: =IF($H$41=0,0,IFERROR(INDEX('🔧 XY LANH'!$N$3:$N$1100,$H$41),0)) -> 0
B8: Thành phần | C8: Mã HH | D8: Chi tiết | F8: Giá (bộ) | H8: =IF($H$42=0,0,IFERROR(INDEX('⚙️ SÉC MĂNG'!$K$3:$K$1100,$H$42),0)) -> 0
B9: 🔩 Piston | C9: =$H$34 | D9: =IF($H$40=0,"(chưa chọn)",$H$2&IF($H$21=""," "," · "&$H$21)&IF($H$11=""," "," · "&$H$11)&IF($H$12=""," "," · Ắc "&$H$12)&IF($H$13=""," "," · Ắc đỉnh "&$H$13)&IF($H$14=""," "," · Dài "&$H$14)&IF($H$33=""," "," · "&$H$33)&IF($H$15=""," "," ("&$H$15&")")) -> (chưa chọn) | F9: =$H$4 -> 0
B10: 🔧 Xy lanh | C10: =$H$35 | D10: =IF($H$41=0,IF($H$40=0,"(chưa chọn)","⚠️ Đời máy này chưa tự dò ra — chọn tay ở ② hoặc gõ Mã HH"),$H$37) -> (chưa chọn) | F10: =$H$7 -> 0 | H10: =IF($H$40=0,"",IFERROR(IF(INDEX('🔩 PISTON'!$E$3:$E$1143,$H$40)=0,"",INDEX('🔩 PISTON'!$E$3:$E$1143,$H$40)),""))
B11: ⚙️ Séc măng | C11: =$H$36 | D11: =IF($H$42=0,IF($H$40=0,"(chưa chọn)","⚠️ chưa tự dò ra — chọn tay ở ③ hoặc gõ Mã HH"),$H$26&" · "&IF($H$19=""," ",$H$19&" · ")&"Ring "&$H$18&" · "&$H$17) -> (chưa chọn) | F11: =$H$8 -> 0 | H11: =IF($H$40=0,"",IFERROR(IF(INDEX('🔩 PISTON'!$F$3:$F$1143,$H$40)=0,"",INDEX('🔩 PISTON'!$F$3:$F$1143,$H$40)),""))
B12: 📦 Đơn vị | C12: =IF($H$41=0,"(chọn xy lanh)","BỘ "&$H$20&" MÁY") -> (chọn xy lanh) | H12: =IF($H$40=0,"",IFERROR(IF(INDEX('🔩 PISTON'!$G$3:$G$1143,$H$40)=0,"",INDEX('🔩 PISTON'!$G$3:$G$1143,$H$40)),""))
B13: 💰 ĐƠN GIÁ 1 BỘ | F13: =$H$4+$H$7+$H$8 -> 0 | H13: =IF($H$40=0,"",IFERROR(IF(INDEX('🔩 PISTON'!$H$3:$H$1143,$H$40)=0,"",INDEX('🔩 PISTON'!$H$3:$H$1143,$H$40)),""))
B14: 🔢 Số lượng (bộ) | F14: 1 | H14: =IF($H$40=0,"",IFERROR(IF(INDEX('🔩 PISTON'!$I$3:$I$1143,$H$40)=0,"",INDEX('🔩 PISTON'!$I$3:$I$1143,$H$40)),""))
B15: 💵 THÀNH TIỀN | F15: =$F$13*$F$14 -> 0 | H15: =IF($H$40=0,"",IFERROR(IF(INDEX('🔩 PISTON'!$J$3:$J$1143,$H$40)=0,"",INDEX('🔩 PISTON'!$J$3:$J$1143,$H$40)),""))
B16: 📝 Bằng chữ | C16: =IFERROR(IF(OR($F$15="",$F$15=0),"Không đồng./.",UPPER(LEFT(TRIM(IF(INT($F$15/1000000000)>0,VLOOKUP(INT($F$15/1000000000),_LOOKUP_VND!A:C,3,FALSE())&" tỷ ","")&IF(MOD(INT($F$15/1000000),1000)>0,IF(INT($F$15/1000000000)>0,VLOOKUP(MOD(INT($F$15/1000000),1000),_LOOKUP_VND!A:C,2,FALSE()),VLOOKUP(MOD(INT($F$15/1000000),1000),_LOOKUP_VND!A:C,3,FALSE()))&" triệu ","")&IF(MOD(INT($F$15/1000),1000)>0,IF(OR(INT($F$15/1000000000)>0,MOD(INT($F$15/1000000),1000)>0),VLOOKUP(MOD(INT($F$15/1000),1000),_LOOKUP_VND!A:C,2,FALSE()),VLOOKUP(MOD(INT($F$15/1000),1000),_LOOKUP_VND!A:C,3,FALSE()))&" nghìn ","")&IF(MOD($F$15,1000)>0,IF(OR(INT($F$15/1000000000)>0,MOD(INT($F$15/1000000),1000)>0,MOD(INT($F$15/1000),1000)>0),VLOOKUP(MOD($F$15,1000),_LOOKUP_VND!A:C,2,FALSE()),VLOOKUP(MOD($F$15,1000),_LOOKUP_VND!A:C,3,FALSE()))&" ","")),1))&MID(TRIM(IF(INT($F$15/1000000000)>0,VLOOKUP(INT($F$15/1000000000),_LOOKUP_VND!A:C,3,FALSE())&" tỷ ","")&IF(MOD(INT($F$15/1000000),1000)>0,IF(INT($F$15/1000000000)>0,VLOOKUP(MOD(INT($F$15/1000000),1000),_LOOKUP_VND!A:C,2,FALSE()),VLOOKUP(MOD(INT($F$15/1000000),1000),_LOOKUP_VND!A:C,3,FALSE()))&" triệu ","")&IF(MOD(INT($F$15/1000),1000)>0,IF(OR(INT($F$15/1000000000)>0,MOD(INT($F$15/1000000),1000)>0),VLOOKUP(MOD(INT($F$15/1000),1000),_LOOKUP_VND!A:C,2,FALSE()),VLOOKUP(MOD(INT($F$15/1000),1000),_LOOKUP_VND!A:C,3,FALSE()))&" nghìn ","")&IF(MOD($F$15,1000)>0,IF(OR(INT($F$15/1000000000)>0,MOD(INT($F$15/1000000),1000)>0,MOD(INT($F$15/1000),1000)>0),VLOOKUP(MOD($F$15,1000),_LOOKUP_VND!A:C,2,FALSE()),VLOOKUP(MOD($F$15,1000),_LOOKUP_VND!A:C,3,FALSE()))&" ","")),2,LEN(TRIM(IF(INT($F$15/1000000000)>0,VLOOKUP(INT($F$15/1000000000),_LOOKUP_VND!A:C,3,FALSE())&" tỷ ","")&IF(MOD(INT($F$15/1000000),1000)>0,IF(INT($F$15/1000000000)>0,VLOOKUP(MOD(INT($F$15/1000000),1000),_LOOKUP_VND!A:C,2,FALSE()),VLOOKUP(MOD(INT($F$15/1000000),1000),_LOOKUP_VND!A:C,3,FALSE()))&" triệu ","")&IF(MOD(INT($F$15/1000),1000)>0,IF(OR(INT($F$15/1000000000)>0,MOD(INT($F$15/1000000),1000)>0),VLOOKUP(MOD(INT($F$15/1000),1000),_LOOKUP_VND!A:C,2,FALSE()),VLOOKUP(MOD(INT($F$15/1000),1000),_LOOKUP_VND!A:C,3,FALSE()))&" nghìn ","")&IF(MOD($F$15,1000)>0,IF(OR(INT($F$15/1000000000)>0,MOD(INT($F$15/1000000),1000)>0,MOD(INT($F$15/1000),1000)>0),VLOOKUP(MOD($F$15,1000),_LOOKUP_VND!A:C,2,FALSE()),VLOOKUP(MOD($F$15,1000),_LOOKUP_VND!A:C,3,FALSE()))&" ",""))))&" đồng chẵn./."),"⚠ Lỗi đọc số") -> Không đồng./.
H17: =IF($H$42=0,"",IFERROR(IF(INDEX('⚙️ SÉC MĂNG'!$H$3:$H$1100,$H$42)=0,"",INDEX('⚙️ SÉC MĂNG'!$H$3:$H$1100,$H$42)),""))
B18: =IF(OR($H$40=0,$H$41=0,$H$42=0),"⬆ Chọn đủ Piston + Xy lanh + Séc măng (theo tên hoặc Mã HH).",IF($H$32="SAI","⛔ XY LANH ("&$H$29&" ĐK"&$H$30&") KHÁC đời máy Piston ("&$H$2&" ĐK"&$H$3&") — KIỂM TRA LẠI!",IF($H$31="SAI","⛔ SÉC MĂNG ("&$H$26&" ĐK"&$H$27&") KHÁC đời máy Piston ("&$H$2&" ĐK"&$H$3&") — KIỂM TRA LẠI!",IF(AND($H$5<>"—",$H$5<>"",$H$19<>$H$5),"⚠️ Xy lanh "&$H$6&" nên dùng séc măng "&$H$5&" — đang chọn "&IF($H$19="","(không mạ)",$H$19)&".","✅ Đủ bộ hơi 3 món · cùng đời máy "&$H$2&IF($H$5="—"," (không phân mạ)"," · séc măng "&$H$19&" hợp xy lanh "&$H$6))))) -> ⬆ Chọn đủ Piston + Xy lanh + Séc măng (theo tên hoặc Mã HH). | H18: =IF($H$42=0,"",IFERROR(IF(INDEX('⚙️ SÉC MĂNG'!$G$3:$G$1100,$H$42)=0,"",INDEX('⚙️ SÉC MĂNG'!$G$3:$G$1100,$H$42)),""))
H19: =IF($H$42=0,"",IFERROR(IF(INDEX('⚙️ SÉC MĂNG'!$F$3:$F$1100,$H$42)=0,"",INDEX('⚙️ SÉC MĂNG'!$F$3:$F$1100,$H$42)),""))
H20: =IF($H$41=0,"",IFERROR(IF(INDEX('🔧 XY LANH'!$D$3:$D$1100,$H$41)=0,"",INDEX('🔧 XY LANH'!$D$3:$D$1100,$H$41)),""))
H21: =IF($H$40=0,"",IF($H$10="(A)+(O)","chân ko",IF($H$10="(A)","kiềng gang",$H$10)))
H26: =IF($H$42=0,"",IFERROR(IF(INDEX('⚙️ SÉC MĂNG'!$C$3:$C$1100,$H$42)=0,"",INDEX('⚙️ SÉC MĂNG'!$C$3:$C$1100,$H$42)),""))
H27: =IF($H$42=0,"",IFERROR(IF(INDEX('⚙️ SÉC MĂNG'!$D$3:$D$1100,$H$42)=0,"",INDEX('⚙️ SÉC MĂNG'!$D$3:$D$1100,$H$42)),""))
H29: =IF($H$41=0,"",IFERROR(IF(INDEX('🔧 XY LANH'!$C$3:$C$1100,$H$41)=0,"",INDEX('🔧 XY LANH'!$C$3:$C$1100,$H$41)),""))
H30: =IF($H$41=0,"",IFERROR(IF(INDEX('🔧 XY LANH'!$K$3:$K$1100,$H$41)=0,"",INDEX('🔧 XY LANH'!$K$3:$K$1100,$H$41)),""))
H31: =IF(OR($H$40=0,$H$42=0),"",IF(OR(ISNUMBER(SEARCH($H$2,$H$26)),ISNUMBER(SEARCH($H$26,$H$2))),IF(OR($H$27="",$H$3="",$H$3=$H$27),"OK","SAI"),"SAI"))
H32: =IF(OR($H$40=0,$H$41=0),"",IF(OR(ISNUMBER(SEARCH($H$2,$H$29)),ISNUMBER(SEARCH($H$29,$H$2))),IF(OR($H$30="",$H$3="",$H$3=$H$30),"OK","SAI"),"SAI"))
H33: =IF($H$40=0,"",IFERROR(IF(INDEX('🔩 PISTON'!$K$3:$K$1143,$H$40)=0,"",INDEX('🔩 PISTON'!$K$3:$K$1143,$H$40)),""))
H34: =IF($H$40=0,"",IFERROR(IF(INDEX('🔩 PISTON'!$A$3:$A$1143,$H$40)=0,"",INDEX('🔩 PISTON'!$A$3:$A$1143,$H$40)),""))
H35: =IF($H$41=0,"",IFERROR(IF(INDEX('🔧 XY LANH'!$A$3:$A$1100,$H$41)=0,"",INDEX('🔧 XY LANH'!$A$3:$A$1100,$H$41)),""))
H36: =IF($H$42=0,"",IFERROR(IF(INDEX('⚙️ SÉC MĂNG'!$A$3:$A$1100,$H$42)=0,"",INDEX('⚙️ SÉC MĂNG'!$A$3:$A$1100,$H$42)),""))
H37: =IF($H$41=0,"",IFERROR(IF(INDEX('🔧 XY LANH'!$S$3:$S$1100,$H$41)=0,"",INDEX('🔧 XY LANH'!$S$3:$S$1100,$H$41)),""))
H40: =IFERROR(IF($F$4<>"",MATCH($F$4,'🔩 PISTON'!$A$3:$A$1143,0),IF($C$4<>"",MATCH($C$4,'🔩 PISTON'!$U$3:$U$1143,0),0)),0) -> 0
H41: =IFERROR(IF($F$5<>"",MATCH($F$5,'🔧 XY LANH'!$A$3:$A$1100,0),IF($C$5<>"",MATCH($C$5,'🔧 XY LANH'!$S$3:$S$1100,0),$H$43)),0) -> 0
H42: =IFERROR(IF($F$6<>"",MATCH($F$6,'⚙️ SÉC MĂNG'!$A$3:$A$1100,0),IF($C$6<>"",MATCH($C$6,'⚙️ SÉC MĂNG'!$R$3:$R$1100,0),$H$44)),0) -> 0
H43: =IF('⚙️ BỘ HƠI'!$H$40=0,0,IF(MIN('🔧 XY LANH'!$U$3:$U$1100)=99999,0,MIN('🔧 XY LANH'!$U$3:$U$1100))) -> 0
H44: =IF('⚙️ BỘ HƠI'!$H$40=0,0,IF(MIN('⚙️ SÉC MĂNG'!$S$3:$S$1100)=99999,0,MIN('⚙️ SÉC MĂNG'!$S$3:$S$1100))) -> 0

Sheet 📦 RON BỘ
A1: STT | B1: 🔖 MÃ VT | C1: 📋 TÊN HÀNG | D1: 🏭 HÃNG | E1: 🏷️ TH SX | F1: 📦 ĐVT | G1: 💰 GIÁ VỐN | H1: 🟢 GIÁ VIP | I1: 🟡 GIÁ Ư.ĐÃI | J1: 🔵 GIÁ ĐẠI LÝ | K1: 🟣 GIÁ GARA | L1: 📦 TỒN | M1: 📝 GHI CHÚ
C2: ◆ HINO (14 sản phẩm)
A3: 1 | B3: HH076479 | C3: Ron bộ Hino DM100 - Amiang - MASAKO | D3: HINO | E3: MASAKO | F3: Bộ | H3: 630000 | I3: 670000 | J3: 720000
A4: 2 | B4: HH084235 | C4: Ron bộ Hino EC100, ASB Amiang - DF | D4: HINO | E4: DF | F4: Bộ | H4: 760000 | I4: 810000 | J4: 860000
A5: 3 | B5: HH076278 | C5: Ron bộ Hino EF750, amiang - MASAKO | D5: HINO | E5: MASAKO | F5: Bộ | H5: 1250000 | I5: 1350000 | J5: 1450000
A6: 4 | B6: HH080139 | C6: Ron bộ Hino EP100, thép - DF | D6: HINO | E6: DF | F6: Bộ | H6: 1670000 | I6: 1770000 | J6: 1900000
A7: 5 | B7: HH072734 | C7: Ron bộ Hino H06C/H07C - Amiang (cổ bô 3 lỗ) - DF | D7: HINO | E7: DF | F7: Bộ
A8: 6 | B8: HH079303 | C8: Ron bộ Hino H06C/H07C sợi tổng hợp (cổ bô 3 lỗ) - MASAKO | D8: HINO | E8: MASAKO | F8: Bộ | H8: 750000 | I8: 800000 | J8: 850000
A9: 7 | B9: HH078075 | C9: Ron bộ Hino H07D/ D6DA/ K6700, Non Asb sợi tổng hợp - DF | D9: HINO | E9: DF | F9: Bộ | H9: 810000 | I9: 860000 | J9: 920000
A10: 8 | B10: HH079048 | C10: Ron bộ Hino J05E, Thép - NICE IN | D10: HINO | E10: NICE IN | F10: Bộ | H10: 1140000 | I10: 1200000 | J10: 1300000
A11: 9 | B11: HH079662 | C11: Ron bộ Hino J07C (sợi tổng hợp) - DF | D11: HINO | E11: DF | F11: Bộ | H11: 1350000 | I11: 1450000 | J11: 1550000
A12: 10 | B12: HH082104 | C12: Ron bộ Hino J08C-T (J08E) Thép Inox - NICE IN | D12: HINO | E12: NICE IN | F12: Bộ | H12: 1450000 | I12: 1550000 | J12: 1650000
A13: 11 | B13: HH077867 | C13: Ron bộ Hino J08E/ J08C, Thép (S) - NICE IN | D13: HINO | E13: NICE IN | F13: Bộ | H13: 1500000 | I13: 1600000 | J13: 1720000
A14: 12 | B14: HH083903 | C14: Ron bộ Hino N04C thép (S) - NICE IN | D14: HINO | E14: NICE IN | F14: Bộ | H14: 650000 | I14: 680000 | J14: 730000
A15: 13 | B15: HH078290 | C15: Ron bộ Hino W04D, sợi tổng hợp - MASAKO | D15: HINO | E15: MASAKO | F15: Bộ | H15: 480000 | I15: 510000 | J15: 550000
A16: 14 | B16: HH078291 | C16: Ron bộ Hino W04E, sợi tổng hợp - MASAKO | D16: HINO | E16: MASAKO | F16: Bộ | H16: 530000 | I16: 560000 | J16: 600000
C17: ◆ ISUZU (47 sản phẩm)
A18: 15 | B18: HH072074 | C18: Ron bộ Isuzu 3KR1 / 3KR2 (Graphite) - DF | D18: ISUZU | E18: DF | F18: Bộ | H18: 670000 | I18: 720000 | J18: 770000
A19: 16 | B19: HH076547 | C19: Ron bộ Isuzu 3KR1/ 3KR2, Graphite - MASAKO | D19: ISUZU | E19: MASAKO | F19: Bộ | H19: 675000 | I19: 720000 | J19: 770000
A20: 17 | B20: HH081491 | C20: Ron bộ Isuzu 3LD1, Steel Thép - DF | D20: ISUZU | E20: DF | F20: Bộ | H20: 690000 | I20: 740000 | J20: 780000
A21: 18 | B21: HH076282 | C21: Ron bộ Isuzu 3LD1, Thép - MASAKO | D21: ISUZU | E21: MASAKO | F21: Bộ | H21: 605000 | I21: 645000 | J21: 690000
A22: 19 | B22: HH083490 | C22: Ron bộ Isuzu 3LD2, Thép - MASAKO (580.620/60) | D22: ISUZU | E22: MASAKO (580.620/60) | F22: Bộ | H22: 580000 | I22: 620000 | J22: 660000
A23: 20 | B23: HH078287 | C23: Ron bộ Isuzu 4BC2 Thép (thun cò trơn dẹt) - MASAKO | D23: ISUZU | E23: MASAKO | F23: Bộ | H23: 460000 | I23: 490000 | J23: 500000
A24: 21 | B24: HH079601 | C24: Ron bộ Isuzu 4BD1/4BB1 Amiang (thun ngạnh, p sau 100-135) - MASAKO | D24: ISUZU | E24: MASAKO | F24: Bộ | H24: 530000 | I24: 565000 | J24: 610000
A25: 22 | B25: HH075743 | C25: Ron bộ Isuzu 4BD1/4BB1 Thép (thun ngạnh, p sau 100-135) - MASAKO | D25: ISUZU | E25: MASAKO | F25: Bộ | H25: 540000 | I25: 570000 | J25: 620000
A26: 23 | B26: HH077342 | C26: Ron bộ Isuzu 4BG1 Thép - MASAKO | D26: ISUZU | E26: MASAKO | F26: Bộ | H26: 540000 | I26: 580000 | J26: 620000
A27: 24 | B27: HH079805 | C27: Ron bộ Isuzu 4BG1 Thép Inox - NICE IN | D27: ISUZU | E27: NICE IN | F27: Bộ | H27: 740000 | I27: 790000 | J27: 840000
A28: 25 | B28: HH00760 | C28: Ron bộ Isuzu 4BG1, Steel Thép - DF | D28: ISUZU | E28: DF | F28: Bộ | H28: 690000 | I28: 740000 | J28: 790000
A29: 26 | B29: HH00152 | C29: Ron bộ Isuzu 4BG1-T, phớt trà, Thép - DF | D29: ISUZU | E29: DF | F29: Bộ
A30: 27 | B30: HH084234 | C30: Ron bộ Isuzu 4FA1, Thép - DF | D30: ISUZU | E30: DF | F30: Bộ | H30: 660000 | I30: 700000 | J30: 750000
A31: 28 | B31: HH078067 | C31: Ron bộ Isuzu 4FB1/ 4FC1, Thép - DF | D31: ISUZU | E31: DF | F31: Bộ | H31: 660000 | I31: 700000 | J31: 750000
A32: 29 | B32: HH078068 | C32: Ron bộ Isuzu 4FE1, Steel Thép - DF | D32: ISUZU | E32: DF | F32: Bộ | H32: 640000 | I32: 680000 | J32: 730000
A33: 30 | B33: HH075973 | C33: Ron bộ Isuzu 4HG1 (new) thép - DF | D33: ISUZU | E33: DF | F33: Bộ | H33: 740000 | I33: 790000 | J33: 840000
A34: 31 | B34: HH075681 | C34: Ron bộ Isuzu 4HG1 (old) thép - DF | D34: ISUZU | E34: DF | F34: Bộ | H34: 740000 | I34: 790000 | J34: 840000
A35: 32 | B35: HH076830 | C35: Ron bộ Isuzu 4HK1-T (đời điện) - thép Inox - NICE IN | D35: ISUZU | E35: NICE IN | F35: Bộ | H35: 1280000 | I35: 1370000 | J35: 1460000
A36: 33 | B36: HH077494 | C36: Ron bộ Isuzu 4JB1 (catte 1 tầng), 4JA1 - Thép - DF | D36: ISUZU | E36: DF | F36: Bộ | H36: 260000 | I36: 280000 | J36: 300000
A37: 34 | B37: HH075744 | C37: Ron bộ Isuzu 4JB1- T (catte 2 tầng) thép - MASAKO | D37: ISUZU | E37: MASAKO | F37: Bộ | H37: 400000 | I37: 430000 | J37: 460000
A38: 35 | B38: HH00764 | C38: Ron bộ Isuzu 4JB1-T (catte 2 tầng) thép, 4JA1 - DF | D38: ISUZU | E38: DF | F38: Bộ | H38: 400000 | I38: 440000 | J38: 470000
A39: 36 | B39: HH076554 | C39: Ron bộ Isuzu 4JC1 (D201) Thép - MASAKO (480.510/50) | D39: ISUZU | E39: MASAKO (480.510/50) | F39: Bộ | H39: 480000 | I39: 510000 | J39: 550000
A40: 37 | B40: HH084251 | C40: Ron bộ Isuzu 4JE1, Thép - DF | D40: ISUZU | E40: DF | F40: Bộ | H40: 610000 | I40: 650000 | J40: 690000
...

Sheet 📄 RON MIẾNG
A1: STT | B1: 🔖 MÃ VT | C1: 📋 TÊN HÀNG | D1: 🏭 HÃNG | E1: 🏷️ TH SX | F1: 📦 ĐVT | G1: 💰 GIÁ VỐN | H1: 🟢 GIÁ VIP | I1: 🟡 GIÁ Ư.ĐÃI | J1: 🔵 GIÁ ĐẠI LÝ | K1: 🟣 GIÁ GARA | L1: 📦 TỒN | M1: 📝 GHI CHÚ
C2: ◆ HINO (16 sản phẩm)
A3: 1 | B3: HH076259 | C3: Ron miếng Hino DM100 - Amiang - MASAKO | D3: HINO | E3: MASAKO | F3: Cái
A4: 2 | B4: HH070916 | C4: Ron miếng Hino DM100, Amiang - NICE IN | D4: HINO | E4: NICE IN | F4: Cái | H4: 140000 | I4: 150000 | J4: 200000
A5: 3 | B5: HH084263 | C5: Ron miếng Hino EC100, ASB amiang - DF | D5: HINO | E5: DF | F5: Cái | H5: 250000 | I5: 270000 | J5: 290000
A6: 4 | B6: HH076280 | C6: Ron miếng Hino EF750/F17D/EF500, ASB amiang - MASAKO | D6: HINO | E6: MASAKO | F6: Bộ 2c | H6: 320000 | I6: 350000 | J6: 400000
A7: 5 | B7: HH078098 | C7: Ron miếng Hino EM100, Steel thép - DF | D7: HINO | E7: DF | F7: Cái | H7: 500000 | I7: 530000 | J7: 560000
A8: 6 | B8: HH076569 | C8: Ron miếng Hino H07C (H06C), Graphite, sợi - NICE IN | D8: HINO | E8: NICE IN | F8: Cái | H8: 200000 | I8: 215000 | J8: 230000
A9: 7 | B9: HH079592 | C9: Ron miếng Hino J05C-T, thép - NICE IN | D9: HINO | E9: NICE IN | F9: Cái | H9: 280000 | I9: 295000 | J9: 320000
A10: 8 | B10: HH081355 | C10: Ron miếng Hino J05E thép (S) - NICE IN | D10: HINO | E10: NICE IN | F10: Cái | H10: 290000 | I10: 310000 | J10: 340000
A11: 9 | B11: HH072088 | C11: Ron miếng Hino J05E, sợi tổng hợp, giấy - DF | D11: HINO | E11: DF | F11: Cái | H11: 300000 | I11: 350000 | J11: 400000
A12: 10 | B12: HH079677 | C12: Ron miếng Hino J07C, sợi tổng hợp - DF | D12: HINO | E12: DF | F12: Cái | H12: 310000 | I12: 350000 | J12: 400000
A13: 11 | B13: HH072089 | C13: Ron miếng Hino J08C/J08E, sợi tổng hợp, giấy - DF | D13: HINO | E13: DF | F13: Cái | H13: 330000 | I13: 380000 | J13: 430000
A14: 12 | B14: HH077878 | C14: Ron miếng Hino J08E / J08C, Thép (S) - NICE IN | D14: HINO | E14: NICE IN | F14: Cái | H14: 320000 | I14: 340000 | J14: 360000
A15: 13 | B15: HH081356 | C15: Ron miếng Hino J08E/ J08C sợi tổng hợp - NICE IN | D15: HINO | E15: NICE IN | F15: Cái | H15: 300000 | I15: 330000 | J15: 350000
... A18: 16 | B18: HH073591 | C18: Ron miếng Hino W04D, sợi tổng hợp - NICE IN | D18: HINO | E18: NICE IN | F18: Cái | H18: 150000 | I18: 170000 | J18: 200000
C19: ◆ ISUZU (42 sản phẩm)
A20: 17 | B20: HH079287 | C20: Ron miếng ISUZU 4LC1/4LB1 amiang - MASAKO | D20: ISUZU | E20: MASAKO | F20: Cái | H20: 85000 | I20: 90000 | J20: 100000
A21: 18 | B21: HH083018 | C21: Ron miếng ISUZU 4LC1/4LB1 amiang - NICE IN (90.100/20) | D21: ISUZU | E21: NICE IN (90.100/20) | F21: Cái | H21: 90000 | I21: 100000 | J21: 120000
A22: 19 | B22: HH076565 | C22: Ron miếng Isuzu 3KC1, GP - MASAKO | D22: ISUZU | E22: MASAKO | F22: Cái | H22: 140000 | I22: 150000 | J22: 170000
A23: 20 | B23: HH077322 | C23: Ron miếng Isuzu 3KC1, GP - NICE IN | D23: ISUZU | E23: NICE IN | F23: Cái | H23: 140000 | I23: 150000 | J23: 170000
A24: 21 | B24: HH081351 | C24: Ron miếng Isuzu 3KR1/3KR2, GP - NICE IN | D24: ISUZU | E24: NICE IN | F24: Cái | H24: 140000 | I24: 150000 | J24: 170000
A25: 22 | B25: HH078270 | C25: Ron miếng Isuzu 3LD1, Thép - NICE IN | D25: ISUZU | E25: NICE IN | F25: Cái | H25: 170000 | I25: 185000 | J25: 200000
A26: 23 | B26: HH083491 | C26: Ron miếng Isuzu 3LD2, Thép - NICE IN (170/90.210) | D26: ISUZU | E26: NICE IN (170/90.210) | F26: Cái | H26: 170000 | I26: 190000 | J26: 210000
A27: 24 | B27: HH079698 | C27: Ron miếng Isuzu 4BD1 Amiang (4BB1) - MASAKO | D27: ISUZU | E27: MASAKO | F27: Cái | H27: 90000 | I27: 100000 | J27: 120000
A28: 25 | B28: HH077324 | C28: Ron miếng Isuzu 4BD1, Thép Inox (4BB1) - NICE IN | D28: ISUZU | E28: NICE IN | F28: Cái | H28: 160000 | I28: 170000 | J28: 190000
A29: 26 | B29: HH075769 | C29: Ron miếng Isuzu 4BD1, Thép, 4BB1 - MASAKO | D29: ISUZU | E29: MASAKO | F29: Cái | H29: 110000 | I29: 130000 | J29: 150000
A30: 27 | B30: HH075762 | C30: Ron miếng Isuzu 4BG1/4BE1 thép (S) - MASAKO | D30: ISUZU | E30: MASAKO | F30: Cái | H30: 110000 | I30: 130000 | J30: 150000
A31: 28 | B31: HH077325 | C31: Ron miếng Isuzu 4BG1/4BE1 thép (S) - NICE IN | D31: ISUZU | E31: NICE IN | F31: Cái | H31: 160000 | I31: 170000 | J31: 180000
... A59: 56 | B59: HH076450 | C59: Ron miếng Isuzu 6WG1 (6WF1), Thép Inox - NICE IN | D59: ISUZU | E59: NICE IN | F59: Cái | H59: 1200000 | I59: 1300000 | J59: 1400000
A60: 57 | B60: HH081932 | C60: Ron miếng Isuzu DA120, Asb amiang - DF | D60: ISUZU | E60: DF | F60: Cái
A61: 58 | B61: HH00792 | C61: Ron miếng Isuzu DA120, Thép kẹp amiang - DF | D61: ISUZU | E61: DF | F61: Cái | H61: 210000 | I61: 220000 | J61: 240000
C62: ◆ MAZDA KIA (6 sản phẩm)
A63: 59 | B63: HH078094 | C63: Ron miếng Hino H07D/ Kia D6DA (sợi tổng hợp) - DF | D63: MAZDA KIA | E63: DF | F63: Cái | H63: 220000 | I63: 240000 | J63: 270000
A64: 60 | B64: HH084265 | C64: Ron miếng Kia J3/ BONGO (direct injection, đời cơ), Thép - DF | D64: MAZDA KIA | E64: DF | F64: Cái | H64: 160000 | I64: 180000 | J64: 200000
A65: 61 | B65: HH074791 | C65: Ron miếng Kia JS, Graphite - DF | D65: MAZDA KIA | E65: DF | F65: Cái | H65: 90000 | I65: 100000 | J65: 110000
A66: 62 | B66: HH084278 | C66: Ron miếng Kia K4100/ E4100 ZB, ASB amiang - DF | D66: MAZDA KIA | E66: DF | F66: Cái | H66: 90000 | I66: 100000 | J66: 120000
A67: 63 | B67: HH084266 | C67: Ron miếng Kia KJ/ J3/ Bongo (Electronic injection, đời điện), Thép - DF | D67: MAZDA KIA | E67: DF | F67: Bộ | H67: 160000 | I67: 180000 | J67: 200000
A68: 64 | B68: HH073063 | C68: Ron miếng mazda-S5/Kia25 (XA/T2500) - CGP | D68: MAZDA KIA | E68: CGP | F68: Cái
C69: ◆ KOMATSU (18 sản phẩm)
...

Sheet 📋 MIỂNG TNC
A1: 📋 MIỂNG (BẠC) — dữ liệu mới nhất
A2: Mã HH | B2: Hãng | C2: Mã ĐC | D2: ĐK | E2: Cos | F2: Loại | G2: Thương hiệu | H2: ĐVT | I2: Vốn | J2: VIP | K2: Ưu đãi | L2: Đại lý | M2: Gara | N2: Tồn | O2: PARNO | P2: Ghi chú | Q2: Tên đầy đủ
C3: ◆ HINO
A4: HH070779 | B4: HINO | C4: DM100/DQ100 | D4: 90 | E4: Cos0 | G4: TAIHO | H4: Bộ | Q4: Bạc miểng DM100/DQ100 Cos0 - TAIHO
A5: HH071938 | B5: HINO | C5: DM100/DQ100 | D5: 90 | E5: Cos1 | G5: TAIHO | H5: Bộ | Q5: Bạc miểng DM100/DQ100 Cos1 - TAIHO
A6: HH071939 | B6: HINO | C6: DM100/DQ100 | D6: 90 | E6: Cos2 | G6: TAIHO | H6: Bộ | Q6: Bạc miểng DM100/DQ100 Cos2 - TAIHO
A7: HH079058 | B7: HINO | C7: DM100/DQ100 | D7: 90 | E7: Cos3 | G7: TAIHO | H7: Bộ | Q7: Bạc miểng DM100/DQ100 Cos3 - TAIHO
A8: HH083728 | B8: HINO | C8: W04D/W04E | D8: 104 | E8: Cos0 | G8: DAIDO NHẬT | H8: Bộ | Q8: Bạc miểng Hino W04D/W04E (M133K, R133K1) STD Cos0 - DAIDO NHẬT
A9: HH00276 | B9: HINO | C9: W04D/W04E | D9: 104 | E9: Cos0 | G9: TAIHO | H9: Bộ | Q9: Bạc miểng W04D / W04E Cos0 - TAIHO
A10: HH083730 | B10: HINO | C10: W06D/W06E | D10: 104 | E10: Cos0 | G10: DAIDO NHẬT | H10: Bộ | Q10: Bạc miểng Hino W06D/W06E (M134K, R134K1) STD Cos0 - DAIDO NHẬT
A11: HH00275 | B11: HINO | C11: W04D/W04E | D11: 104 | E11: Cos1 | G11: TAIHO | H11: Bộ | Q11: Bạc miểng W04D / W04E Cos1 - TAIHO
A12: HH072136 | B12: HINO | C12: W06D/W06E | D12: 104 | E12: Cos4 | G12: TAIHO | H12: Bộ | Q12: Bạc miểng W06D/ W06E Cos4 - TAIHO
A13: HH074388 | B13: HINO | C13: DS30/DS50 | D13: 110 | E13: Cos0 | G13: NDC | H13: Bộ | Q13: Bạc miểng DS30/DS50 cos0 - NDC
A14: HH073146 | B14: HINO | C14: EH700 | D14: 110 | E14: Cos0 | G14: NDC | H14: Bộ | Q14: Bạc miểng EH700 Cos0 - NDC
A15: HH068735 | B15: HINO | C15: H06B-T/H06C/H07C | D15: 110 | E15: Cos0 | G15: NDC | H15: Bộ | Q15: Bạc miểng H06B-T/H06C/H07C Cos0 - NDC
... A17: HH071871 | B17: HINO | C17: H06C/H07C | D17: 110 | E17: Cos1 | G17: TaiHo | H17: Bộ | Q17: Bạc miểng H06C/H07C Cos1 - TaiHo
A18: HH080514 | B18: HINO | C18: H06C/H07C | D18: 110 | E18: Cos1 | F18: baze | H18: Bộ | Q18: Miểng baze H06C/H07C cos1 - TDC - M1108K
A19: HH080534 | B19: HINO | C19: H06C/H07C | D19: 110 | E19: Cos1 | F19: dên | H19: Bộ | Q19: Miểng dên H06C/H07C cos1 - TDC - R109K
A20: HH076404 | B20: HINO | C20: H06C/H07C | D20: 110 | E20: Cos2 | F20: baze | G20: TaiHo | H20: Bộ | Q20: Miểng baze H06C/H07C (M218H1) Cos2 - TaiHo
A21: HH080515 | B21: HINO | C21: H06C/H07C | D21: 110 | E21: Cos2 | F21: baze | H21: Bộ | Q21: Miểng baze H06C/H07C cos2 - TDC - M1108K
A22: HH076407 | B22: HINO | C22: H06C/H07C | D22: 110 | E22: Cos2 | F22: dên | G22: TaiHo | H22: Bộ | Q22: Miểng dên H06C/H07C (M218H1) Cos2 - TaiHo
A23: HH080535 | B23: HINO | C23: H06C/H07C | D23: 110 | E23: Cos2 | F23: dên | H23: Bộ | Q23: Miểng dên H06C/H07C cos2 - TDC - R109K
A24: HH071381 | B24: HINO | C24: H06C/H07C | D24: 110 | E24: Cos3 | G24: TaiHo | H24: Bộ | Q24: Bạc miểng H06C/H07C Cos3 - TaiHo
A25: HH081206 | B25: HINO | C25: H06C/H07C | D25: 110 | E25: Cos4 | G25: TaiHo | H25: Bộ | Q25: Bạc miểng H06C/H07C Cos4 - TaiHo
A26: HH078906 | B26: HINO | C26: J05E | D26: 112 | E26: Cos0 | G26: MAHLE | H26: Bộ | Q26: Bạc miểng J05E Cos0 - MAHLE
A27: HH076393 | B27: HINO | C27: J08C/J05C/J08E/J05E | D27: 112 | E27: Cos0 | F27: baze | G27: TAIHO | H27: Cặp | Q27: Miểng baze J08C/J05C/J08E/J05E Cos0 (MP224H) - TAIHO
A28: HH079888 | B28: HINO | C28: J08E | D28: 112 | E28: Cos0 | F28: dên | G28: CS IVECO | H28: Bộ | Q28: Miểng dên J08E (R226H) Cos0 - CS IVECO
A29: HH080548 | B29: HINO | C29: J08E/J05E | D29: 112 | E29: Cos0 | F29: dên | H29: Cặp | Q29: Miểng dên (Cặp) J08E/J05E Cos0 - TDC - RP1106K
A30: HH079886 | B30: HINO | C30: J08E/J08C | D30: 112 | E30: Cos0 | F30: baze | G30: CS IVECO | H30: Bộ | Q30: Miểng baze J08E/ J08C (M224H) Cos0 - CS IVECO
A31: HH076394 | B31: HINO | C31: J08C/J05C/J08E/J05E | D31: 112 | E31: Cos1 | F31: baze | G31: TAIHO | H31: Cặp | Q31: Miểng baze J08C/J05C/J08E/J05E Cos1 (MP224H) - TAIHO
A32: HH079889 | B32: HINO | C32: J08E | D32: 112 | E32: Cos1 | F32: dên | G32: CS IVECO | H32: Bộ | Q32: Miểng dên J08E (R226H) Cos1 - CS IVECO
A33: HH080549 | B33: HINO | C33: J08E/J05E | D33: 112 | E33: Cos1 | F33: dên | H33: Cặp | Q33: Miểng dên (Cặp) J08E/J05E Cos1 - TDC - RP1106K
A34: HH079887 | B34: HINO | C34: J08E/J08C | D34: 112 | E34: Cos1 | F34: baze | G34: CS IVECO | H34: Bộ | Q34: Miểng baze J08E/ J08C (M224H) Cos1 - CS IVECO
A35: HH076395 | B35: HINO | C35: J08C/J05C/J08E/J05E | D35: 112 | E35: Cos2 | F35: baze | G35: TAIHO | H35: Cặp | Q35: Miểng baze J08C/J05C/J08E/J05E Cos2 (MP224H) - TAIHO
A36: HH076401 | B36: HINO | C36: J08E/J05E | D36: 112 | E36: Cos2 | F36: dên | G36: TAIHO | H36: Cặp | Q36: Miểng dên J08E/J05E Cos2 (RP226H) - TAIHO
A37: HH076396 | B37: HINO | C37: J08C/J05C | D37: 114 | E37: Cos0 | F37: dên | G37: TAIHO | H37: Cặp | O37: RP224H1 | Q37: Miểng dên J08C/J05C Cos0 (RP224H1) - TAIHO
A38: HH078907 | B38: HINO | C38: J08CT/J08E | D38: 114 | E38: Cos0 | G38: MAHLE | H38: Bộ | P38: kiểm tra lại tồn | Q38: (kiểm tra lại tồn) Bạc miểng J08CT/J08E Cos0 - MAHLE
A39: HH0355 | B39: HINO | C39: J08C | D39: 114 | E39: Cos1 | G39: TAIHO | H39: Bộ | Q39: Bạc miểng J08C Cos1 - TAIHO
A40: HH076397 | B40: HINO | C40: J08C/J05C | D40: 114 | E40: Cos1 | F40: dên | G40: TAIHO | H40: Cặp | O40: RP224H1 | Q40: Miểng dên J08C/J05C Cos1 (RP224H1) - TAIHO
A41: HH070653 | B41: HINO | C41: J08CT/J08E | D41: 114 | E41: Cos1 | G41: TAIHO | H41: Bộ | Q41: Bạc miểng J08CT/J08E Cos1 - TAIHO
...

Sheet 🔍 MIỂNG TRA CỨU
A1: 🔍 MIỂNG TRA CỨU — chuyển từ v10 (điền Mã HH + giá để vào Báo giá)
A2: 🏭 Hãng | B2: ⚙️ Mã ĐC | C2: Loại | D2: Tên loại | E2: PARNO | F2: Cung trong | G2: Cung ngoài | H2: Cao | I2: Dày | J2: 📦 ĐVT | K2: 🏷️ Mã HH | L2: 🏷️ TH SX | M2: 💰 Vốn | N2: 🟢 VIP | O2: 🟡 Ưu đãi | P2: 🔵 Đại lý | Q2: 🟣 Gara | R2: 📦 Tồn
A3: CATERPILLAR | B3: 1140/1145/1150/1160/3145/3150/3160 | C3: M | D3: Miểng baze | E3: 4W8091 | G3: 94.195 | H3: 25.4 | I3: 2.604 | J3: Bộ | R3: 🟢 CÓ
A4: CATERPILLAR | B4: 1140/1145/1150/1160/3145/3150/3160 | C4: R | D4: Miểng dên | E4: 9N5923 | G4: 73.74 | H4: 24.3 | I4: 2.407 | J4: Bộ | R4: 🟢 CÓ
A5: CATERPILLAR | B5: 3013C | C5: M | D5: Miểng baze | G5: 72.02 | H5: 19.5 | I5: 2 | J5: Bộ | R5: 🟢 CÓ
A6: CATERPILLAR | B6: 3013C | C6: R | D6: Miểng dên | G6: 55.02 | H6: 19.75 | I6: 1.5 | J6: Bộ | R6: 🟢 CÓ
A7: CATERPILLAR | B7: 3024/3024T | C7: M | D7: Miểng baze | G7: 72.02 | H7: 19.5 | I7: 2 | J7: Bộ | R7: 🟢 CÓ
A8: CATERPILLAR | B8: 3114 | C8: M | D8: Miểng baze | E8: 101-1530 | G8: 95.015 | H8: 31.8 | I8: 2.44 | J8: Bộ | R8: 🟢 CÓ
A9: CATERPILLAR | B9: 3114 | C9: R | D9: Miểng dên | E9: 7W9415 | G9: 75.014 | H9: 33.8 | I9: 2.465 | J9: Bộ | R9: 🟢 CÓ
A10: CATERPILLAR | B10: 3114/3116/3126 | C10: M | D10: Miểng baze | E10: 107-7708 | G10: 95.015 | H10: 31.8 | I10: 2.44 | J10: Bộ | R10: 🟢 CÓ
A11: CATERPILLAR | B11: 3114/3116/3126 | C11: R | D11: Miểng dên | E11: 7W9415 | G11: 75.014 | H11: 33.8 | I11: 2.465 | J11: Bộ | R11: 🟢 CÓ
A12: CATERPILLAR | B12: 3116 | C12: M | D12: Miểng baze | E12: 101-1530 | G12: 95.015 | H12: 31.8 | I12: 2.44 | J12: Bộ | R12: 🟢 CÓ
A13: CATERPILLAR | B13: 3116 | C13: R | D13: Miểng dên | E13: 7W9415 | G13: 75.014 | H13: 33.8 | I13: 2.465 | J13: Bộ | R13: 🟢 CÓ
A14: CATERPILLAR | B14: 3126 | C14: M | D14: Miểng baze | E14: 107-7708 | G14: 95.015 | H14: 31.8 | I14: 2.44 | J14: Bộ | R14: 🟢 CÓ
A15: CATERPILLAR | B15: 3126 | C15: R | D15: Miểng dên | E15: 7W9415 | G15: 75.014 | H15: 33.8 | I15: 2.465 | J15: Bộ | R15: 🟢 CÓ
A16: CATERPILLAR | B16: 3145/3150/3160 | C16: M | D16: Miểng baze | E16: 4W8091 | G16: 94.195 | H16: 25.4 | I16: 2.604 | J16: Bộ | R16: 🟢 CÓ
A17: CATERPILLAR | B17: 3145/3150/3160 | C17: R | D17: Miểng dên | E17: 9N5923 | G17: 73.74 | H17: 24.3 | I17: 2.407 | J17: Bộ | R17: 🟢 CÓ
A18: CATERPILLAR | B18: 3176 | C18: M | D18: Miểng baze | E18: 7W4107 | G18: 108.014 | H18: 35.8 | I18: 3.955 | J18: Bộ | R18: 🟢 CÓ
A19: CATERPILLAR | B19: 3176 | C19: R | D19: Miểng dên | E19: 4P8167 | G19: 86.812 | H19: 43.3 | I19: 2.363 | J19: Bộ | R19: 🟢 CÓ
... A54: CATERPILLAR | B54: XN1P | C54: R | D54: Miểng dên | E54: 01-4558/4 | G54: 53.674 | H54: 23.4 | I54: 1.818 | J54: Bộ | R54: 🟢 CÓ
A55: ◆ CUMMINS (39 sản phẩm)
A56: CUMMINS | B56: 4BT/4D102/6D102/6BT | C56: M | D56: Miểng baze | E56: 3802070 | F56: 83 | G56: 88 | H56: 37.3 | I56: 2.46 | J56: Bộ | R56: 🟢 CÓ
A57: CUMMINS | B57: 4BT/4D102/6D102/6BT | C57: R | D57: Miểng dên | E57: 3901170 | F57: 69 | G57: 73 | H57: 31.1 | I57: 1.97 | J57: Bộ | R57: 🟢 CÓ
A58: CUMMINS | B58: 6CT | C58: M | D58: Miểng baze | E58: 3802210 | G58: 105 | H58: 42.85 | I58: 3.45 | J58: Bộ
A59: CUMMINS | B59: 6CT | C59: R | D59: Miểng dên | E59: 3901430 | G59: 81 | H59: 38.1 | I59: 2.47 | J59: Bộ | R59: 🟢 CÓ
A60: CUMMINS | B60: 6D107/QSB6.7/6BT NEW | C60: M | D60: Miểng baze | E60: 6736-21-8110 | G60: 88 | H60: 37.3 | I60: 2.46 | J60: Bộ | R60: 🟢 CÓ
A61: CUMMINS | B61: 6D107/QSB6.7/6BT NEW | C61: R | D61: Miểng dên | E61: 6754-31-3410 | G61: 73 | H61: 31.1 | I61: 1.97 | J61: Bộ | R61: 🟢 CÓ
A62: CUMMINS | B62: A2300 | C62: M | D62: Miểng baze | E62: 4900232 | G62: 58 | H62: 22.05 | I62: 2 | J62: Bộ | R62: 🟢 CÓ
A63: CUMMINS | B63: A2300 | C63: R | D63: Miểng dên | E63: 4900563 | G63: 53 | H63: 22.05 | I63: 1.5 | J63: Bộ | R63: 🟢 CÓ
A64: CUMMINS | B64: ISB | C64: M | D64: Miểng baze | E64: 3802070 | G64: 88 | H64: F37.300 | I64: 2.46 | J64: Bộ | R64: 🟢 CÓ
A65: CUMMINS | B65: ISB | C65: R | D65: Miểng dên | E65: 4893693 | G65: 73 | H65: 31.1 | I65: 1.97 | J65: Bộ | R65: 🟢 CÓ
A66: CUMMINS | B66: ISC | C66: M | D66: Miểng baze | E66: 3945917 | G66: 105 | H66: F42.850 | I66: 3.45 | J66: Bộ | R66: 🟢 CÓ
A67: CUMMINS | B67: ISC | C67: R | D67: Miểng dên | E67: 3950661 | G67: 81 | H67: 36 | I67: 2.47 | J67: Bộ | R67: 🟢 CÓ
A68: CUMMINS | B68: ISF | C68: M | D68: Miểng baze | E68: 4996250 | G68: 79.018 | H68: F32.24 | I68: 2.465 | J68: Bộ | R68: 🟢 CÓ
A69: CUMMINS | B69: ISF | C69: R | D69: Miểng dên | G69: 73 | H69: 31.1 | I69: 1.97 | J69: Bộ | R69: 🟢 CÓ
A70: CUMMINS | B70: ISX/QSX | C70: M | D70: Miểng baze | E70: 3800298 | G70: 133 | H70: 39.7 | I70: 3.21 | J70: Bộ | R70: 🟢 CÓ
A71: CUMMINS | B71: ISX/QSX | C71: R | D71: Miểng dên | E71: 4089405 | G71: 99 | H71: 46.7 | I71: 2.375 | J71: Bộ | R71: 🟢 CÓ
A72: CUMMINS | B72: K38，KT38，KTA38/KTAA38/KTA2300，KV12 | C72: M | D72: Miểng baze | E72: AR12250 | G72: 173.88 | H72: 52.7 | I72: 4.335 | J72: Bộ | R72: 🟢 CÓ
A73: CUMMINS | B73: K38，KT38，KTA38/KTAA38/KTA2300，KV12 | C73: R | D73: Miểng dên | E73: 3047390 | G73: 114.36 | H73: 52.7 | I73: 3.157 | J73: Bộ | R73: 🟢 CÓ
A74: CUMMINS | B74: K50，KT50，KTA50/KTAA50/KT3067，KTA3067，KV16 | C74: M | D74: Miểng baze | E74: 3018210 | G74: 173.88 | H74: 52.7 | I74: 4.335 | J74: Bộ | R74: 🟢 CÓ
...

Sheet 🔨 CĂN THAU
A1: 🔨 CĂN THAU — chuyển từ v10 (điền Mã HH + giá để vào Báo giá)
A2: 🏷️ Mã HH | B2: 🏭 Hãng | C2: ⚙️ Mã ĐC | D2: Loại | E2: PARNO | F2: Cung trong | G2: Cung ngoài | H2: Cao | I2: Dày | J2: 🏷️ TH SX | K2: 📦 ĐVT | L2: 💰 Vốn | M2: 🟢 VIP | N2: 🟡 Ưu đãi | O2: 🔵 Đại lý | P2: 🟣 Gara | Q2: 📦 Tồn | R2: 📝 Ghi chú
B3: ◆ HINO (15 Sản Phẩm)
B4: HINO | C4: 1W / W04C-T/W04D/W04D-T / W06D/W06D-T/W06E | D4: Căn dọc | E4: 11011-1240 | F4: 98.9 | G4: 82.25 | H4: 2.5 | I4: 4.0 | K4: Cái | Q4: 🟢 CÓ
B5: HINO | C5: EC100 / EH100 / EH300 / EH500/EH700/EH700-T | D5: Căn dọc | E5: 11011-1110 | F5: 98.75 | G5: 81.25 | H5: 2.5 | I5: 4.0 | K5: Cái | Q5: 🟢 CÓ
B6: HINO | C6: EF100/EF100-T/EF300/EG100 | D6: Căn dọc | E6: 11011-1030 | F6: 144.6 | G6: 117.2 | H6: 3.97 | I6: 3.0 | K6: Cái | Q6: 🟢 CÓ
B7: HINO | C7: EF100/EF100-T/EF300/EG100 / EF350/EF500/EF700/EF700-T | D7: Căn dọc | E7: 11011-1150 | F7: 144.6 | G7: 117.2 | H7: 4.47 | I7: 3.0 | K7: Cái | Q7: 🟢 CÓ
B8: HINO | C8: EF550/EF750/EF750-T / F17C/T/F17D/T/F17E/F20C | D8: Căn dọc | E8: 11011-1210 | F8: 149.6 | G8: 122.2 | H8: 4.47 | I8: 3.0 | K8: Cái | Q8: 🟢 CÓ
B9: HINO | C9: EF550/EF750/EF750-T / V21C/V22C/V25C | D9: Căn dọc | E9: 11011-1260 | F9: 149.6 | G9: 122.2 | H9: 4.47 | I9: 4.0 | K9: Cái | Q9: 🟢 CÓ
B10: HINO | C10: EK100/EK100-T/EK200/EK130-T / EK100/EK200/K13D/K13U/K130-T / K13C/K13C-T | D10: Căn dọc | E10: 11011-1011 | F10: 127.6 | G10: 102 | H10: 3.97 | I10: 3.0 | K10: Cái | Q10: 🟢 CÓ
B11: HINO | C11: EK100/EK100-T/EK200/EK130-T / K13C/K13C-T | D11: Căn dọc | E11: 11011-1250 | F11: 127.6 | G11: 102 | H11: 3.97 | I11: 4.0 | K11: Cái | Q11: 🟢 CÓ
B12: HINO | C12: EL100/EL100-T | D12: Căn dọc | E12: 11011-1180 | F12: 122.6 | G12: 102.3 | H12: 3.47 | I12: 4.0 | K12: Cái | Q12: 🟢 CÓ
B13: HINO | C13: EL100/EL100-T / EM100 / EP100-T / EP100/EP100-T/P09B-T / M10U | D13: Căn dọc | E13: 11011-1220 | F13: 124.6 | G13: 102.3 | H13: 2.97 | I13: 4.0 | K13: Cái | Q13: 🟢 CÓ
B14: HINO | C14: F21C | D14: Căn dọc | E14: 11011-1300A | F14: 150 | G14: 122.2 | H14: 4.47 | I14: 3.0 | K14: Cái | Q14: 🟢 CÓ
B15: HINO | C15: H06C/H07C/H06B-T/H06C-T / H07C/H06B-T/H06C-T/H07C-T / H07D / J05C/J05C-T1 / J07C / J08C / J08C-T1/D6DA | D15: Căn dọc | E15: 11011-1270 | F15: 104.9 | G15: 85.25 | H15: 2.5 | I15: 4.0 | K15: Cái | Q15: 🟢 CÓ
... B17: HINO | C17: V25C/V26C/V22D | D17: Căn dọc | E17: 11011-1290 | F17: 150 | G17: 122.2 | H17: 4.47 | I17: 4.0 | K17: Cái | Q17: 🟢 CÓ
B18: ◆ ISUZU (15 sản phẩm)
B19: ISUZU | C19: 3AE1/3AF1 | D19: Căn dọc | E19: 9-11581-057 | F19: 92.2 | G19: 77.8 | H19: 2.48 | I19: 2 | K19: Cái | Q19: 🟢 CÓ
B20: ISUZU | C20: 3KR1 / 3LD1/3LE1 | D20: Căn dọc | E20: 9-11599-003 | F20: 78.5 | G20: 68 | H20: 2.65 | I20: 2 | K20: Cái | Q20: 🟢 CÓ
B21: ISUZU | C21: 4BA1/4BB1/4BC1/4BC2/4BE1/4BE2 / 4BD1/4BD1-T/4BG1 | D21: Căn dọc | E21: 8-94114-565 | F21: 101 | G21: 88.25 | H21: 2.5 | I21: 4 | K21: Cái | Q21: 🟢 CÓ
B22: ISUZU | C22: 4BA1/4BB1/4BC1/4BC2/4BE1/4BE2 / 6BB1 / C330 / D500 | D22: Căn dọc | E22: 9-11585-601 | F22: 101 | G22: 84.25 | H22: 2.5 | I22: 4 | K22: Cái | Q22: 🟢 CÓ
B23: ISUZU | C23: 4BD1/4BD1-T/4BG1 / 6BB1/6BD1/6BD1-T/6BF1/6BF1-T / 6BB1/6BD1/6BF1/6BF1-T/6BG1/6BG1-T / 6BD1-T/6BF1-T | D23: Căn dọc | E23: 1-11680-001 | F23: 101 | G23: 88.25 | H23: 2.5 | I23: 4 | K23: Cái | Q23: 🟢 CÓ
B24: ISUZU | C24: 4EC1/4ECT-T / 4EE1-T | D24: Căn dọc | E24: 8-94321-611 | F24: 69.95 | G24: 59 | H24: 2.21 | I24: 2 | K24: Cái | Q24: 🟢 CÓ
B25: ISUZU | C25: 4EE1-T / 4XC1/4XC1-T/4XE1 | D25: Căn dọc | E25: 8-94321-679-0 | F25: 73.7 | G25: 59 | H25: 2.21 | I25: 2 | K25: Cái | Q25: 🟢 CÓ
B26: ISUZU | C26: 4HE1-T/4HF1/4HG1/4HJ1/4HK1 / 6HE1-T/6HK1 / 6HE1/6HH1 | D26: Căn dọc | E26: 8-94396-980 | F26: 109.75 | G26: 92.75 | H26: 3 | I26: 3 | K26: Cái | Q26: 🟢 CÓ
B27: ISUZU | C27: 4JA1/4JC1/4JD1/4JE1/4JF1/D201 / C190 / C190/C223/C223-T | D27: Căn dọc | E27: 8-94168-555 | F27: 86.95 | G27: 73.05 | H27: 2.48 | I27: 2 | K27: Cái | Q27: 🟢 CÓ
B28: ISUZU | C28: 4JB1/4JB1-T/4JG2/4JH1-T / C221/C240 | D28: Căn dọc | E28: 8-94453-520 / T4651A1 | F28: 92.95 | G28: 78.05 | H28: 2.48 | I28: 2 | K28: Cái | Q28: 🟢 CÓ
B29: ISUZU | C29: 4LE1 / 4LE2 | D29: Căn dọc | E29: 5-11599-003 | F29: 78.5 | G29: 68 | H29: 2.65 | I29: 2 | K29: Cái | Q29: 🟢 CÓ
B30: ISUZU | C30: 4XC1/4XC1-T/4XE1 | D30: Căn dọc | E30: 8-94257-903 | F30: 69.95 | G30: 55.25 | H30: 2.21 | I30: 2 | K30: Cái | Q30: 🟢 CÓ
... B32: ISUZU | C32: G130/G150/G160/G161/G161W/G180W/G180Z/G180S/G200W/G201 / G200Z/G200W | D32: Căn dọc | E32: 8-94210-750 | F32: 80.2 | G32: 63 | H32: 2.36 | I32: 2 | K32: Cái | Q32: 🟢 CÓ
B33: ◆ MITSUBISHI (30 sản phẩm)
B34: MITSUBISHI | C34: 10DC6/10DC8/10DC6/10DC60/10DC/10DC80 / 6D20/6D21/6D22/6D22A/6D22-T/6D23 / 6D24 / 8DC2/8DC20/8DC4/8DC40/8DC6/8DC60/8DC8/8DC80/8DC7/8DC70/8DC9/8DC90/8DC10/8DC11/8DC61/8DC81 | D34: Căn dọc | E34: 31209-78101 | F34: 139 | G34: 108.5 | H34: 2.95 | I34: 3 | K34: Cái | Q34: 🟢 CÓ
B35: MITSUBISHI | C35: 10DC6/10DC8/10DC6/10DC60/10DC/10DC80 / 6D20/6D21/6D22/6D22A/6D22-T/6D23 / 6DC2/6DC20 / 8DC2/8DC20/8DC4/8DC40/8DC6/8DC60/8DC8/8DC80/8DC7/8DC70/8DC9/8DC90/8DC10/8DC11/8DC61/8DC81 | D35: Căn dọc | E35: 31109-07109 | F35: 130 | G35: 108.5 | H35: 2.95 | I35: 3 | K35: Cái | Q35: 🟢 CÓ
B36: MITSUBISHI | C36: 3G81/3G82/3G83 / 4G81/4G82/4G83 | D36: Căn dọc | E36: MD115171 | F36: 56.7 | G36: 45 | H36: 2.475 | I36: 2 | K36: Cái | Q36: 🟢 CÓ
B37: MITSUBISHI | C37: 4A90/4A91 | D37: Căn dọc | E37: MN195449 | F37: 67.45 | G37: 52 | H37: 3.255 | I37: 2 | K37: Cái | Q37: 🟢 CÓ
B38: MITSUBISHI | C38: 4B10/4B11/4B11TC/4B12 | D38: Căn dọc | F38: 77 | G38: 58 | H38: 1.95 | I38: 2 | K38: Cái | Q38: 🟢 CÓ
B39: MITSUBISHI | C39: 4D30/4D31/4D31-T/4D32/4D33/4D34/4D34-T/4D35/4D36 / 6D34 | D39: Căn dọc | E39: ME013644 | F39: 110 | G39: 83 | H39: 2.45 | I39: 3 | K39: Cái | Q39: 🟢 CÓ
B40: MITSUBISHI | C40: 4D56-Ti | D40: Căn dọc | E40: MD374820 | F40: 90 | G40: 72 | H40: 2.48 | I40: 2 | K40: Cái | Q40: 🟢 CÓ
B41: MITSUBISHI | C41: 4DR5/4DR6-T/4DR7/4DR50/4DR51/4DR52 / 6DR5/6DR50/6DR51 | D41: Căn dọc | E41: 31309-08101 | F41: 95 | G41: 77.25 | H41: 2.45 | I41: 3 | K41: Cái | Q41: 🟢 CÓ
B42: MITSUBISHI | C42: 4G41/4G42/KE43/KE44/KE46 | D42: Căn dọc | E42: MD010350 | F42: 41.35 | G42: 34.3 | H42: 3.575 | I42: 2 | K42: Cái | Q42: 🟢 CÓ
...

Sheet 📚 CHÚ GIẢI
B1: 📚 CHÚ GIẢI KÝ HIỆU
B2: Ký hiệu | C2: Ý nghĩa
B3: (A) | C3: Có kiềng gang
B4: (A+0) | C4: Lỗ làm mát chân không
B5: F/F | C5: Xy lanh đã xoáy
B6: S/F | C6: Xy lanh chưa xoáy (luôn có thông số)
B7: Kiếng | C7: Xy lanh gốc hãng → séc măng KHÔNG mạ
B8: Gang | C8: Xy lanh thay thế → séc măng CÓ mạ
B9: STD | C9: Cốt 0 (zin)
B10: 0.25 | C10: Cốt 1
B11: 0.50 | C11: Cốt 2
B12: 0.75 | C12: Cốt 3
B13: 1.0 | C13: Cốt 4
B14: Mã HH | C14: Mã hàng hóa trong kho
B16: 🏷️ THƯƠNG HIỆU — XUẤT XỨ
B17: Thương hiệu | C17: Xuất xứ
B18: NPR | C18: Nhật Bản
B19: RIK (Rikken) | C19: Nhật Bản
B20: TP | C20: Nhật Bản
B21: IKAZU | C21: Trung Quốc xuất Châu Âu
B22: IZUMI | C22: Trung Quốc xuất Châu Âu
B23: HENWEIT | C23: Trung Quốc xuất Châu Âu
B24: NSP | C24: Châu Âu
B25: MAHLE | C25: Đức
B26: PROXMANN | C26: (bổ sung)

Sheet _LOOKUP_VND
A1: Số | B1: Chữ_Giữa | C1: Chữ_Đầu
A2: 0
A3: 1 | B3: không trăm lẻ một | C3: một
A4: 2 | B4: không trăm lẻ hai | C4: hai
A5: 3 | B5: không trăm lẻ ba | C5: ba
A6: 4 | B6: không trăm lẻ bốn | C6: bốn
A7: 5 | B7: không trăm lẻ năm | C7: năm
A8: 6 | B8: không trăm lẻ sáu | C8: sáu
A9: 7 | B9: không trăm lẻ bảy | C9: bảy
A10: 8 | B10: không trăm lẻ tám | C10: tám
A11: 9 | B11: không trăm lẻ chín | C11: chín
A12: 10 | B12: không trăm mười | C12: mười
A13: 11 | B13: không trăm mười một | C13: mười một
A14: 12 | B14: không trăm mười hai | C14: mười hai
... A1001: 999 | B1001: chín trăm chín mươi chín | C1001: chín trăm chín mươi chín

Sheet 🔩 PISTON
A1: 🔩 PISTON — dữ liệu thật từ v10
A2: 🏷️ Mã HH | B2: 🏭 Hãng | C2: ⚙️ Mã ĐC | D2: 📐 ĐK | E2: 🔖 Ký hiệu | F2: Buồng nổ | G2: Ắc | H2: Ắc đỉnh | I2: Tổng dài | J2: Ring 1-5 | K2: 🏷️ Thương hiệu | L2: 📦 ĐVT | M2: 💰 Vốn | N2: 🟢 VIP | O2: 🟡 Ưu đãi | P2: 🔵 Đại lý | Q2: 🟣 Gara | R2: 📦 Tồn | S2: 🔧 PARNO | T2: 📝 Ghi chú | U2: _KEY
B3: ◆ HINO (69 sản phẩm) | U3: =IF($C3="","",B3&" "&C3&" · ĐK"&D3&IF(E3=""," "," "&E3)&IF(K3=""," "," - "&K3))
A4: HH0600 | B4: HINO | C4: DM100 | D4: 90 | E4: (A) | F4: Buồng Nổ hình đầu trâu có 2 dấu supap | G4: 29x77 | H4: 38.5 | I4: 104 | J4: 2.5-2.5-2.5-4-4 | K4: IZUMI | L4: Bộ 6 | R4: 🟢 CÓ | U4: =IF($C4="","",B4&" "&C4&" · ĐK"&D4&IF(E4=""," "," "&E4)&IF(K4=""," "," - "&K4)) -> HINO DM100 · ĐK90 (A) - IZUMI
A5: HH082015 | B5: HINO | C5: DM100 | D5: 90 | E5: (A) | F5: Buồng Nổ hình đầu trâu có 2 dấu supap | G5: 29x77 | H5: 38.5 | I5: 104 | J5: 2.5-2.5-2.5-4-4 | K5: IKAZU | L5: Bộ 6 | R5: 🟢 CÓ | U5: =IF($C5="","",B5&" "&C5&" · ĐK"&D5&IF(E5=""," "," "&E5)&IF(K5=""," "," - "&K5)) -> HINO DM100 · ĐK90 (A) - IKAZU
A6: HH083874 | B6: HINO | C6: EC100 | D6: 97 | E6: 0 kiềng gang | F6: Buồng Nổ hình đầu trâu có 2 dấu supap | G6: 31.5x81.5 | H6: 42 | I6: 112 | J6: 2.5-2.5-2.5-4-4 | K6: IKAZU | L6: Bộ 6 | R6: 🟢 CÓ | U6: =IF($C6="","",B6&" "&C6&" · ĐK"&D6&IF(E6=""," "," "&E6)&IF(K6=""," "," - "&K6)) -> HINO EC100 · ĐK97 0 kiềng gang - IKAZU
A7: HH070788 | B7: HINO | C7: W04C-T/W06C-T | D7: 104 | E7: (A) | F7: Buồng Nổ tròn 57 nhọn thấp có 2 dấu supap | G7: 37x85 | H7: 44 | I7: 109 | J7: 2.8K-2.5-5 | K7: IZUMI | L7: Bộ 4 | R7: 🟢 CÓ | U7: =IF($C7="","",B7&" "&C7&" · ĐK"&D7&IF(E7=""," "," "&E7)&IF(K7=""," "," - "&K7)) -> HINO W04C-T/W06C-T · ĐK104 (A) - IZUMI
A8: HH00270 | B8: HINO | C8: W04D | D8: 104 | E8: (A) | F8: Buồng Nổ tròn 51 bằng khuyết có 2 dấu supap | G8: 35x85 | H8: 45 | I8: 108.5 | J8: 2.5-2-5 | K8: IZUMI | L8: Bộ 4 | R8: 🟢 CÓ | U8: =IF($C8="","",B8&" "&C8&" · ĐK"&D8&IF(E8=""," "," "&E8)&IF(K8=""," "," - "&K8)) -> HINO W04D · ĐK104 (A) - IZUMI
A9: HH082312 | B9: HINO | C9: W04D-T | D9: 104 | E9: (A) | F9: Buồng Nổ tròn 57 nhọn cao có 2 dấu supap | G9: 37x85 | H9: 41.5 | I9: 106 | J9: 2.8K-2-4 | K9: IKAZU | L9: Bộ 4 | R9: 🟢 CÓ | S9: 13216-E0020 | U9: =IF($C9="","",B9&" "&C9&" · ĐK"&D9&IF(E9=""," "," "&E9)&IF(K9=""," "," - "&K9)) -> HINO W04D-T · ĐK104 (A) - IKAZU
B10: HINO | C10: W04DT-NEW | D10: 104 | E10: (A) | F10: Buồng Nổ tròn 51 bằng khuyết có 2 dấu supap | G10: 37x85 | H10: 41.5 | I10: 106 | J10: 2.5-2-4 | L10: Bộ 4 | R10: 🟢 CÓ | U10: =IF($C10="","",B10&" "&C10&" · ĐK"&D10&IF(E10=""," "," "&E10)&IF(K10=""," "," - "&K10)) -> HINO W04DT-NEW · ĐK104 (A)
