Workbook

Sheet 🧮 TÍNH NHANH
A1: 🧮 BẢNG TÍNH NHANH — CÔNG CỤ KINH DOANH
A2: Phụ tùng động cơ diesel • Báo giá · Tính kênh giá · Phiếu VAT 8% | H2: Ngày: | I2: =TODAY()
A3: 🧭 Nhảy tới: | C3: ① MÁY TÍNH GIÁ | E3: ② TÍNH KÊNH GIÁ | G3: ③ PHIẾU ĐẶT HÀNG VAT | I3: 🟡 Ô vàng = nhập
A5: ① MÁY TÍNH GIÁ GỢI Ý — Nhập GIÁ VỐN, tự tính 5 mức giá để báo khách (Copy → Paste vào sheet kho)
A6: Ngày: | B6: =TODAY() | C6: Người lập: | D6: Luân Nguyễn | E6: Khách hàng: | I6: Số phiếu:
A7: STT | B7: MÃ SP | C7: TÊN SẢN PHẨM | D7: ĐVT | E7: SL | F7: 💰 GIÁ VỐN (VNĐ) | G7: 🟢 VIP (+20%) | H7: 🟡 Ư.ĐÃI (+25%) | I7: 🔵 ĐẠI LÝ (+20%) | J7: 🟣 GARA (+25%) | K7: 🔴 BÁN LẺ (+30%)
A8: 1 | D8: Cái | E8: 1 | F8: 840000 | G8: =IFERROR(IF(F8="","",ROUND(F8*1.2*IF(E8="",1,E8),0)),"") | H8: =IFERROR(IF(F8="","",ROUND(F8*1.25*IF(E8="",1,E8),0)),"") | I8: =IFERROR(IF(F8="","",ROUND(F8*1.2*IF(E8="",1,E8),0)),"") | J8: =IFERROR(IF(F8="","",ROUND(F8*1.25*IF(E8="",1,E8),0)),"") | K8: =IFERROR(IF(F8="","",ROUND(F8*1.3*IF(E8="",1,E8),0)),"")
A9: 2 | G9: =IFERROR(IF(F9="","",ROUND(F9*1.2*IF(E9="",1,E9),0)),"") | H9: =IFERROR(IF(F9="","",ROUND(F9*1.25*IF(E9="",1,E9),0)),"") | I9: =IFERROR(IF(F9="","",ROUND(F9*1.2*IF(E9="",1,E9),0)),"") | J9: =IFERROR(IF(F9="","",ROUND(F9*1.25*IF(E9="",1,E9),0)),"") | K9: =IFERROR(IF(F9="","",ROUND(F9*1.3*IF(E9="",1,E9),0)),"")
A10: 3 | G10: =IFERROR(IF(F10="","",ROUND(F10*1.2*IF(E10="",1,E10),0)),"") | H10: =IFERROR(IF(F10="","",ROUND(F10*1.25*IF(E10="",1,E10),0)),"") | I10: =IFERROR(IF(F10="","",ROUND(F10*1.2*IF(E10="",1,E10),0)),"") | J10: =IFERROR(IF(F10="","",ROUND(F10*1.25*IF(E10="",1,E10),0)),"") | K10: =IFERROR(IF(F10="","",ROUND(F10*1.3*IF(E10="",1,E10),0)),"")
A11: 4 | G11: =IFERROR(IF(F11="","",ROUND(F11*1.2*IF(E11="",1,E11),0)),"") | H11: =IFERROR(IF(F11="","",ROUND(F11*1.25*IF(E11="",1,E11),0)),"") | I11: =IFERROR(IF(F11="","",ROUND(F11*1.2*IF(E11="",1,E11),0)),"") | J11: =IFERROR(IF(F11="","",ROUND(F11*1.25*IF(E11="",1,E11),0)),"") | K11: =IFERROR(IF(F11="","",ROUND(F11*1.3*IF(E11="",1,E11),0)),"")
A12: 5 | G12: =IFERROR(IF(F12="","",ROUND(F12*1.2*IF(E12="",1,E12),0)),"") | H12: =IFERROR(IF(F12="","",ROUND(F12*1.25*IF(E12="",1,E12),0)),"") | I12: =IFERROR(IF(F12="","",ROUND(F12*1.2*IF(E12="",1,E12),0)),"") | J12: =IFERROR(IF(F12="","",ROUND(F12*1.25*IF(E12="",1,E12),0)),"") | K12: =IFERROR(IF(F12="","",ROUND(F12*1.3*IF(E12="",1,E12),0)),"")
A13: TỔNG CỘNG | F13: =SUM(F8:F12) | G13: =SUM(G8:G12) | H13: =SUM(H8:H12) | I13: =SUM(I8:I12) | J13: =SUM(J8:J12) | K13: =SUM(K8:K12)
A14: 💡 Chỉ nhập GIÁ VỐN (cột F) — 5 mức giá tự nhảy. Copy số → Paste vào sheet kho (PISTON, SÉC MĂNG, ...)
A16: ② TÍNH TIỀN KÊNH GIÁ — Khi khách chuyển cao hơn giá thực (VAT 8%, công ty giữ 20%, trả khách 80%)
A17: 💡 Chỉ nhập 2 cột VÀNG: [Tiền khách chuyển] và [Tiền hàng thực xuất] — Các cột còn lại tự động tính
A18: STT | B18: KHÁCH HÀNG | C18: MÔ TẢ GIAO DỊCH | D18: NGÀY | E18: KHÁCH CHUYỂN (có VAT) | F18: HÀNG THỰC (chưa VAT) | G18: GIÁ HÀNG ÷ 1.08 | H18: VAT 8% | I18: PHẦN KÊNH | K18: TRẢ KHÁCH (80%)
A19: 1 | E19: 15000000 | F19: 10000000 | G19: =IFERROR(IF(E19="","",E19/1.08),"") | H19: =IFERROR(IF(E19="","",E19-G19),"") | I19: =IFERROR(IF(OR(E19="",F19=""),"",MAX(0,G19-F19)),"") | K19: =IFERROR(IF(I19="","",I19*0.8),"")
A20: 2 | G20: =IFERROR(IF(E20="","",E20/1.08),"") | H20: =IFERROR(IF(E20="","",E20-G20),"") | I20: =IFERROR(IF(OR(E20="",F20=""),"",MAX(0,G20-F20)),"") | K20: =IFERROR(IF(I20="","",I20*0.8),"")
A21: 3 | G21: =IFERROR(IF(E21="","",E21/1.08),"") | H21: =IFERROR(IF(E21="","",E21-G21),"") | I21: =IFERROR(IF(OR(E21="",F21=""),"",MAX(0,G21-F21)),"") | K21: =IFERROR(IF(I21="","",I21*0.8),"")
A22: 4 | G22: =IFERROR(IF(E22="","",E22/1.08),"") | H22: =IFERROR(IF(E22="","",E22-G22),"") | I22: =IFERROR(IF(OR(E22="",F22=""),"",MAX(0,G22-F22)),"") | K22: =IFERROR(IF(I22="","",I22*0.8),"")
A23: TỔNG CỘNG 4 GIAO DỊCH | E23: =IFERROR(SUM(E19:E22),0) | F23: =IFERROR(SUM(F19:F22),0) | G23: =IFERROR(SUM(G19:G22),0) | H23: =IFERROR(SUM(H19:H22),0) | I23: =IFERROR(SUM(I19:I22),0) | K23: =IFERROR(SUM(J19:J22),0)
A24: 🧾 Công thức: VAT = Tiền chuyển × 8/108 • Phần kênh = Giá chưa VAT − Giá thực • Trả khách = Phần kênh × 80%
A26: ③ PHIẾU ĐẶT HÀNG CÓ VAT 8% — Xuất hóa đơn cho khách
A27: Khách hàng: | G27: Số phiếu:
A28: Địa chỉ: | G28: Ngày: | H28: =TODAY()
A29: STT | B29: MÃ SP | C29: TÊN SẢN PHẨM | D29: ĐVT | E29: SỐ LƯỢNG | F29: ĐƠN GIÁ (VNĐ) | G29: THÀNH TIỀN (VNĐ) | H29: VAT 8% (VNĐ) | I29: TỔNG CỘNG (VNĐ) | K29: GHI CHÚ
A30: 1 | E30: 1 | F30: 5150000 | G30: =IFERROR(E30*F30,0) | H30: =IFERROR(G30*0.08,0) | I30: =IFERROR(G30+H30,0)
A31: 2 | G31: =IFERROR(E31*F31,0) | H31: =IFERROR(G31*0.08,0) | I31: =IFERROR(G31+H31,0)
A32: 3 | G32: =IFERROR(E32*F32,0) | H32: =IFERROR(G32*0.08,0) | I32: =IFERROR(G32+H32,0)
A33: 4 | G33: =IFERROR(E33*F33,0) | H33: =IFERROR(G33*0.08,0) | I33: =IFERROR(G33+H33,0)
A34: 5 | G34: =IFERROR(E34*F34,0) | H34: =IFERROR(G34*0.08,0) | I34: =IFERROR(G34+H34,0)
A35: 6 | G35: =IFERROR(E35*F35,0) | H35: =IFERROR(G35*0.08,0) | I35: =IFERROR(G35+H35,0)
A36: 7 | G36: =IFERROR(E36*F36,0) | H36: =IFERROR(G36*0.08,0) | I36: =IFERROR(G36+H36,0)
A37: 8 | G37: =IFERROR(E37*F37,0) | H37: =IFERROR(G37*0.08,0) | I37: =IFERROR(G37+H37,0)
A38: 9 | G38: =IFERROR(E38*F38,0) | H38: =IFERROR(G38*0.08,0) | I38: =IFERROR(G38+H38,0)
A39: 10 | G39: =IFERROR(E39*F39,0) | H39: =IFERROR(G39*0.08,0) | I39: =IFERROR(G39+H39,0)
A40: TỔNG CỘNG | G40: =SUM(G30:G39) | H40: =SUM(H30:H39) | I40: =SUM(I30:I39)
A41: Tổng tiền hàng (chưa VAT): | I41: =G40
A42: Tổng VAT 8%: | I42: =H40
A43: 💰 TỔNG THANH TOÁN: | I43: =I40
...

Sheet 💰 BÁO GIÁ
B1: CÔNG TY TNHH MÁY CÔNG TRÌNH MIỀN NAM | N1: =MATCH($C$9,{"Giá vốn";"Giá VIP";"Giá ưu đãi";"Giá đại lý";"Giá gara"},0)+4
B2: Địa chỉ: ………………… | ĐT: ………………… | MST: …………………
B4: PHIẾU BÁO GIÁ
B5: Số: | C5: BG-001 | G5: Ngày: | H5: =TODAY() | I5: VAT (%): | J5: 0.08
B6: Khách hàng: | G6: Điện thoại: | H6: =IFERROR(VLOOKUP($C$6,'👥 KHÁCH HÀNG'!$A:$E,2,0),"")
B7: Địa chỉ: | C7: =IFERROR(VLOOKUP($C$6,'👥 KHÁCH HÀNG'!$A:$E,3,0),"") | G7: MST: | H7: =IFERROR(VLOOKUP($C$6,'👥 KHÁCH HÀNG'!$A:$E,4,0),"")
B8: Nhà xe: | C8: =IFERROR(VLOOKUP($C$6,'👥 KHÁCH HÀNG'!$A:$I,9,0),"") | G8: Giờ nhận: | H8: =IFERROR(VLOOKUP($C$8,'🚛 NHÀ XE'!$A:$F,2,0)&" · "&VLOOKUP($C$8,'🚛 NHÀ XE'!$A:$F,3,0),"")
B9: Bảng giá áp dụng: | C9: Giá VIP
B10: STT | C10: Mã HH | D10: Tên vật tư sản phẩm | E10: ĐVT | F10: Số lượng | G10: Đơn giá (chưa VAT) | H10: Thành tiền (chưa VAT) | I10: Thuế VAT (8%) | J10: Tổng tiền (gồm VAT) | K10: 🎚️ Cấp giá
B11: 1 | D11: =IFERROR(VLOOKUP($C11,'📂 DATA'!$A:$I,2,0),"") | E11: =IFERROR(VLOOKUP($C11,'📂 DATA'!$A:$I,4,0),"") | G11: =IFERROR(VLOOKUP($C11,'📂 DATA'!$A:$J,MATCH(IF($K11="",$C$9,$K11),{"Giá vốn";"Giá VIP";"Giá ưu đãi";"Giá đại lý";"Giá gara"},0)+4,0),"") | H11: =IF($C11="","",N($F11)*N($G11)) | I11: =IF($C11="","",$H11*$J$5) | J11: =IF($C11="","",$H11+$I11)
B12: 2 | D12: =IFERROR(VLOOKUP($C12,'📂 DATA'!$A:$I,2,0),"") | E12: =IFERROR(VLOOKUP($C12,'📂 DATA'!$A:$I,4,0),"") | G12: =IFERROR(VLOOKUP($C12,'📂 DATA'!$A:$J,MATCH(IF($K12="",$C$9,$K12),{"Giá vốn";"Giá VIP";"Giá ưu đãi";"Giá đại lý";"Giá gara"},0)+4,0),"") | H12: =IF($C12="","",N($F12)*N($G12)) | I12: =IF($C12="","",$H12*$J$5) | J12: =IF($C12="","",$H12+$I12)
B13: 3 | D13: =IFERROR(VLOOKUP($C13,'📂 DATA'!$A:$I,2,0),"") | E13: =IFERROR(VLOOKUP($C13,'📂 DATA'!$A:$I,4,0),"") | G13: =IFERROR(VLOOKUP($C13,'📂 DATA'!$A:$J,MATCH(IF($K13="",$C$9,$K13),{"Giá vốn";"Giá VIP";"Giá ưu đãi";"Giá đại lý";"Giá gara"},0)+4,0),"") | H13: =IF($C13="","",N($F13)*N($G13)) | I13: =IF($C13="","",$H13*$J$5) | J13: =IF($C13="","",$H13+$I13)
B14: 4 | D14: =IFERROR(VLOOKUP($C14,'📂 DATA'!$A:$I,2,0),"") | E14: =IFERROR(VLOOKUP($C14,'📂 DATA'!$A:$I,4,0),"") | G14: =IFERROR(VLOOKUP($C14,'📂 DATA'!$A:$J,MATCH(IF($K14="",$C$9,$K14),{"Giá vốn";"Giá VIP";"Giá ưu đãi";"Giá đại lý";"Giá gara"},0)+4,0),"") | H14: =IF($C14="","",N($F14)*N($G14)) | I14: =IF($C14="","",$H14*$J$5) | J14: =IF($C14="","",$H14+$I14)
B15: 5 | D15: =IFERROR(VLOOKUP($C15,'📂 DATA'!$A:$I,2,0),"") | E15: =IFERROR(VLOOKUP($C15,'📂 DATA'!$A:$I,4,0),"") | G15: =IFERROR(VLOOKUP($C15,'📂 DATA'!$A:$J,MATCH(IF($K15="",$C$9,$K15),{"Giá vốn";"Giá VIP";"Giá ưu đãi";"Giá đại lý";"Giá gara"},0)+4,0),"") | H15: =IF($C15="","",N($F15)*N($G15)) | I15: =IF($C15="","",$H15*$J$5) | J15: =IF($C15="","",$H15+$I15)
B16: 6 | D16: =IFERROR(VLOOKUP($C16,'📂 DATA'!$A:$I,2,0),"") | E16: =IFERROR(VLOOKUP($C16,'📂 DATA'!$A:$I,4,0),"") | G16: =IFERROR(VLOOKUP($C16,'📂 DATA'!$A:$J,MATCH(IF($K16="",$C$9,$K16),{"Giá vốn";"Giá VIP";"Giá ưu đãi";"Giá đại lý";"Giá gara"},0)+4,0),"") | H16: =IF($C16="","",N($F16)*N($G16)) | I16: =IF($C16="","",$H16*$J$5) | J16: =IF($C16="","",$H16+$I16)
B17: 7 | D17: =IFERROR(VLOOKUP($C17,'📂 DATA'!$A:$I,2,0),"") | E17: =IFERROR(VLOOKUP($C17,'📂 DATA'!$A:$I,4,0),"") | G17: =IFERROR(VLOOKUP($C17,'📂 DATA'!$A:$J,MATCH(IF($K17="",$C$9,$K17),{"Giá vốn";"Giá VIP";"Giá ưu đãi";"Giá đại lý";"Giá gara"},0)+4,0),"") | H17: =IF($C17="","",N($F17)*N($G17)) | I17: =IF($C17="","",$H17*$J$5) | J17: =IF($C17="","",$H17+$I17)
B18: 8 | D18: =IFERROR(VLOOKUP($C18,'📂 DATA'!$A:$I,2,0),"") | E18: =IFERROR(VLOOKUP($C18,'📂 DATA'!$A:$I,4,0),"") | G18: =IFERROR(VLOOKUP($C18,'📂 DATA'!$A:$J,MATCH(IF($K18="",$C$9,$K18),{"Giá vốn";"Giá VIP";"Giá ưu đãi";"Giá đại lý";"Giá gara"},0)+4,0),"") | H18: =IF($C18="","",N($F18)*N($G18)) | I18: =IF($C18="","",$H18*$J$5) | J18: =IF($C18="","",$H18+$I18)
B19: Tổng cộng | F19: =SUM($F$11:$F$18) | H19: =SUM($H$11:$H$18) | I19: =SUM($I$11:$I$18) | J19: =SUM($J$11:$J$18)
B20: ="Bằng chữ: "&IFERROR(IF(OR($J$19="",$J$19=0),"Không đồng./.",UPPER(LEFT(TRIM(IF(INT($J$19/1000000000)>0,VLOOKUP(INT($J$19/1000000000),_LOOKUP_VND!A:C,3,FALSE())&" tỷ ","")&IF(MOD(INT($J$19/1000000),1000)>0,IF(INT($J$19/1000000000)>0,VLOOKUP(MOD(INT($J$19/1000000),1000),_LOOKUP_VND!A:C,2,FALSE()),VLOOKUP(MOD(INT($J$19/1000000),1000),_LOOKUP_VND!A:C,3,FALSE()))&" triệu ","")&IF(MOD(INT($J$19/1000),1000)>0,IF(OR(INT($J$19/1000000000)>0,MOD(INT($J$19/1000000),1000)>0),VLOOKUP(MOD(INT($J$19/1000),1000),_LOOKUP_VND!A:C,2,FALSE()),VLOOKUP(MOD(INT($J$19/1000),1000),_LOOKUP_VND!A:C,3,FALSE()))&" nghìn ","")&IF(MOD($J$19,1000)>0,IF(OR(INT($J$19/1000000000)>0,MOD(INT($J$19/1000000),1000)>0,MOD(INT($J$19/1000),1000)>0),VLOOKUP(MOD($J$19,1000),_LOOKUP_VND!A:C,2,FALSE()),VLOOKUP(MOD($J$19,1000),_LOOKUP_VND!A:C,3,FALSE()))&" ","")),1))&MID(TRIM(IF(INT($J$19/1000000000)>0,VLOOKUP(INT($J$19/1000000000),_LOOKUP_VND!A:C,3,FALSE())&" tỷ ","")&IF(MOD(INT($J$19/1000000),1000)>0,IF(INT($J$19/1000000000)>0,VLOOKUP(MOD(INT($J$19/1000000),1000),_LOOKUP_VND!A:C,2,FALSE()),VLOOKUP(MOD(INT($J$19/1000000),1000),_LOOKUP_VND!A:C,3,FALSE()))&" triệu ","")&IF(MOD(INT($J$19/1000),1000)>0,IF(OR(INT($J$19/1000000000)>0,MOD(INT($J$19/1000000),1000)>0),VLOOKUP(MOD(INT($J$19/1000),1000),_LOOKUP_VND!A:C,2,FALSE()),VLOOKUP(MOD(INT($J$19/1000),1000),_LOOKUP_VND!A:C,3,FALSE()))&" nghìn ","")&IF(MOD($J$19,1000)>0,IF(OR(INT($J$19/1000000000)>0,MOD(INT($J$19/1000000),1000)>0,MOD(INT($J$19/1000),1000)>0),VLOOKUP(MOD($J$19,1000),_LOOKUP_VND!A:C,2,FALSE()),VLOOKUP(MOD($J$19,1000),_LOOKUP_VND!A:C,3,FALSE()))&" ","")),2,LEN(TRIM(IF(INT($J$19/1000000000)>0,VLOOKUP(INT($J$19/1000000000),_LOOKUP_VND!A:C,3,FALSE())&" tỷ ","")&IF(MOD(INT($J$19/1000000),1000)>0,IF(INT($J$19/1000000000)>0,VLOOKUP(MOD(INT($J$19/1000000),1000),_LOOKUP_VND!A:C,2,FALSE()),VLOOKUP(MOD(INT($J$19/1000000),1000),_LOOKUP_VND!A:C,3,FALSE()))&" triệu ","")&IF(MOD(INT($J$19/1000),1000)>0,IF(OR(INT($J$19/1000000000)>0,MOD(INT($J$19/1000000),1000)>0),VLOOKUP(MOD(INT($J$19/1000),1000),_LOOKUP_VND!A:C,2,FALSE()),VLOOKUP(MOD(INT($J$19/1000),1000),_LOOKUP_VND!A:C,3,FALSE()))&" nghìn ","")&IF(MOD($J$19,1000)>0,IF(OR(INT($J$19/1000000000)>0,MOD(INT($J$19/1000000),1000)>0,MOD(INT($J$19/1000),1000)>0),VLOOKUP(MOD($J$19,1000),_LOOKUP_VND!A:C,2,FALSE()),VLOOKUP(MOD($J$19,1000),_LOOKUP_VND!A:C,3,FALSE()))&" ",""))))&" đồng chẵn./."),"⚠ Lỗi đọc số")
C22: KHÁCH HÀNG | H22: NGƯỜI BÁO GIÁ
H23: Luân Nguyễn
B26: ──────── 🔎 TÌM NHANH (không in ra) ────────
B27: 🔎 Gõ:
C28: Mã HH | D28: Tên hàng | E28: ĐVT | F28: ĐK | G28: Giá vốn | H28: Giá VIP | I28: Giá ưu đãi | J28: Giá đại lý | K28: Giá gara
C29: =IF(M29="","",INDEX('📂 DATA'!$A$2:$A$7684,M29)) | D29: =IF(M29="","",INDEX('📂 DATA'!$B$2:$B$7684,M29)) | E29: =IF(M29="","",INDEX('📂 DATA'!$D$2:$D$7684,M29)) | F29: =IF(M29="","",INDEX('📂 DATA'!$J$2:$J$7684,M29)) | G29: =IF(M29="","",INDEX('📂 DATA'!$E$2:$E$7684,M29)) | H29: =IF(M29="","",INDEX('📂 DATA'!$F$2:$F$7684,M29)) | I29: =IF(M29="","",INDEX('📂 DATA'!$G$2:$G$7684,M29)) | J29: =IF(M29="","",INDEX('📂 DATA'!$H$2:$H$7684,M29)) | K29: =IF(M29="","",INDEX('📂 DATA'!$I$2:$I$7684,M29)) | M29: =IFERROR(MATCH(1,'📂 DATA'!$O$2:$O$7684,0),"")
C30: =IF(M30="","",INDEX('📂 DATA'!$A$2:$A$7684,M30)) | D30: =IF(M30="","",INDEX('📂 DATA'!$B$2:$B$7684,M30)) | E30: =IF(M30="","",INDEX('📂 DATA'!$D$2:$D$7684,M30)) | F30: =IF(M30="","",INDEX('📂 DATA'!$J$2:$J$7684,M30)) | G30: =IF(M30="","",INDEX('📂 DATA'!$E$2:$E$7684,M30)) | H30: =IF(M30="","",INDEX('📂 DATA'!$F$2:$F$7684,M30)) | I30: =IF(M30="","",INDEX('📂 DATA'!$G$2:$G$7684,M30)) | J30: =IF(M30="","",INDEX('📂 DATA'!$H$2:$H$7684,M30)) | K30: =IF(M30="","",INDEX('📂 DATA'!$I$2:$I$7684,M30)) | M30: =IFERROR(MATCH(2,'📂 DATA'!$O$2:$O$7684,0),"")
C31: =IF(M31="","",INDEX('📂 DATA'!$A$2:$A$7684,M31)) | D31: =IF(M31="","",INDEX('📂 DATA'!$B$2:$B$7684,M31)) | E31: =IF(M31="","",INDEX('📂 DATA'!$D$2:$D$7684,M31)) | F31: =IF(M31="","",INDEX('📂 DATA'!$J$2:$J$7684,M31)) | G31: =IF(M31="","",INDEX('📂 DATA'!$E$2:$E$7684,M31)) | H31: =IF(M31="","",INDEX('📂 DATA'!$F$2:$F$7684,M31)) | I31: =IF(M31="","",INDEX('📂 DATA'!$G$2:$G$7684,M31)) | J31: =IF(M31="","",INDEX('📂 DATA'!$H$2:$H$7684,M31)) | K31: =IF(M31="","",INDEX('📂 DATA'!$I$2:$I$7684,M31)) | M31: =IFERROR(MATCH(3,'📂 DATA'!$O$2:$O$7684,0),"")
C32: =IF(M32="","",INDEX('📂 DATA'!$A$2:$A$7684,M32)) | D32: =IF(M32="","",INDEX('📂 DATA'!$B$2:$B$7684,M32)) | E32: =IF(M32="","",INDEX('📂 DATA'!$D$2:$D$7684,M32)) | F32: =IF(M32="","",INDEX('📂 DATA'!$J$2:$J$7684,M32)) | G32: =IF(M32="","",INDEX('📂 DATA'!$E$2:$E$7684,M32)) | H32: =IF(M32="","",INDEX('📂 DATA'!$F$2:$F$7684,M32)) | I32: =IF(M32="","",INDEX('📂 DATA'!$G$2:$G$7684,M32)) | J32: =IF(M32="","",INDEX('📂 DATA'!$H$2:$H$7684,M32)) | K32: =IF(M32="","",INDEX('📂 DATA'!$I$2:$I$7684,M32)) | M32: =IFERROR(MATCH(4,'📂 DATA'!$O$2:$O$7684,0),"")
C33: =IF(M33="","",INDEX('📂 DATA'!$A$2:$A$7684,M33)) | D33: =IF(M33="","",INDEX('📂 DATA'!$B$2:$B$7684,M33)) | E33: =IF(M33="","",INDEX('📂 DATA'!$D$2:$D$7684,M33)) | F33: =IF(M33="","",INDEX('📂 DATA'!$J$2:$J$7684,M33)) | G33: =IF(M33="","",INDEX('📂 DATA'!$E$2:$E$7684,M33)) | H33: =IF(M33="","",INDEX('📂 DATA'!$F$2:$F$7684,M33)) | I33: =IF(M33="","",INDEX('📂 DATA'!$G$2:$G$7684,M33)) | J33: =IF(M33="","",INDEX('📂 DATA'!$H$2:$H$7684,M33)) | K33: =IF(M33="","",INDEX('📂 DATA'!$I$2:$I$7684,M33)) | M33: =IFERROR(MATCH(5,'📂 DATA'!$O$2:$O$7684,0),"")
C34: =IF(M34="","",INDEX('📂 DATA'!$A$2:$A$7684,M34)) | D34: =IF(M34="","",INDEX('📂 DATA'!$B$2:$B$7684,M34)) | E34: =IF(M34="","",INDEX('📂 DATA'!$D$2:$D$7684,M34)) | F34: =IF(M34="","",INDEX('📂 DATA'!$J$2:$J$7684,M34)) | G34: =IF(M34="","",INDEX('📂 DATA'!$E$2:$E$7684,M34)) | H34: =IF(M34="","",INDEX('📂 DATA'!$F$2:$F$7684,M34)) | I34: =IF(M34="","",INDEX('📂 DATA'!$G$2:$G$7684,M34)) | J34: =IF(M34="","",INDEX('📂 DATA'!$H$2:$H$7684,M34)) | K34: =IF(M34="","",INDEX('📂 DATA'!$I$2:$I$7684,M34)) | M34: =IFERROR(MATCH(6,'📂 DATA'!$O$2:$O$7684,0),"")
C35: =IF(M35="","",INDEX('📂 DATA'!$A$2:$A$7684,M35)) | D35: =IF(M35="","",INDEX('📂 DATA'!$B$2:$B$7684,M35)) | E35: =IF(M35="","",INDEX('📂 DATA'!$D$2:$D$7684,M35)) | F35: =IF(M35="","",INDEX('📂 DATA'!$J$2:$J$7684,M35)) | G35: =IF(M35="","",INDEX('📂 DATA'!$E$2:$E$7684,M35)) | H35: =IF(M35="","",INDEX('📂 DATA'!$F$2:$F$7684,M35)) | I35: =IF(M35="","",INDEX('📂 DATA'!$G$2:$G$7684,M35)) | J35: =IF(M35="","",INDEX('📂 DATA'!$H$2:$H$7684,M35)) | K35: =IF(M35="","",INDEX('📂 DATA'!$I$2:$I$7684,M35)) | M35: =IFERROR(MATCH(7,'📂 DATA'!$O$2:$O$7684,0),"")
C36: =IF(M36="","",INDEX('📂 DATA'!$A$2:$A$7684,M36)) | D36: =IF(M36="","",INDEX('📂 DATA'!$B$2:$B$7684,M36)) | E36: =IF(M36="","",INDEX('📂 DATA'!$D$2:$D$7684,M36)) | F36: =IF(M36="","",INDEX('📂 DATA'!$J$2:$J$7684,M36)) | G36: =IF(M36="","",INDEX('📂 DATA'!$E$2:$E$7684,M36)) | H36: =IF(M36="","",INDEX('📂 DATA'!$F$2:$F$7684,M36)) | I36: =IF(M36="","",INDEX('📂 DATA'!$G$2:$G$7684,M36)) | J36: =IF(M36="","",INDEX('📂 DATA'!$H$2:$H$7684,M36)) | K36: =IF(M36="","",INDEX('📂 DATA'!$I$2:$I$7684,M36)) | M36: =IFERROR(MATCH(8,'📂 DATA'!$O$2:$O$7684,0),"")
C37: =IF(M37="","",INDEX('📂 DATA'!$A$2:$A$7684,M37)) | D37: =IF(M37="","",INDEX('📂 DATA'!$B$2:$B$7684,M37)) | E37: =IF(M37="","",INDEX('📂 DATA'!$D$2:$D$7684,M37)) | F37: =IF(M37="","",INDEX('📂 DATA'!$J$2:$J$7684,M37)) | G37: =IF(M37="","",INDEX('📂 DATA'!$E$2:$E$7684,M37)) | H37: =IF(M37="","",INDEX('📂 DATA'!$F$2:$F$7684,M37)) | I37: =IF(M37="","",INDEX('📂 DATA'!$G$2:$G$7684,M37)) | J37: =IF(M37="","",INDEX('📂 DATA'!$H$2:$H$7684,M37)) | K37: =IF(M37="","",INDEX('📂 DATA'!$I$2:$I$7684,M37)) | M37: =IFERROR(MATCH(9,'📂 DATA'!$O$2:$O$7684,0),"")
C38: =IF(M38="","",INDEX('📂 DATA'!$A$2:$A$7684,M38)) | D38: =IF(M38="","",INDEX('📂 DATA'!$B$2:$B$7684,M38)) | E38: =IF(M38="","",INDEX('📂 DATA'!$D$2:$D$7684,M38)) | F38: =IF(M38="","",INDEX('📂 DATA'!$J$2:$J$7684,M38)) | G38: =IF(M38="","",INDEX('📂 DATA'!$E$2:$E$7684,M38)) | H38: =IF(M38="","",INDEX('📂 DATA'!$F$2:$F$7684,M38)) | I38: =IF(M38="","",INDEX('📂 DATA'!$G$2:$G$7684,M38)) | J38: =IF(M38="","",INDEX('📂 DATA'!$H$2:$H$7684,M38)) | K38: =IF(M38="","",INDEX('📂 DATA'!$I$2:$I$7684,M38)) | M38: =IFERROR(MATCH(10,'📂 DATA'!$O$2:$O$7684,0),"")
C39: =IF(M39="","",INDEX('📂 DATA'!$A$2:$A$7684,M39)) | D39: =IF(M39="","",INDEX('📂 DATA'!$B$2:$B$7684,M39)) | E39: =IF(M39="","",INDEX('📂 DATA'!$D$2:$D$7684,M39)) | F39: =IF(M39="","",INDEX('📂 DATA'!$J$2:$J$7684,M39)) | G39: =IF(M39="","",INDEX('📂 DATA'!$E$2:$E$7684,M39)) | H39: =IF(M39="","",INDEX('📂 DATA'!$F$2:$F$7684,M39)) | I39: =IF(M39="","",INDEX('📂 DATA'!$G$2:$G$7684,M39)) | J39: =IF(M39="","",INDEX('📂 DATA'!$H$2:$H$7684,M39)) | K39: =IF(M39="","",INDEX('📂 DATA'!$I$2:$I$7684,M39)) | M39: =IFERROR(MATCH(11,'📂 DATA'!$O$2:$O$7684,0),"")
C40: =IF(M40="","",INDEX('📂 DATA'!$A$2:$A$7684,M40)) | D40: =IF(M40="","",INDEX('📂 DATA'!$B$2:$B$7684,M40)) | E40: =IF(M40="","",INDEX('📂 DATA'!$D$2:$D$7684,M40)) | F40: =IF(M40="","",INDEX('📂 DATA'!$J$2:$J$7684,M40)) | G40: =IF(M40="","",INDEX('📂 DATA'!$E$2:$E$7684,M40)) | H40: =IF(M40="","",INDEX('📂 DATA'!$F$2:$F$7684,M40)) | I40: =IF(M40="","",INDEX('📂 DATA'!$G$2:$G$7684,M40)) | J40: =IF(M40="","",INDEX('📂 DATA'!$H$2:$H$7684,M40)) | K40: =IF(M40="","",INDEX('📂 DATA'!$I$2:$I$7684,M40)) | M40: =IFERROR(MATCH(12,'📂 DATA'!$O$2:$O$7684,0),"")

Sheet ⚙️ BỘ HƠI
B1: ⚙️ GOM BỘ HƠI (Piston + Séc măng + Xy lanh)
B2: Chọn Piston → Xy lanh → Séc măng. Báo theo BỘ; SL = số máy. Cảnh báo nếu lệch đời máy / sai mạ. | H2: =IF($H$40=0,"",IFERROR(IF(INDEX('🔩 PISTON'!$C$3:$C$1371,$H$40)=0,"",INDEX('🔩 PISTON'!$C$3:$C$1371,$H$40)),""))
H3: =IF($H$40=0,"",IFERROR(IF(INDEX('🔩 PISTON'!$D$3:$D$1371,$H$40)=0,"",INDEX('🔩 PISTON'!$D$3:$D$1371,$H$40)),""))
B4: ① Chọn Piston: | C4: KOMATSU 4D130 · ĐK130 (A) | E4: Mã HH: | H4: =IF($H$40=0,0,IFERROR(INDEX('🔩 PISTON'!$N$3:$N$1371,$H$40),0))
B5: ② Chọn Xy lanh: | C5: Xy lanh 4D130 (123503/N-6115-21-2211) - NSP | E5: Mã HH: | H5: =IF($H$6="kiếng","Không mạ",IF($H$6="gang","Có mạ","—"))
B6: ③ Chọn Séc măng: | C6: Séc măng 4D130/ 3.5-2.5-5.5 (SDK04011ZZ) - NPR | E6: Mã HH: | H6: =IF($H$41=0,"",IFERROR(IF(INDEX('🔧 XY LANH'!$F$3:$F$1100,$H$41)=0,"",INDEX('🔧 XY LANH'!$F$3:$F$1100,$H$41)),""))
H7: =IF($H$41=0,0,IFERROR(INDEX('🔧 XY LANH'!$J$3:$J$1100,$H$41),0))
B8: Thành phần | C8: Mã HH | D8: Chi tiết | F8: Giá (bộ) | H8: =IF($H$42=0,0,IFERROR(INDEX('⚙️ SÉC MĂNG'!$K$3:$K$1100,$H$42),0))
B9: 🔩 Piston | C9: =$H$34 | D9: =IF($H$40=0,"(chưa chọn)",$H$2&IF($H$21=""," "," · "&$H$21)&IF($H$11=""," "," · "&$H$11)&IF($H$12=""," "," · Ắc "&$H$12)&IF($H$13=""," "," · Ắc đỉnh "&$H$13)&IF($H$14=""," "," · Dài "&$H$14)&IF($H$33=""," "," · "&$H$33)&IF($H$15=""," "," ("&$H$15&")")) | F9: =$H$4
B10: 🔧 Xy lanh | C10: =$H$35 | D10: =IF($H$41=0,IF($H$40=0,"(chưa chọn)","⚠️ Đời máy này chưa tự dò ra — chọn tay ở ② hoặc gõ Mã HH"),$H$37) | F10: =$H$7 | H10: =IF($H$40=0,"",IFERROR(IF(INDEX('🔩 PISTON'!$E$3:$E$1371,$H$40)=0,"",INDEX('🔩 PISTON'!$E$3:$E$1371,$H$40)),""))
B11: ⚙️ Séc măng | C11: =$H$36 | D11: =IF($H$42=0,IF($H$40=0,"(chưa chọn)","⚠️ chưa tự dò ra — chọn tay ở ③ hoặc gõ Mã HH"),$H$26&" · "&IF($H$19=""," ",$H$19&" · ")&"Ring "&$H$18&" · "&$H$17) | F11: =$H$8 | H11: =IF($H$40=0,"",IFERROR(IF(INDEX('🔩 PISTON'!$F$3:$F$1371,$H$40)=0,"",INDEX('🔩 PISTON'!$F$3:$F$1371,$H$40)),""))
B12: 📦 Đơn vị | C12: =IF($H$41=0,"(chọn xy lanh)","BỘ "&$H$20&" MÁY") | H12: =IF($H$40=0,"",IFERROR(IF(INDEX('🔩 PISTON'!$G$3:$G$1371,$H$40)=0,"",INDEX('🔩 PISTON'!$G$3:$G$1371,$H$40)),""))
B13: 💰 ĐƠN GIÁ 1 BỘ | F13: =$H$4+$H$7+$H$8 | H13: =IF($H$40=0,"",IFERROR(IF(INDEX('🔩 PISTON'!$H$3:$H$1371,$H$40)=0,"",INDEX('🔩 PISTON'!$H$3:$H$1371,$H$40)),""))
B14: 🔢 Số lượng (bộ) | F14: 1 | H14: =IF($H$40=0,"",IFERROR(IF(INDEX('🔩 PISTON'!$I$3:$I$1371,$H$40)=0,"",INDEX('🔩 PISTON'!$I$3:$I$1371,$H$40)),""))
B15: 💵 THÀNH TIỀN | F15: =$F$13*$F$14 | H15: =IF($H$40=0,"",IFERROR(IF(INDEX('🔩 PISTON'!$J$3:$J$1371,$H$40)=0,"",INDEX('🔩 PISTON'!$J$3:$J$1371,$H$40)),""))
B16: 📝 Bằng chữ | C16: =IFERROR(IF(OR($F$15="",$F$15=0),"Không đồng./.",UPPER(LEFT(TRIM(IF(INT($F$15/1000000000)>0,VLOOKUP(INT($F$15/1000000000),_LOOKUP_VND!A:C,3,FALSE())&" tỷ ","")&IF(MOD(INT($F$15/1000000),1000)>0,IF(INT($F$15/1000000000)>0,VLOOKUP(MOD(INT($F$15/1000000),1000),_LOOKUP_VND!A:C,2,FALSE()),VLOOKUP(MOD(INT($F$15/1000000),1000),_LOOKUP_VND!A:C,3,FALSE()))&" triệu ","")&IF(MOD(INT($F$15/1000),1000)>0,IF(OR(INT($F$15/1000000000)>0,MOD(INT($F$15/1000000),1000)>0),VLOOKUP(MOD(INT($F$15/1000),1000),_LOOKUP_VND!A:C,2,FALSE()),VLOOKUP(MOD(INT($F$15/1000),1000),_LOOKUP_VND!A:C,3,FALSE()))&" nghìn ","")&IF(MOD($F$15,1000)>0,IF(OR(INT($F$15/1000000000)>0,MOD(INT($F$15/1000000),1000)>0,MOD(INT($F$15/1000),1000)>0),VLOOKUP(MOD($F$15,1000),_LOOKUP_VND!A:C,2,FALSE()),VLOOKUP(MOD($F$15,1000),_LOOKUP_VND!A:C,3,FALSE()))&" ","")),1))&MID(TRIM(IF(INT($F$15/1000000000)>0,VLOOKUP(INT($F$15/1000000000),_LOOKUP_VND!A:C,3,FALSE())&" tỷ ","")&IF(MOD(INT($F$15/1000000),1000)>0,IF(INT($F$15/1000000000)>0,VLOOKUP(MOD(INT($F$15/1000000),1000),_LOOKUP_VND!A:C,2,FALSE()),VLOOKUP(MOD(INT($F$15/1000000),1000),_LOOKUP_VND!A:C,3,FALSE()))&" triệu ","")&IF(MOD(INT($F$15/1000),1000)>0,IF(OR(INT($F$15/1000000000)>0,MOD(INT($F$15/1000000),1000)>0),VLOOKUP(MOD(INT($F$15/1000),1000),_LOOKUP_VND!A:C,2,FALSE()),VLOOKUP(MOD(INT($F$15/1000),1000),_LOOKUP_VND!A:C,3,FALSE()))&" nghìn ","")&IF(MOD($F$15,1000)>0,IF(OR(INT($F$15/1000000000)>0,MOD(INT($F$15/1000000),1000)>0,MOD(INT($F$15/1000),1000)>0),VLOOKUP(MOD($F$15,1000),_LOOKUP_VND!A:C,2,FALSE()),VLOOKUP(MOD($F$15,1000),_LOOKUP_VND!A:C,3,FALSE()))&" ","")),2,LEN(TRIM(IF(INT($F$15/1000000000)>0,VLOOKUP(INT($F$15/1000000000),_LOOKUP_VND!A:C,3,FALSE())&" tỷ ","")&IF(MOD(INT($F$15/1000000),1000)>0,IF(INT($F$15/1000000000)>0,VLOOKUP(MOD(INT($F$15/1000000),1000),_LOOKUP_VND!A:C,2,FALSE()),VLOOKUP(MOD(INT($F$15/1000000),1000),_LOOKUP_VND!A:C,3,FALSE()))&" triệu ","")&IF(MOD(INT($F$15/1000),1000)>0,IF(OR(INT($F$15/1000000000)>0,MOD(INT($F$15/1000000),1000)>0),VLOOKUP(MOD(INT($F$15/1000),1000),_LOOKUP_VND!A:C,2,FALSE()),VLOOKUP(MOD(INT($F$15/1000),1000),_LOOKUP_VND!A:C,3,FALSE()))&" nghìn ","")&IF(MOD($F$15,1000)>0,IF(OR(INT($F$15/1000000000)>0,MOD(INT($F$15/1000000),1000)>0,MOD(INT($F$15/1000),1000)>0),VLOOKUP(MOD($F$15,1000),_LOOKUP_VND!A:C,2,FALSE()),VLOOKUP(MOD($F$15,1000),_LOOKUP_VND!A:C,3,FALSE()))&" ",""))))&" đồng chẵn./."),"⚠ Lỗi đọc số")
H17: =IF($H$42=0,"",IFERROR(IF(INDEX('⚙️ SÉC MĂNG'!$H$3:$H$1100,$H$42)=0,"",INDEX('⚙️ SÉC MĂNG'!$H$3:$H$1100,$H$42)),""))
B18: =IF(OR($H$40=0,$H$41=0,$H$42=0),"⬆ Chọn đủ Piston + Xy lanh + Séc măng (theo tên hoặc Mã HH).",IF($H$32="SAI","⛔ XY LANH ("&$H$29&" ĐK"&$H$30&") KHÁC đời máy Piston ("&$H$2&" ĐK"&$H$3&") — KIỂM TRA LẠI!",IF($H$31="SAI","⛔ SÉC MĂNG ("&$H$26&" ĐK"&$H$27&") KHÁC đời máy Piston ("&$H$2&" ĐK"&$H$3&") — KIỂM TRA LẠI!",IF(AND($H$5<>"—",$H$5<>"",$H$19<>$H$5),"⚠️ Xy lanh "&$H$6&" nên dùng séc măng "&$H$5&" — đang chọn "&IF($H$19="","(không mạ)",$H$19)&".","✅ Đủ bộ hơi 3 món · cùng đời máy "&$H$2&IF($H$5="—"," (không phân mạ)"," · séc măng "&$H$19&" hợp xy lanh "&$H$6))))) | H18: =IF($H$42=0,"",IFERROR(IF(INDEX('⚙️ SÉC MĂNG'!$G$3:$G$1100,$H$42)=0,"",INDEX('⚙️ SÉC MĂNG'!$G$3:$G$1100,$H$42)),""))
H19: =IF($H$42=0,"",IFERROR(IF(INDEX('⚙️ SÉC MĂNG'!$F$3:$F$1100,$H$42)=0,"",INDEX('⚙️ SÉC MĂNG'!$F$3:$F$1100,$H$42)),""))
H20: =IF($H$41=0,"",IFERROR(IF(INDEX('🔧 XY LANH'!$E$3:$E$1100,$H$41)=0,"",INDEX('🔧 XY LANH'!$E$3:$E$1100,$H$41)),""))
H21: =IF($H$40=0,"",IF($H$10="(A)+(O)","chân ko",IF($H$10="(A)","kiềng gang",$H$10)))
H26: =IF($H$42=0,"",IFERROR(IF(INDEX('⚙️ SÉC MĂNG'!$C$3:$C$1100,$H$42)=0,"",INDEX('⚙️ SÉC MĂNG'!$C$3:$C$1100,$H$42)),""))
H27: =IF($H$42=0,"",IFERROR(IF(INDEX('⚙️ SÉC MĂNG'!$D$3:$D$1100,$H$42)=0,"",INDEX('⚙️ SÉC MĂNG'!$D$3:$D$1100,$H$42)),""))
H29: =IF($H$41=0,"",IFERROR(IF(INDEX('🔧 XY LANH'!$C$3:$C$1100,$H$41)=0,"",INDEX('🔧 XY LANH'!$C$3:$C$1100,$H$41)),""))
H30: =IF($H$41=0,"",IFERROR(IF(INDEX('🔧 XY LANH'!#REF!,$H$41)=0,"",INDEX('🔧 XY LANH'!#REF!,$H$41)),""))
H31: =IF(OR($H$40=0,$H$42=0),"",IF(OR(ISNUMBER(SEARCH($H$2,$H$26)),ISNUMBER(SEARCH($H$26,$H$2))),IF(OR($H$27="",$H$3="",$H$3=$H$27),"OK","SAI"),"SAI"))
H32: =IF(OR($H$40=0,$H$41=0),"",IF(OR(ISNUMBER(SEARCH($H$2,$H$29)),ISNUMBER(SEARCH($H$29,$H$2))),IF(OR($H$30="",$H$3="",$H$3=$H$30),"OK","SAI"),"SAI"))
H33: =IF($H$40=0,"",IFERROR(IF(INDEX('🔩 PISTON'!$K$3:$K$1371,$H$40)=0,"",INDEX('🔩 PISTON'!$K$3:$K$1371,$H$40)),""))
H34: =IF($H$40=0,"",IFERROR(IF(INDEX('🔩 PISTON'!$A$3:$A$1371,$H$40)=0,"",INDEX('🔩 PISTON'!$A$3:$A$1371,$H$40)),""))
H35: =IF($H$41=0,"",IFERROR(IF(INDEX('🔧 XY LANH'!$A$3:$A$1100,$H$41)=0,"",INDEX('🔧 XY LANH'!$A$3:$A$1100,$H$41)),""))
H36: =IF($H$42=0,"",IFERROR(IF(INDEX('⚙️ SÉC MĂNG'!$A$3:$A$1100,$H$42)=0,"",INDEX('⚙️ SÉC MĂNG'!$A$3:$A$1100,$H$42)),""))
H37: =IF($H$41=0,"",IFERROR(IF(INDEX('🔧 XY LANH'!$N$3:$N$1100,$H$41)=0,"",INDEX('🔧 XY LANH'!$N$3:$N$1100,$H$41)),""))
H40: =IFERROR(IF($F$4<>"",MATCH($F$4,'🔩 PISTON'!$A$3:$A$1371,0),IF($C$4<>"",MATCH($C$4,'🔩 PISTON'!$U$3:$U$1371,0),0)),0)
H41: =IFERROR(IF($F$5<>"",MATCH($F$5,'🔧 XY LANH'!$A$3:$A$1100,0),IF($C$5<>"",MATCH($C$5,'🔧 XY LANH'!$N$3:$N$1100,0),$H$43)),0)
H42: =IFERROR(IF($F$6<>"",MATCH($F$6,'⚙️ SÉC MĂNG'!$A$3:$A$1100,0),IF($C$6<>"",MATCH($C$6,'⚙️ SÉC MĂNG'!$R$3:$R$1100,0),$H$44)),0)
H43: =IF('⚙️ BỘ HƠI'!$H$40=0,0,IF(MIN('🔧 XY LANH'!$P$3:$P$1100)=99999,0,MIN('🔧 XY LANH'!$P$3:$P$1100)))
H44: =IF('⚙️ BỘ HƠI'!$H$40=0,0,IF(MIN('⚙️ SÉC MĂNG'!$S$3:$S$1100)=99999,0,MIN('⚙️ SÉC MĂNG'!$S$3:$S$1100)))

Sheet 📦 RON BỘ
A1: STT | B1: 🔖 MÃ VT | C1: 📋 TÊN HÀNG | D1: 📐 ĐK | E1: 🏭 HÃNG | F1: 🏷️ TH SX | G1: 📦 ĐVT | H1: 💰 GIÁ VỐN | I1: 🟢 GIÁ VIP | J1: 🟡 GIÁ Ư.ĐÃI | K1: 🔵 GIÁ ĐẠI LÝ | L1: 🟣 GIÁ GARA | M1: 📦 TỒN | N1: 📝 GHI CHÚ
C2: ◆ HINO (14 sản phẩm)
A3: 1 | B3: HH076479 | C3: Ron bộ Hino DM100 - Amiang - MASAKO | D3: 90 | E3: HINO | F3: MASAKO | G3: Bộ | I3: 630000 | J3: 670000 | K3: 720000
A4: 2 | B4: HH084235 | C4: Ron bộ Hino EC100, ASB Amiang - DF | D4: 97 | E4: HINO | F4: DF | G4: Bộ | I4: 760000 | J4: 810000 | K4: 860000
A5: 3 | B5: HH076278 | C5: Ron bộ Hino EF750, amiang - MASAKO | D5: 137 | E5: HINO | F5: MASAKO | G5: Bộ | I5: 1250000 | J5: 1350000 | K5: 1450000
A6: 4 | B6: HH080139 | C6: Ron bộ Hino EP100, thép - DF | E6: HINO | F6: DF | G6: Bộ | I6: 1670000 | J6: 1770000 | K6: 1900000
A7: 5 | B7: HH072734 | C7: Ron bộ Hino H06C/H07C - Amiang (cổ bô 3 lỗ) - DF | D7: 108 | E7: HINO | F7: DF | G7: Bộ
A8: 6 | B8: HH079303 | C8: Ron bộ Hino H06C/H07C sợi tổng hợp (cổ bô 3 lỗ) - MASAKO | D8: 108 | E8: HINO | F8: MASAKO | G8: Bộ | I8: 750000 | J8: 800000 | K8: 850000
A9: 7 | B9: HH078075 | C9: Ron bộ Hino H07D/ D6DA/ K6700, Non Asb sợi tổng hợp - DF | D9: 109/110 | E9: HINO | F9: DF | G9: Bộ | I9: 810000 | J9: 860000 | K9: 920000
A10: 8 | B10: HH079048 | C10: Ron bộ Hino J05E, Thép - NICE IN | D10: 112 | E10: HINO | F10: NICE IN | G10: Bộ | I10: 1140000 | J10: 1200000 | K10: 1300000
A11: 9 | B11: HH079662 | C11: Ron bộ Hino J07C (sợi tổng hợp) - DF | D11: 114 | E11: HINO | F11: DF | G11: Bộ | I11: 1350000 | J11: 1450000 | K11: 1550000
A12: 10 | B12: HH082104 | C12: Ron bộ Hino J08C-T (J08E) Thép Inox - NICE IN | D12: 112/114 | E12: HINO | F12: NICE IN | G12: Bộ | I12: 1450000 | J12: 1550000 | K12: 1650000
A13: 11 | B13: HH077867 | C13: Ron bộ Hino J08E/ J08C, Thép (S) - NICE IN | D13: 112/114 | E13: HINO | F13: NICE IN | G13: Bộ | I13: 1500000 | J13: 1600000 | K13: 1720000
A14: 12 | B14: HH083903 | C14: Ron bộ Hino N04C thép (S) - NICE IN | E14: HINO | F14: NICE IN | G14: Bộ | I14: 650000 | J14: 680000 | K14: 730000
A15: 13 | B15: HH078290 | C15: Ron bộ Hino W04D, sợi tổng hợp - MASAKO | D15: 104 | E15: HINO | F15: MASAKO | G15: Bộ | I15: 480000 | J15: 510000 | K15: 550000
A16: 14 | B16: HH078291 | C16: Ron bộ Hino W04E, sợi tổng hợp - MASAKO | D16: 104 | E16: HINO | F16: MASAKO | G16: Bộ | I16: 530000 | J16: 560000 | K16: 600000
C17: ◆ ISUZU (47 sản phẩm)
A18: 15 | B18: HH072074 | C18: Ron bộ Isuzu 3KR1 / 3KR2 (Graphite) - DF | D18: 81 | E18: ISUZU | F18: DF | G18: Bộ | I18: 670000 | J18: 720000 | K18: 770000
A19: 16 | B19: HH076547 | C19: Ron bộ Isuzu 3KR1/ 3KR2, Graphite - MASAKO | D19: 81 | E19: ISUZU | F19: MASAKO | G19: Bộ | I19: 675000 | J19: 720000 | K19: 770000
A20: 17 | B20: HH081491 | C20: Ron bộ Isuzu 3LD1, Steel Thép - DF | D20: 83 | E20: ISUZU | F20: DF | G20: Bộ | I20: 690000 | J20: 740000 | K20: 780000
A21: 18 | B21: HH076282 | C21: Ron bộ Isuzu 3LD1, Thép - MASAKO | D21: 83 | E21: ISUZU | F21: MASAKO | G21: Bộ | I21: 605000 | J21: 645000 | K21: 690000
A22: 19 | B22: HH083490 | C22: Ron bộ Isuzu 3LD2, Thép - MASAKO (580.620/60) | D22: 83 | E22: ISUZU | F22: MASAKO (580.620/60) | G22: Bộ | I22: 580000 | J22: 620000 | K22: 660000
A23: 20 | B23: HH078287 | C23: Ron bộ Isuzu 4BC2 Thép (thun cò trơn dẹt) - MASAKO | D23: 102 | E23: ISUZU | F23: MASAKO | G23: Bộ | I23: 460000 | J23: 490000 | K23: 500000
A24: 21 | B24: HH079601 | C24: Ron bộ Isuzu 4BD1/4BB1 Amiang (thun ngạnh, p sau 100-135) - MASAKO | D24: 102 | E24: ISUZU | F24: MASAKO | G24: Bộ | I24: 530000 | J24: 565000 | K24: 610000
A25: 22 | B25: HH075743 | C25: Ron bộ Isuzu 4BD1/4BB1 Thép (thun ngạnh, p sau 100-135) - MASAKO | D25: 102 | E25: ISUZU | F25: MASAKO | G25: Bộ | I25: 540000 | J25: 570000 | K25: 620000
A26: 23 | B26: HH077342 | C26: Ron bộ Isuzu 4BG1 Thép - MASAKO | D26: 105 | E26: ISUZU | F26: MASAKO | G26: Bộ | I26: 540000 | J26: 580000 | K26: 620000
A27: 24 | B27: HH079805 | C27: Ron bộ Isuzu 4BG1 Thép Inox - NICE IN | D27: 105 | E27: ISUZU | F27: NICE IN | G27: Bộ | I27: 740000 | J27: 790000 | K27: 840000
A28: 25 | B28: HH00760 | C28: Ron bộ Isuzu 4BG1, Steel Thép - DF | D28: 105 | E28: ISUZU | F28: DF | G28: Bộ | I28: 690000 | J28: 740000 | K28: 790000
A29: 26 | B29: HH00152 | C29: Ron bộ Isuzu 4BG1-T, phớt trà, Thép - DF | D29: 105 | E29: ISUZU | F29: DF | G29: Bộ
A30: 27 | B30: HH084234 | C30: Ron bộ Isuzu 4FA1, Thép - DF | E30: ISUZU | F30: DF | G30: Bộ | I30: 660000 | J30: 700000 | K30: 750000
A31: 28 | B31: HH078067 | C31: Ron bộ Isuzu 4FB1/ 4FC1, Thép - DF | E31: ISUZU | F31: DF | G31: Bộ | I31: 660000 | J31: 700000 | K31: 750000
A32: 29 | B32: HH078068 | C32: Ron bộ Isuzu 4FE1, Steel Thép - DF | E32: ISUZU | F32: DF | G32: Bộ | I32: 640000 | J32: 680000 | K32: 730000
A33: 30 | B33: HH075973 | C33: Ron bộ Isuzu 4HG1 (new) thép - DF | E33: ISUZU | F33: DF | G33: Bộ | I33: 740000 | J33: 790000 | K33: 840000
A34: 31 | B34: HH075681 | C34: Ron bộ Isuzu 4HG1 (old) thép - DF | E34: ISUZU | F34: DF | G34: Bộ | I34: 740000 | J34: 790000 | K34: 840000
A35: 32 | B35: HH076830 | C35: Ron bộ Isuzu 4HK1-T (đời điện) - thép Inox - NICE IN | E35: ISUZU | F35: NICE IN | G35: Bộ | I35: 1280000 | J35: 1370000 | K35: 1460000
A36: 33 | B36: HH077494 | C36: Ron bộ Isuzu 4JB1 (catte 1 tầng), 4JA1 - Thép - DF | D36: 93 | E36: ISUZU | F36: DF | G36: Bộ | I36: 260000 | J36: 280000 | K36: 300000
A37: 34 | B37: HH075744 | C37: Ron bộ Isuzu 4JB1- T (catte 2 tầng) thép - MASAKO | D37: 93 | E37: ISUZU | F37: MASAKO | G37: Bộ | I37: 400000 | J37: 430000 | K37: 460000
A38: 35 | B38: HH00764 | C38: Ron bộ Isuzu 4JB1-T (catte 2 tầng) thép, 4JA1 - DF | D38: 93 | E38: ISUZU | F38: DF | G38: Bộ | I38: 400000 | J38: 440000 | K38: 470000
A39: 36 | B39: HH076554 | C39: Ron bộ Isuzu 4JC1 (D201) Thép - MASAKO (480.510/50) | D39: 88 | E39: ISUZU | F39: MASAKO (480.510/50) | G39: Bộ | I39: 480000 | J39: 510000 | K39: 550000
A40: 37 | B40: HH084251 | C40: Ron bộ Isuzu 4JE1, Thép - DF | E40: ISUZU | F40: DF | G40: Bộ | I40: 610000 | J40: 650000 | K40: 690000
...

Sheet 📄 RON MIẾNG
A1: STT | B1: 🔖 MÃ VT | C1: 📋 TÊN HÀNG | D1: 📐 ĐK | E1: 🏭 HÃNG | F1: 🏷️ TH SX | G1: 📦 ĐVT | H1: GHI CHÚ | I1: 💰 GIÁ VỐN | J1: 🟢 GIÁ VIP | K1: 🟡 GIÁ Ư.ĐÃI | L1: 🔵 GIÁ ĐẠI LÝ | M1: 🟣 GIÁ GARA | N1: 📦 TỒN | O1: 📝 GHI CHÚ
C2: ◆ HINO (16 sản phẩm)
A3: 1 | B3: HH076259 | C3: Ron miếng Hino DM100 - Amiang - MASAKO | D3: 90 | E3: HINO | F3: MASAKO | G3: Cái
A4: 2 | B4: HH070916 | C4: Ron miếng Hino DM100, Amiang - NICE IN | D4: 90 | E4: HINO | F4: NICE IN | G4: Cái | J4: 140000 | K4: 150000 | L4: 200000
A5: 3 | B5: HH084263 | C5: Ron miếng Hino EC100, ASB amiang - DF | D5: 97 | E5: HINO | F5: DF | G5: Cái | J5: 250000 | K5: 270000 | L5: 290000
A6: 4 | B6: HH076280 | C6: Ron miếng Hino EF750/F17D/EF500, ASB amiang - MASAKO | D6: 137 | E6: HINO | F6: MASAKO | G6: Bộ 2c | J6: 320000 | K6: 350000 | L6: 400000
A7: 5 | B7: HH078098 | C7: Ron miếng Hino EM100, Steel thép - DF | D7: 124 | E7: HINO | F7: DF | G7: Cái | J7: 500000 | K7: 530000 | L7: 560000
A8: 6 | B8: HH076569 | C8: Ron miếng Hino H07C (H06C), Graphite, sợi - NICE IN | D8: 108 | E8: HINO | F8: NICE IN | G8: Cái | J8: 200000 | K8: 215000 | L8: 230000
A9: 7 | B9: HH079592 | C9: Ron miếng Hino J05C-T, thép - NICE IN | E9: HINO | F9: NICE IN | G9: Cái | J9: 280000 | K9: 295000 | L9: 320000
A10: 8 | B10: HH081355 | C10: Ron miếng Hino J05E thép (S) - NICE IN | D10: 112 | E10: HINO | F10: NICE IN | G10: Cái | J10: 290000 | K10: 310000 | L10: 340000
A11: 9 | B11: HH072088 | C11: Ron miếng Hino J05E, sợi tổng hợp, giấy - DF | D11: 112 | E11: HINO | F11: DF | G11: Cái | J11: 300000 | K11: 350000 | L11: 400000
A12: 10 | B12: HH079677 | C12: Ron miếng Hino J07C, sợi tổng hợp - DF | D12: 114 | E12: HINO | F12: DF | G12: Cái | J12: 310000 | K12: 350000 | L12: 400000
A13: 11 | B13: HH072089 | C13: Ron miếng Hino J08C/J08E, sợi tổng hợp, giấy - DF | D13: 112/114 | E13: HINO | F13: DF | G13: Cái | J13: 330000 | K13: 380000 | L13: 430000
A14: 12 | B14: HH077878 | C14: Ron miếng Hino J08E / J08C, Thép (S) - NICE IN | D14: 112/114 | E14: HINO | F14: NICE IN | G14: Cái | J14: 320000 | K14: 340000 | L14: 360000
A15: 13 | B15: HH081356 | C15: Ron miếng Hino J08E/ J08C sợi tổng hợp - NICE IN | D15: 112/114 | E15: HINO | F15: NICE IN | G15: Cái | J15: 300000 | K15: 330000 | L15: 350000
A16: 14 | B16: HH083902 | C16: Ron miếng Hino N04C, thép (S) - NICE IN | E16: HINO | F16: NICE IN | G16: Cái | J16: 180000 | K16: 200000 | L16: 220000
A17: 15 | B17: HH078274 | C17: Ron miếng Hino P11C thép - NICE IN | E17: HINO | F17: NICE IN | G17: Cái | J17: 320000 | K17: 340000 | L17: 370000
A18: 16 | B18: HH073591 | C18: Ron miếng Hino W04D, sợi tổng hợp - NICE IN | D18: 104 | E18: HINO | F18: NICE IN | G18: Cái | J18: 150000 | K18: 170000 | L18: 200000
C19: ◆ ISUZU (42 sản phẩm)
A20: 17 | B20: HH079287 | C20: Ron miếng ISUZU 4LC1/4LB1 amiang - MASAKO | D20: 77.4 | E20: ISUZU | F20: MASAKO | G20: Cái | J20: 85000 | K20: 90000 | L20: 100000
A21: 18 | B21: HH083018 | C21: Ron miếng ISUZU 4LC1/4LB1 amiang - NICE IN (90.100/20) | D21: 77.4 | E21: ISUZU | F21: NICE IN (90.100/20) | G21: Cái | J21: 90000 | K21: 100000 | L21: 120000
A22: 19 | B22: HH076565 | C22: Ron miếng Isuzu 3KC1, GP - MASAKO | D22: 74 | E22: ISUZU | F22: MASAKO | G22: Cái | J22: 140000 | K22: 150000 | L22: 170000
A23: 20 | B23: HH077322 | C23: Ron miếng Isuzu 3KC1, GP - NICE IN | D23: 74 | E23: ISUZU | F23: NICE IN | G23: Cái | J23: 140000 | K23: 150000 | L23: 170000
A24: 21 | B24: HH081351 | C24: Ron miếng Isuzu 3KR1/3KR2, GP - NICE IN | D24: 81 | E24: ISUZU | F24: NICE IN | G24: Cái | J24: 140000 | K24: 150000 | L24: 170000
A25: 22 | B25: HH078270 | C25: Ron miếng Isuzu 3LD1, Thép - NICE IN | D25: 83 | E25: ISUZU | F25: NICE IN | G25: Cái | J25: 170000 | K25: 185000 | L25: 200000
A26: 23 | B26: HH083491 | C26: Ron miếng Isuzu 3LD2, Thép - NICE IN (170/90.210) | D26: 83 | E26: ISUZU | F26: NICE IN (170/90.210) | G26: Cái | J26: 170000 | K26: 190000 | L26: 210000
A27: 24 | B27: HH079698 | C27: Ron miếng Isuzu 4BD1 Amiang (4BB1) - MASAKO | D27: 102 | E27: ISUZU | F27: MASAKO | G27: Cái | J27: 90000 | K27: 100000 | L27: 120000
A28: 25 | B28: HH077324 | C28: Ron miếng Isuzu 4BD1, Thép Inox (4BB1) - NICE IN | D28: 102 | E28: ISUZU | F28: NICE IN | G28: Cái | J28: 160000 | K28: 170000 | L28: 190000
A29: 26 | B29: HH075769 | C29: Ron miếng Isuzu 4BD1, Thép, 4BB1 - MASAKO | D29: 102 | E29: ISUZU | F29: MASAKO | G29: Cái | J29: 110000 | K29: 130000 | L29: 150000
A30: 27 | B30: HH075762 | C30: Ron miếng Isuzu 4BG1/4BE1 thép (S) - MASAKO | D30: 105 | E30: ISUZU | F30: MASAKO | G30: Cái | J30: 110000 | K30: 130000 | L30: 150000
A31: 28 | B31: HH077325 | C31: Ron miếng Isuzu 4BG1/4BE1 thép (S) - NICE IN | D31: 105 | E31: ISUZU | F31: NICE IN | G31: Cái | J31: 160000 | K31: 170000 | L31: 180000
A32: 29 | B32: HH084262 | C32: Ron miếng Isuzu 4FA1, Thép - DF | E32: ISUZU | F32: DF | G32: Cái | J32: 180000 | K32: 190000 | L32: 210000
A33: 30 | B33: HH078099 | C33: Ron miếng Isuzu 4FB1/4FC1, Steel Thép - DF | E33: ISUZU | F33: DF | G33: Cái | J33: 150000 | K33: 160000 | L33: 180000
A34: 31 | B34: HH083885 | C34: Ron miếng Isuzu 4HF1 Old, Thép - NICE IN | D34: 112 | E34: ISUZU | F34: NICE IN | G34: Cái | J34: 200000 | K34: 220000 | L34: 250000
A35: 32 | B35: HH075974 | C35: Ron miếng Isuzu 4HG1-New thép - DF | E35: ISUZU | F35: DF | G35: Cái | J35: 230000 | K35: 250000 | L35: 270000
A36: 33 | B36: HH075975 | C36: Ron miếng Isuzu 4HG1-Old, thép - DF | E36: ISUZU | F36: DF | G36: Cái | J36: 240000 | K36: 260000 | L36: 280000
A37: 34 | B37: HH080622 | C37: Ron miếng Isuzu 4JB1 (4JA1) Thép Inox - NICE IN | D37: 93 | E37: ISUZU | F37: NICE IN | G37: Cái | J37: 100000 | K37: 120000 | L37: 150000
A38: 35 | B38: HH075768 | C38: Ron miếng Isuzu 4JB1 Thép (4JA1) - MASAKO | D38: 93 | E38: ISUZU | F38: MASAKO | G38: Cái | J38: 95000 | K38: 110000 | L38: 120000
A39: 36 | B39: HH079343 | C39: Ron miếng Isuzu 4JB1/4JA1, ASB amiang - MASAKO | D39: 93 | E39: ISUZU | F39: MASAKO | G39: Cái | J39: 80000 | K39: 90000 | L39: 100000
A40: 37 | B40: HH076262 | C40: Ron miếng Isuzu 4JC1 (D201) Thép - MASAKO | D40: 88 | E40: ISUZU | F40: MASAKO | G40: Cái | J40: 140000 | K40: 150000 | L40: 170000
...

Sheet 📋 MIỂNG TNC
A1: 📋 MIỂNG (BẠC) — dữ liệu mới nhất
A2: Mã HH | B2: Hãng | C2: Mã ĐC | D2: ĐK | E2: Cos | F2: Loại | G2: Thương hiệu | H2: ĐVT | I2: Ghi chú | J2: VIP | K2: Ưu đãi | L2: Đại lý | M2: Gara | N2: Tồn | O2: PARNO | P2: Tên đầy đủ
C3: ◆ HINO
A4: HH070779 | B4: HINO | C4: Bạc miểng DM100/DQ100 Cos0 - TAIHO | D4: 90 | E4: Cos0 | F4: Baze+Dên | G4: TAIHO | H4: Bộ | P4: Bạc miểng DM100/DQ100 Cos0 - TAIHO
A5: HH071938 | B5: HINO | C5: Bạc miểng DM100/DQ100 Cos1 - TAIHO | D5: 90 | E5: Cos1 | F5: Baze+Dên | G5: TAIHO | H5: Bộ | P5: Bạc miểng DM100/DQ100 Cos1 - TAIHO
A6: HH071939 | B6: HINO | C6: Bạc miểng DM100/DQ100 Cos2 - TAIHO | D6: 90 | E6: Cos2 | F6: Baze+Dên | G6: TAIHO | H6: Bộ | P6: Bạc miểng DM100/DQ100 Cos2 - TAIHO
A7: HH079058 | B7: HINO | C7: Bạc miểng DM100/DQ100 Cos3 - TAIHO | D7: 90 | E7: Cos3 | F7: Baze+Dên | G7: TAIHO | H7: Bộ | P7: Bạc miểng DM100/DQ100 Cos3 - TAIHO
B8: HINO | C8: Bạc Miểng DM100/DQ100 | D8: 90 | E8: Cos4 | F8: Baze+Dên | H8: Bộ
A9: HH083728 | B9: HINO | C9: Bạc miểng Hino W04D/W04E (M133K, R133K1) STD Cos0 - DAIDO NHẬT | D9: 104 | E9: Cos0 | F9: Baze+Dên | G9: DAIDO NHẬT | H9: Bộ | J9: 590000 | K9: 630000 | L9: 680000 | P9: Bạc miểng Hino W04D/W04E (M133K, R133K1) STD Cos0 - DAIDO NHẬT
A10: HH00276 | B10: HINO | C10: Bạc miểng W04D / W04E Cos0 - TAIHO | D10: 104 | E10: Cos0 | F10: Baze+Dên | G10: TAIHO | H10: Bộ | P10: Bạc miểng W04D / W04E Cos0 - TAIHO
A11: HH00275 | B11: HINO | C11: Bạc miểng W04D / W04E Cos1 - TAIHO | D11: 104 | E11: Cos1 | F11: Baze+Dên | G11: TAIHO | H11: Bộ | P11: Bạc miểng W04D / W04E Cos1 - TAIHO
B12: HINO | C12: Bạc Miểng W04D/W04E | D12: 104 | E12: Cos2 | F12: Baze+Dên | H12: Bộ
B13: HINO | C13: Bạc Miểng W04D/W04E | D13: 104 | E13: Cos3 | F13: Baze+Dên | H13: Bộ
B14: HINO | C14: Bạc Miểng W04D/W04E | D14: 104 | E14: Cos4 | F14: Baze+Dên | H14: Bộ
A15: HH083730 | B15: HINO | C15: Bạc miểng Hino W06D/W06E (M134K, R134K1) STD Cos0 - DAIDO NHẬT | D15: 104 | E15: Cos0 | F15: Baze+Dên | G15: DAIDO NHẬT | H15: Bộ | J15: 1800000 | K15: 1900000 | L15: 2050000 | P15: Bạc miểng Hino W06D/W06E (M134K, R134K1) STD Cos0 - DAIDO NHẬT
B16: HINO | C16: Bạc Miểng W06D/W06E | D16: 104 | E16: Cos1 | F16: Baze+Dên | H16: Bộ
B17: HINO | C17: Bạc Miểng W06D/W06E | D17: 104 | E17: Cos2 | F17: Baze+Dên | H17: Bộ
B18: HINO | C18: Bạc Miểng W06D/W06E | D18: 104 | E18: Cos3 | F18: Baze+Dên | H18: Bộ
A19: HH072136 | B19: HINO | C19: Bạc miểng W06D/ W06E Cos4 - TAIHO | D19: 104 | E19: Cos4 | F19: Baze+Dên | G19: TAIHO | H19: Bộ | P19: Bạc miểng W06D/ W06E Cos4 - TAIHO
A20: HH070806 | B20: HINO | C20: Bạc miểng W06D/ W06E Cos2 - TAIHO | E20: Cos2 | F20: Baze+Dên | G20: TAIHO | H20: Bộ | P20: Bạc miểng W06D/ W06E Cos2 - TAIHO
A21: HH074388 | B21: HINO | C21: Bạc miểng DS30/DS50 cos0 - NDC | D21: 110 | E21: Cos0 | F21: Baze+Dên | G21: NDC | H21: Bộ | P21: Bạc miểng DS30/DS50 cos0 - NDC
B22: HINO | C22: Bạc Miểng DS30/DS50 | D22: 110 | E22: Cos1 | F22: Baze+Dên | H22: Bộ
B23: HINO | C23: Bạc Miểng DS30/DS50 | D23: 110 | E23: Cos2 | F23: Baze+Dên | H23: Bộ
B24: HINO | C24: Bạc Miểng DS30/DS50 | D24: 110 | E24: Cos3 | F24: Baze+Dên | H24: Bộ
B25: HINO | C25: Bạc Miểng DS30/DS50 | D25: 110 | E25: Cos4 | F25: Baze+Dên | H25: Bộ
A26: HH073146 | B26: HINO | C26: Bạc miểng EH700 Cos0 - NDC | D26: 110 | E26: Cos0 | F26: Baze+Dên | G26: NDC | H26: Bộ | P26: Bạc miểng EH700 Cos0 - NDC
B27: HINO | C27: Bạc Miểng EH700 | D27: 110 | E27: Cos1 | F27: Baze+Dên | H27: Bộ
B28: HINO | C28: Bạc Miểng EH700 | D28: 110 | E28: Cos2 | F28: Baze+Dên | H28: Bộ
B29: HINO | C29: Bạc Miểng EH700 | D29: 110 | E29: Cos3 | F29: Baze+Dên | H29: Bộ
B30: HINO | C30: Bạc Miểng EH700 | D30: 110 | E30: Cos4 | F30: Baze+Dên | H30: Bộ
A31: HH068735 | B31: HINO | C31: Bạc miểng H06B-T/H06C/H07C Cos0 - NDC | D31: 110 | E31: Cos0 | F31: Baze+Dên | G31: NDC | H31: Bộ | P31: Bạc miểng H06B-T/H06C/H07C Cos0 - NDC
B32: HINO | C32: Bạc Miểng H06B-T/H06C/H07C | D32: 110 | E32: Cos1 | F32: Baze+Dên | H32: Bộ
B33: HINO | C33: Bạc Miểng H06B-T/H06C/H07C | D33: 110 | E33: Cos2 | F33: Baze+Dên | H33: Bộ
B34: HINO | C34: Bạc Miểng H06B-T/H06C/H07C | D34: 110 | E34: Cos3 | F34: Baze+Dên | H34: Bộ
B35: HINO | C35: Bạc Miểng H06B-T/H06C/H07C | D35: 110 | E35: Cos4 | F35: Baze+Dên | H35: Bộ
A36: HH00587 | B36: HINO | C36: Bạc miểng H06C/H07C Cos0 - TaiHo | D36: 110 | E36: Cos0 | F36: Baze+Dên | G36: TAIHO | H36: Bộ | P36: Bạc miểng H06C/H07C Cos0 - TaiHo
A37: HH071871 | B37: HINO | C37: Bạc miểng H06C/H07C Cos1 - TaiHo | D37: 110 | E37: Cos1 | F37: Baze+Dên | G37: TAIHO | H37: Bộ | P37: Bạc miểng H06C/H07C Cos1 - TaiHo
B38: HINO | C38: Bạc Miểng H06C/H07C | D38: 110 | E38: Cos2 | F38: Baze+Dên | H38: Bộ
A39: HH071381 | B39: HINO | C39: Bạc miểng H06C/H07C Cos3 - TaiHo | D39: 110 | E39: Cos3 | F39: Baze+Dên | G39: TAIHO | H39: Bộ | P39: Bạc miểng H06C/H07C Cos3 - TaiHo
A40: HH081206 | B40: HINO | C40: Bạc miểng H06C/H07C Cos4 - TaiHo | D40: 110 | E40: Cos4 | F40: Baze+Dên | G40: TAIHO | H40: Bộ | P40: Bạc miểng H06C/H07C Cos4 - TaiHo
...

Sheet 🔍 MIỂNG TRA CỨU
A1: 🔍 MIỂNG TRA CỨU — chuyển từ v10 (điền Mã HH + giá để vào Báo giá)
A2: 🏭 Hãng | B2: ⚙️ Mã ĐC | C2: 📐 ĐK | D2: Loại | E2: Tên loại | F2: PARNO | G2: Cung trong | H2: Cung ngoài | I2: Cao | J2: Dày | K2: 📦 ĐVT | L2: 🏷️ Mã HH | M2: 🏷️ TH SX | N2: 💰 Vốn | O2: 🟢 VIP | P2: 🟡 Ưu đãi | Q2: 🔵 Đại lý | R2: 🟣 Gara | S2: 📦 Tồn
A3: CATERPILLAR | B3: 1140/1145/1150/1160/3145/3150/3160 | D3: M | E3: Miểng baze | F3: 4W8091 | H3: 94.195 | I3: 25.4 | J3: 2.604 | K3: Bộ | S3: 🟢 CÓ
A4: CATERPILLAR | B4: 1140/1145/1150/1160/3145/3150/3160 | D4: R | E4: Miểng dên | F4: 9N5923 | H4: 73.74 | I4: 24.3 | J4: 2.407 | K4: Bộ | S4: 🟢 CÓ
A5: CATERPILLAR | B5: 3013C | D5: M | E5: Miểng baze | H5: 72.02 | I5: 19.5 | J5: 2 | K5: Bộ | S5: 🟢 CÓ
A6: CATERPILLAR | B6: 3013C | D6: R | E6: Miểng dên | H6: 55.02 | I6: 19.75 | J6: 1.5 | K6: Bộ | S6: 🟢 CÓ
A7: CATERPILLAR | B7: 3024/3024T | D7: M | E7: Miểng baze | H7: 72.02 | I7: 19.5 | J7: 2 | K7: Bộ | S7: 🟢 CÓ
A8: CATERPILLAR | B8: 3114 | C8: 105 | D8: M | E8: Miểng baze | F8: 101-1530 | H8: 95.015 | I8: 31.8 | J8: 2.44 | K8: Bộ | S8: 🟢 CÓ
A9: CATERPILLAR | B9: 3114 | C9: 105 | D9: R | E9: Miểng dên | F9: 7W9415 | H9: 75.014 | I9: 33.8 | J9: 2.465 | K9: Bộ | S9: 🟢 CÓ
A10: CATERPILLAR | B10: 3114/3116/3126 | C10: 105/110 | D10: M | E10: Miểng baze | F10: 107-7708 | H10: 95.015 | I10: 31.8 | J10: 2.44 | K10: Bộ | S10: 🟢 CÓ
A11: CATERPILLAR | B11: 3114/3116/3126 | C11: 105/110 | D11: R | E11: Miểng dên | F11: 7W9415 | H11: 75.014 | I11: 33.8 | J11: 2.465 | K11: Bộ | S11: 🟢 CÓ
A12: CATERPILLAR | B12: 3116 | C12: 105 | D12: M | E12: Miểng baze | F12: 101-1530 | H12: 95.015 | I12: 31.8 | J12: 2.44 | K12: Bộ | S12: 🟢 CÓ
A13: CATERPILLAR | B13: 3116 | C13: 105 | D13: R | E13: Miểng dên | F13: 7W9415 | H13: 75.014 | I13: 33.8 | J13: 2.465 | K13: Bộ | S13: 🟢 CÓ
A14: CATERPILLAR | B14: 3126 | C14: 110 | D14: M | E14: Miểng baze | F14: 107-7708 | H14: 95.015 | I14: 31.8 | J14: 2.44 | K14: Bộ | S14: 🟢 CÓ
A15: CATERPILLAR | B15: 3126 | C15: 110 | D15: R | E15: Miểng dên | F15: 7W9415 | H15: 75.014 | I15: 33.8 | J15: 2.465 | K15: Bộ | S15: 🟢 CÓ
A16: CATERPILLAR | B16: 3145/3150/3160 | D16: M | E16: Miểng baze | F16: 4W8091 | H16: 94.195 | I16: 25.4 | J16: 2.604 | K16: Bộ | S16: 🟢 CÓ
A17: CATERPILLAR | B17: 3145/3150/3160 | D17: R | E17: Miểng dên | F17: 9N5923 | H17: 73.74 | I17: 24.3 | J17: 2.407 | K17: Bộ | S17: 🟢 CÓ
A18: CATERPILLAR | B18: 3176 | D18: M | E18: Miểng baze | F18: 7W4107 | H18: 108.014 | I18: 35.8 | J18: 3.955 | K18: Bộ | S18: 🟢 CÓ
A19: CATERPILLAR | B19: 3176 | D19: R | E19: Miểng dên | F19: 4P8167 | H19: 86.812 | I19: 43.3 | J19: 2.363 | K19: Bộ | S19: 🟢 CÓ
A20: CATERPILLAR | B20: 3204 | D20: M | E20: Miểng baze | F20: 4W8093 | H20: 94.195 | I20: 25.4 | J20: 2.604 | K20: Bộ | S20: 🟢 CÓ
A21: CATERPILLAR | B21: 3204 | D21: R | E21: Miểng dên | F21: 8N6308 | H21: 96.2 | I21: 49.1 | J21: 3.058 | K21: Bộ | S21: 🟢 CÓ
A22: CATERPILLAR | B22: 3406/3408/3412 | D22: M | E22: Miểng baze | F22: 4W5492 | H22: 129.903 | I22: 41.8 | J22: 4.58 | K22: Bộ | S22: 🟢 CÓ
A23: CATERPILLAR | B23: 3406/3408/3412 | D23: R | E23: Miểng dên | F23: 9Y9497 | H23: 103.512 | I23: 39 | J23: 3.195 | K23: Bộ | S23: 🟢 CÓ
A24: CATERPILLAR | B24: 3508 | D24: M | E24: Miểng baze | F24: 149-6031 | H24: 169.762 | I24: 57.1 | J24: 4.805 | K24: Bộ | S24: 🟢 CÓ
A25: CATERPILLAR | B25: 3508 | D25: R | E25: Miểng dên | F25: 107-7330 | H25: 143.043 | I25: 57.1 | J25: 3.955 | K25: Bộ | S25: 🟢 CÓ
A26: CATERPILLAR | B26: 3512 | D26: M | E26: Miểng baze | F26: 105-0253 | H26: 169.762 | I26: 57.1 | J26: 4.805 | K26: Bộ | S26: 🟢 CÓ
A27: CATERPILLAR | B27: 3512 | D27: R | E27: Miểng dên | F27: 107-7330 | H27: 143.043 | I27: 57.1 | J27: 3.955 | K27: Bộ | S27: 🟢 CÓ
... A29: CATERPILLAR | B29: C6.4 | D29: R | E29: Miểng dên | F29: 297-1748 | H29: 69.02 | I29: 27.6 | J29: 2 | K29: Bộ | S29: 🟢 CÓ
A30: CATERPILLAR | B30: C6.6 | C30: 105 | D30: M | E30: Miểng baze | F30: 211-0588 | H30: 116.013 | I30: 35.7 | J30: 3.952 | K30: Bộ | S30: 🟢 CÓ
A31: CATERPILLAR | B31: C6.6 | C31: 105 | D31: R | E31: Miểng dên | F31: 217-0577 | H31: 86.813 | I31: 45.3 | J31: 2.368 | K31: Bộ | S31: 🟢 CÓ
A32: CATERPILLAR | B32: C7 | D32: R | E32: Miểng dên | F32: M2246638-6 | H32: 75.013 | I32: 33.8 | J32: 2.465 | K32: Bộ | S32: 🟢 CÓ
A33: CATERPILLAR | B33: C9 537 | C33: 112 | D33: M | E33: Miểng baze | F33: 151-2939 | H33: 112.013 | I33: 30.7 | J33: 3.952 | K33: Bộ | S33: 🟢 CÓ
A34: CATERPILLAR | B34: C9 537 | C34: 112 | D34: R | E34: Miểng dên | F34: 213-3190 | H34: 85.013 | I34: 36.6 | J34: 2.469 | K34: Bộ | S34: 🟢 CÓ
A35: CATERPILLAR | B35: D315/D315G/D318/D318G | D35: M | E35: Miểng baze | F35: 4F1726 | H35: 107.963 | I35: 69.5 | J35: 9.45 | K35: Bộ | S35: 🟢 CÓ
A36: CATERPILLAR | B36: D315/D315G/D318/D318G | D36: R | E36: Miểng dên | F36: 9F8580 | H36: 84.557 | I36: 38.1 | J36: 4.13 | K36: Bộ | S36: 🟢 CÓ
A37: CATERPILLAR | B37: D330/D333/G333/D334/3304/3306/C3306 | D37: M | E37: Miểng baze | F37: 4W5738 | H37: 96.926 | I37: 28.7 | J37: 3.988 | K37: Bộ | S37: 🟢 CÓ
A38: CATERPILLAR | B38: D330/D333/G333/D334/3304/3306/C3306 | D38: R | E38: Miểng dên | F38: 9F8580 | H38: 84.55 | I38: 38.1 | J38: 4.13 | K38: Bộ | S38: 🟢 CÓ
A39: CATERPILLAR | B39: D339 | D39: M | E39: Miểng baze | F39: 8N7928 | H39: 117.474 | I39: 82.6 | J39: 4.572 | K39: Bộ | S39: 🟢 CÓ
A40: CATERPILLAR | B40: D339 | D40: R | E40: Miểng dên | F40: 8N7933 | H40: 100.774 | I40: 50.8 | J40: 4.3 | K40: Bộ | S40: 🟢 CÓ
A41: CATERPILLAR | B41: D339/D342/G342/D7/D7C/D7D/D7E | C41: 108 | D41: M | E41: Miểng baze | F41: 9M2430 | H41: 104.515 | I41: 82.7 | J41: 4.572 | K41: Bộ | S41: 🟢 CÓ
...

Sheet 🔧 BẠC THAU
A1: 🔧 BẠC THAU — nhập 16/06/2026 (điền giá vào Vốn/VIP/Ưu đãi/Đại lý/Gara)
A2: Mã HH | B2: Tên vật tư | C2: 📐 ĐK | D2: ĐVT | E2: Vốn | F2: VIP | G2: Ưu đãi | H2: Đại lý | I2: Gara | J2: Tồn | K2: PARNO | L2: Ghi chú
A3: HH0635 | B3: Bạc thau 4BB1/4BD1/4BG1 - TAIHO | C3: 102/105 | D3: Cái
A4: HH01076 | B4: Bạc thau 4BT - IVECO | C4: 102 | D4: Cái
A5: HH082040 | B5: Bạc thau 4D120/ 4D130 đã xoáy-Taiho (1 bộ xuất 8 cái) | C5: 120/130 | D5: Cái
A6: HH00087 | B6: Bạc thau 4D30/4D31/4D32/6D31 | C6: 100/104 | D6: Cái
A7: HH00510 | B7: Bạc thau 4D30/4D31/4D32/S4KT - NDC | C7: 100/102/104 | D7: Cái
A8: HH0323 | B8: Bạc thau 4D30/4D31/4D32/S4KT - TAIHO | C8: 100/102/104 | D8: Cái | H8: 40000
A9: HH071412 | B9: Bạc thau 4D33/4D31/D4AE/4D34 (ắc 34)- TAIHO | C9: 100/104/108 | D9: Cái | H9: 40000
A10: HH071413 | B10: Bạc thau 4D35/ 4D34 (ắc 36) / 6D34 - TAIHO | C10: 104/110 | D10: Cái | H10: 62500
A11: HH081210 | B11: Bạc thau 4D55/ 4D56 (chưa xoáy) | C11: 91.1 | D11: Cái
A12: HH081209 | B12: Bạc thau 4D55/ 4D56 (xoáy rồi) | C12: 91.1 | D12: Cái
A13: HH00036 | B13: Bạc thau 4D92/4D94 - NDC | C13: 92/94 | D13: Cái
A14: HH071422 | B14: Bạc thau 4D92/4D94 - TAIHO | C14: 92/94 | D14: Cái
A15: HH071427 | B15: Bạc thau 4HG1/4HH1/4HE1/4HF1 - TAIHO | C15: 112 | D15: Cái | G15: 62500 | H15: 70000
A16: HH00057 | B16: Bạc thau 4JA1/4JB1 ắc 31 | C16: 93 | D16: Cái | G16: 30000 | H16: 35000
A17: HH076319 | B17: Bạc thau 4JA1/4JB1 ắc 31 - TDC P450L | C17: 93 | D17: Cái | G17: 30000 | H17: 35000
A18: HH078363 | B18: Bạc thau 4JB1/4JA1 chưa xoáy ắc 31 - CS IVECO | C18: 93 | D18: Cái | G18: 30000 | H18: 35000
A19: HH076604 | B19: Bạc thau 4JB1/4JG1/4JG2 chưa xoáy ắc 34 - CS IVECO | C19: 93/95.4 | D19: Cái | G19: 25000 | H19: 30000
A20: HH01078 | B20: Bạc thau 6BT - IVECO | C20: 102 | D20: Cái
A21: HH01079 | B21: Bạc thau 6CT | C21: 114 | D21: Cái | G21: 45000 | H21: 50000
A22: HH071423 | B22: Bạc thau 6D105/ S6D105/ S4D105-5 ắc 40 - TAIHO | C22: 105 | D22: Cái | H22: 50000
A23: HH00143 | B23: Bạc thau 6D105-1/S6D110 dên xéo - NDC | C23: 105/110 | D23: Cái
A24: HH076609 | B24: Bạc thau 6D107/6D102/4D102/6BT/4BT chưa xoáy - CS IVECO | C24: 102/107 | D24: Cái
A25: HH071426 | B25: Bạc thau 6D107/6D102/4D102/6BT/4BT/S6D107/S6D102/S4D102 - TAIHO | C25: 102/107 | D25: Cái | H25: 100000
A26: HH075680 | B26: Bạc thau 6D107/6D102/4D102/6BT/4BT/S6D107/S6D102/S4D102 loại bán hoàn thiện | C26: 102/107 | D26: Cái | G26: 50000 | H26: 60000
A27: HH00365 | B27: Bạc thau 6D125 | D27: Cái
A28: HH0217 | B28: Bạc thau 6D15T/16T/17T/NE6TA | C28: 110 | D28: Cái
A29: HH071415 | B29: Bạc thau 6D15T/6D16T/6D17T dên xéo, lưng 42 - TAIHO | C29: 118 | D29: Cái | H29: 75000
A30: HH00188 | B30: Bạc thau 6D16/6D105/4D105 size 38 | C30: 105 | D30: Cái
A31: HH00287 | B31: Bạc thau 6D16/6D15/6D14/6D11/6D10/4D105 phi 38 lưng 41 - TAIHO | C31: 105/113 | D31: Cái | G31: 50000 | H31: 60000
A32: HH20486 | B32: Bạc thau 6D16T/ 6M60T lưng 42 dên xéo | C32: 118 | D32: Cái
A33: HH076608 | B33: Bạc thau 6D20/6D21/6D22/6D24 chưa xoáy - CS IVECO | C33: 125 | D33: Cái
A34: HH084105 | B34: Bạc thau 6D20/6D21/6D22/6D24 chưa xoáy - ĐL | C34: 125 | D34: Cái
A35: HH071429 | B35: Bạc thau 6D31 (P903H) ắc 34 - TAIHO | D35: Cái | H35: 60000
A36: HH00046 | B36: Bạc thau 6D34/ 4D34 ắc 36 (lắp lẫn DB58 ắc 36) | C36: 102/104 | D36: Cái
A37: HH00038 | B37: Bạc thau 6D95L/6D95 - NDC | D37: Cái
A38: HH071425 | B38: Bạc thau 6D95L/6D95 - TAIHO | D38: Cái | G38: 40000 | H38: 45000
A39: HH071428 | B39: Bạc thau 6HG1/6HH1/6HE1/6HF1 - TAIHO | C39: 110/115 | D39: Cái | H39: 70000
A40: HH080598 | B40: Bạc thau 6HG1/6HH1/6HE1/6HF1 -ĐL | C40: 110/115 | D40: Cái
...

Sheet 📏 CĂN DỌC
A1: 📏 CĂN DỌC — nhập 16/06/2026 (điền giá vào Vốn/VIP/Ưu đãi/Đại lý/Gara)
A2: Mã HH | B2: Tên vật tư | C2: 📐 ĐK | D2: ĐVT | E2: Vốn | F2: VIP | G2: Ưu đãi | H2: Đại lý | I2: Gara | J2: Tồn | K2: PARNO | L2: Ghi chú
A3: HH080557 | B3: Căn dọc 1DZ Cos0 - TDC - T9383A | C3: 86 | D3: Bộ | F3: 55000 | G3: 60000 | H3: 70000
A4: HH080558 | B4: Căn dọc 1DZ Cos1 - TDC - T9383A | C4: 86 | D4: Bộ | F4: 55000 | G4: 60000 | H4: 70000
A5: HH074817 | B5: Căn dọc 2J Cos0 | C5: 88 | D5: Bộ
A6: HH073964 | B6: Căn dọc 2J Cos1 | C6: 88 | D6: Bộ
A7: HH078932 | B7: Căn dọc 3306/ 3304 cos0 - TDC TW1110K2 | D7: Bộ | F7: 300000 | G7: 330000 | H7: 360000
A8: HH080513 | B8: Căn dọc 3D84/4D84/3TN84/4TN84/3D88/4D88/3TN88/4TN88 - Cos0 - TDC - T894A | C8: 84/88 | D8: Bộ | F8: 60000 | G8: 70000 | H8: 80000
A9: HH076341 | B9: Căn dọc 3D84/4D84/3TN84/4TN84/3D88/4D88/3TN88/4TN88 - Cos0 - TDC T-TNE84A | C9: 84/88 | D9: Bộ | F9: 50000 | G9: 60000 | H9: 70000
A10: HH078969 | B10: Căn dọc 3D84/4D84/3TN84/4TN84/3D88/4D88/3TN88/4TN88 - Cos1 - TDC T-TNE84A | C10: 84/88 | D10: Bộ | F10: 50000 | G10: 60000 | H10: 70000
A11: HH078970 | B11: Căn dọc 3D84/4D84/3TN84/4TN84/3D88/4D88/3TN88/4TN88 - Cos2 - TDC T-TNE84A | C11: 84/88 | D11: Bộ | F11: 60000 | G11: 70000 | H11: 80000
A12: HH082837 | B12: Căn dọc 3TNE78/ 3TN78/ 3TNE82/ 3D82 (T-TNE78A) - Cos0 - TDC | C12: 78/82 | D12: Cặp | F12: 50000 | G12: 60000 | H12: 70000
A13: HH082838 | B13: Căn dọc 3TNE78/ 3TN78/ 3TNE82/ 3D82 (T-TNE78A) - Cos1 - TDC | C13: 78/82 | D13: Cặp | F13: 50000 | G13: 60000 | H13: 70000
A14: HH076909 | B14: Căn dọc 490QB Cos0 | D14: Bộ
A15: HH079868 | B15: Căn dọc 4D105-3/ 4D105-1 Cos0 - CS IVECO | C15: 105 | D15: Bộ | F15: 50000 | G15: 60000 | H15: 70000
A16: HH079869 | B16: Căn dọc 4D105-3/ 4D105-1 Cos1 - CS IVECO | C16: 105 | D16: Bộ | F16: 50000 | G16: 60000 | H16: 70000
A17: HH00309 | B17: Căn dọc 4D105-3/4D105-1 Cos0 | C17: 105 | D17: Bộ
A18: HH079854 | B18: Căn dọc 4D105-5/ 6D105/ S6D105/ 6D110 Cos0 - CS IVECO | C18: 105 | D18: Bộ | F18: 50000 | G18: 60000 | H18: 70000
A19: HH079855 | B19: Căn dọc 4D105-5/ 6D105/ S6D105/ 6D110 Cos1 - CS IVECO | C19: 105 | D19: Bộ | F19: 50000 | G19: 60000 | H19: 70000
A20: HH00319 | B20: Căn dọc 4D105-5/6D105/S6D105/6D110 Cos0 | C20: 105 | D20: Bộ
A21: HH076331 | B21: Căn dọc 4D120/4D130 cos0 - TDC T852P | C21: 120/130 | D21: Bộ | F21: 460000 | G21: 500000 | H21: 550000
A22: HH079876 | B22: Căn dọc 4D30/ 4D31/ 4D32/ 6D31/ 6DS7 Cos0 - CS IVECO | C22: 98/100/104 | D22: Bộ
A23: HH079877 | B23: Căn dọc 4D30/ 4D31/ 4D32/ 6D31/ 6DS7 Cos1 - CS IVECO | C23: 98/100/104 | D23: Bộ | F23: 50000 | G23: 60000 | H23: 70000
A24: HH00292 | B24: Căn dọc 4D30/4D31/4D32/6D31/6DS7 Cos0 | C24: 98/100/104 | D24: Bộ
A25: HH00291 | B25: Căn dọc 4D30/4D31/4D32/6D31/6DS7 Cos1 | C25: 98/100/104 | D25: Bộ
A26: HH071300 | B26: Căn dọc 4D30/4D31/4D32/6D31/6DS7 Cos2 | C26: 98/100/104 | D26: Bộ
A27: HH00293 | B27: Căn dọc 4D34/6D34 Cos0 | C27: 104 | D27: Bộ
A28: HH080556 | B28: Căn dọc 4D56-Ti cos0 - TDC - T7278A | D28: Bộ | F28: 40000 | G28: 50000 | H28: 60000
A29: HH079862 | B29: Căn dọc 4D92/ 4D94 - Cos0 - CS IVECO | C29: 92/94 | D29: Bộ | F29: 40000 | G29: 50000 | H29: 60000
A30: HH079863 | B30: Căn dọc 4D92/ 4D94 - Cos1 - CS IVECO | C30: 92/94 | D30: Bộ | F30: 40000 | G30: 50000 | H30: 60000
A31: HH00106 | B31: Căn dọc 4D92/4D94 - Cos0 | C31: 92/94 | D31: Bộ
A32: HH00107 | B32: Căn dọc 4D92/4D94 - Cos1 | C32: 92/94 | D32: Bộ
A33: HH00523 | B33: Căn dọc 4D92/4D94 - Cos3 | C33: 92/94 | D33: Bộ
A34: HH074284 | B34: Căn dọc 4D94E/4TN94 - Cos0 | C34: 94 | D34: Bộ
A35: HH074551 | B35: Căn dọc 4D94E/4TN94 - Cos1 | C35: 94 | D35: Bộ
A36: HH074552 | B36: Căn dọc 4D94E/4TN94 - Cos2 | C36: 94 | D36: Bộ
A37: HH078971 | B37: Căn dọc 4D94E/4TNV94/4TNE94 - Cos0 - TDC - T851A | C37: 94 | D37: Bộ | F37: 60000 | G37: 70000 | H37: 80000
A38: HH079870 | B38: Căn dọc 4D95/ 6D95 Cos0 - CS IVECO | C38: 95 | D38: Bộ
A39: HH00104 | B39: Căn dọc 4D95/6D95 Cos0 | C39: 95 | D39: Bộ
A40: HH078958 | B40: Căn dọc 4D95/6D95 Cos0 - TDC - T888L | C40: 95 | D40: Bộ
...

Sheet 📚 CHÚ GIẢI
B1: 📚 CHÚ GIẢI KÝ HIỆU
B2: Ký hiệu | C2: Ý nghĩa
B3: (A) | C3: Có kiềng gang
B4: (A+0) | C4: Lỗ làm mát chân không
B5: F/F | C5: Xy lanh đã xoáy
B6: S/F | C6: Xy lanh chưa xoáy (luôn có thông số)
B7: Kiếng | C7: Xy lanh gốc hãng → séc măng KHÔNG mạ
B8: Gang | C8: Xy lanh thay thế → séc măng CÓ mạ
B9: STD | C9: Cốt 0 (zin)
B10: 0.25 | C10: Cốt 1
B11: 0.50 | C11: Cốt 2
B12: 0.75 | C12: Cốt 3
B13: 1.0 | C13: Cốt 4
B14: Mã HH | C14: Mã hàng hóa trong kho
B16: 🏷️ THƯƠNG HIỆU — XUẤT XỨ
B17: Thương hiệu | C17: Xuất xứ
B18: NPR | C18: Nhật Bản
B19: RIK (Rikken) | C19: Nhật Bản
B20: TP | C20: Nhật Bản
B21: IKAZU | C21: Trung Quốc xuất Châu Âu
B22: IZUMI | C22: Trung Quốc xuất Châu Âu
B23: HENWEIT | C23: Trung Quốc xuất Châu Âu
B24: NSP | C24: Châu Âu
B25: MAHLE | C25: Đức
B26: PROXMANN | C26: (bổ sung)
B28: TIẾNG ANH | C28: TIẾNG VIỆT
B29: ★ Từ điển thuật ngữ kỹ thuật động cơ diesel | A → Z
B30: A — (3 thuật ngữ)
B31: Air Cleaner Assy | C31: Bầu Lọc Gió
B32: Altennator | C32: Máy Phát
B33: Arm Rocker | C33: Nguyên Giàn Cò
B34: B — (3 thuật ngữ)
B35: B | C35: Balance Shaft Bushing Set
B36: Belt | C36: Cây Cu Roa
B37: Bolt | C37: Bulon Nắp Quy Lát
B38: C — (17 thuật ngữ)
B39: C | C39: Camshaft Bearing Set
B40: Camshaft | C40: Trục Cam
B41: Camshaft Drive Belt | C41: Dây Cu Roa Trục Cam
B42: Camshaft Sprocket | C42: Nhông Cam
...

Sheet _LOOKUP_VND
A1: Số | B1: Chữ_Giữa | C1: Chữ_Đầu
A2: 0
A3: 1 | B3: không trăm lẻ một | C3: một
A4: 2 | B4: không trăm lẻ hai | C4: hai
A5: 3 | B5: không trăm lẻ ba | C5: ba
A6: 4 | B6: không trăm lẻ bốn | C6: bốn
A7: 5 | B7: không trăm lẻ năm | C7: năm
A8: 6 | B8: không trăm lẻ sáu | C8: sáu
A9: 7 | B9: không trăm lẻ bảy | C9: bảy
A10: 8 | B10: không trăm lẻ tám | C10: tám
A11: 9 | B11: không trăm lẻ chín | C11: chín
A12: 10 | B12: không trăm mười | C12: mười
A13: 11 | B13: không trăm mười một | C13: mười một
A14: 12 | B14: không trăm mười hai | C14: mười hai
... A1001: 999 | B1001: chín trăm chín mươi chín | C1001: chín trăm chín mươi chín

Sheet 🔩 PISTON
A1: 🔩 PISTON —
A2: 🏷️ Mã HH | B2: 🏭 Hãng | C2: ⚙️ Mã ĐC | D2: 📐 ĐK | E2: 🔖 Ký hiệu | F2: Buồng nổ | G2: Ắc | H2: Ắc đỉnh | I2: Tổng dài | J2: Ring 1-5 | K2: 🏷️ Thương hiệu | L2: 📦 ĐVT | M2: 💰 Vốn | N2: 🟢 VIP | O2: 🟡 Ưu đãi | P2: 🔵 Đại lý | Q2: 🟣 Gara | R2: 📦 Tồn | S2: 🔧 PARNO | T2: 📝 Ghi chú | U2: _KEY
B3: ◆ HINO (69 sản phẩm) | U3: =IF($C3="","",B3&" "&C3&" · ĐK"&D3&IF(E3=""," "," "&E3)&IF(K3=""," "," - "&K3))
