Workbook

Sheet DASHBOARD
B2: 📊 TURBO DIESEL — DASHBOARD TỔNG QUAN KHO HÀNG
B4: Tự động cập nhật từ file BÁO GIÁ TURBO · Nguồn: sheet 🚗 BÁO GIÁ TURBO
B6: TỔNG SKU TURBO | D6: ĐÃ CÓ MÃ VT | F6: THƯƠNG HIỆU ĐỦ | H6: TRÙNG MÃ VT | J6: BỔ SUNG KHÁC TH
B7: 424 | D7: 365 | F7: 336 | H7: 26 | J7: 233
D8: 86% | F8: 79% | H8: cần xem lại | J8: khác thương hiệu
B10: 🏭 TOP HÃNG MÁY (theo số loại Turbo) | G10: 🏷️ PHÂN BỔ THƯƠNG HIỆU
B11: HÃNG MÁY | C11: SỐ LOẠI | D11: TỶ LỆ | E11: BAR | G11: THƯƠNG HIỆU | H11: SỐ LOẠI | I11: TỶ LỆ | J11: BAR
B12: HYUNDAI | C12: 68 | D12: 16.0% | E12: ████████████ | G12: SL | H12: 157 | I12: 37.0% | J12: ██████████████
B13: CUMMINS | C13: 57 | D13: 13.4% | E13: ██████████ | G13: JRONE | H13: 63 | I13: 14.9% | J13: █████
B14: KOMATSU | C14: 44 | D14: 10.4% | E14: ███████ | G14: VIDARIR | H14: 45 | I14: 10.6% | J14: ████
B15: CAT | C15: 34 | D15: 8.0% | E15: ██████ | G15: TBS | H15: 18 | I15: 4.2% | J15: █
B16: ISUZU | C16: 34 | D16: 8.0% | E16: ██████ | G16: FIRE | H16: 15 | I16: 3.5% | J16: █
B17: HITACHI | C17: 31 | D17: 7.3% | E17: █████ | G17: EE | H17: 14 | I17: 3.3% | J17: █
B18: KOBELCO | C18: 19 | D18: 4.5% | E18: ███ | G18: MX | H18: 9 | I18: 2.1%
B19: DEUTZ | C19: 15 | D19: 3.5% | E19: ██ | G19: GARRETT | H19: 2 | I19: 0.5%
B20: FORD | C20: 15 | D20: 3.5% | E20: ██
B21: HINO | C21: 13 | D21: 3.1% | E21: ██
B22: PERKINS | C22: 12 | D22: 2.8% | E22: ██ | G22: ⚙️ HÃNG SẢN XUẤT TURBO
B23: NISSAN | C23: 11 | D23: 2.6% | E23: █ | G23: HÃNG SX | H23: SỐ LOẠI | I23: TỶ LỆ | J23: BAR
G24: Garrett | H24: 121 | I24: 28.5% | J24: ██████████████
G25: Holset | H25: 82 | I25: 19.3% | J25: █████████
B26: ✅ CHẤT LƯỢNG DỮ LIỆU | G26: IHI | H26: 81 | I26: 19.1% | J26: █████████
B27: TRƯỜNG | C27: ĐÃ ĐIỀN | D27: TỔNG | E27: HOÀN THÀNH | G27: Mitsubishi | H27: 73 | I27: 17.2% | J27: ████████
B28: OEM PART NO | C28: 424 | D28: 424 | E28: 100.0% | G28: BorgWarner | H28: 59 | I28: 13.9% | J28: ██████
B29: MÃ VT | C29: 365 | D29: 424 | E29: 86.1%
B30: THƯƠNG HIỆU | C30: 336 | D30: 424 | E30: 79.2%
B31: TRÙNG MÃ VT | C31: 26 | D31: 365 | E31: 7.1%
B35: Cập nhật lần cuối: từ file MÃ_VT_TURBO.xls · Tổng bổ sung thêm 233 dòng khác thương hiệu · Bản dành cho Claude Projects

Sheet TRA CỨU TỔNG HỢP
A1: 🔎 TRA CỨU TỔNG HỢP — TURBO & RUỘT TURBO
A3: 🔍 GÕ TÌM: | F3: ↳ Gõ MÃ VT / OEM / Model / Mã động cơ / Hãng máy — Enter để hiện
A4: Turbo khớp: | B4: =IF($B$3="",0,COUNT('🚗 BÁO GIÁ TURBO '!$W$4:$W$690)) | C4: Ruột khớp: | D4: =IF($B$3="",0,COUNT('RUỘT TURBO'!$U$4:$U$892)) | E4: (Hiển thị tối đa 20 dòng mỗi loại — nếu nhiều hơn, gõ thêm ký tự cho gọn)
A6: 🚗 TURBO (kết quả tra cứu — tối đa 20 dòng)
A7: HÃNG MÁY | B7: MÃ VT | C7: MODEL TURBO | D7: MÃ ĐỘNG CƠ | E7: OEM PART NO | F7: ĐẶC ĐIỂM | G7: ỨNG DỤNG | H7: GHI CHÚ | I7: THƯƠNG HIỆU
A8: =IFERROR(IF(INDEX('🚗 BÁO GIÁ TURBO '!$A$4:$A$690,MATCH(1,'🚗 BÁO GIÁ TURBO '!$W$4:$W$690,0))="","",INDEX('🚗 BÁO GIÁ TURBO '!$A$4:$A$690,MATCH(1,'🚗 BÁO GIÁ TURBO '!$W$4:$W$690,0))),"") | B8: =IFERROR(IF(INDEX('🚗 BÁO GIÁ TURBO '!$B$4:$B$690,MATCH(1,'🚗 BÁO GIÁ TURBO '!$W$4:$W$690,0))="","",INDEX('🚗 BÁO GIÁ TURBO '!$B$4:$B$690,MATCH(1,'🚗 BÁO GIÁ TURBO '!$W$4:$W$690,0))),"") | C8: =IFERROR(IF(INDEX('🚗 BÁO GIÁ TURBO '!$D$4:$D$690,MATCH(1,'🚗 BÁO GIÁ TURBO '!$W$4:$W$690,0))="","",INDEX('🚗 BÁO GIÁ TURBO '!$D$4:$D$690,MATCH(1,'🚗 BÁO GIÁ TURBO '!$W$4:$W$690,0))),"") | D8: =IFERROR(IF(INDEX('🚗 BÁO GIÁ TURBO '!$E$4:$E$690,MATCH(1,'🚗 BÁO GIÁ TURBO '!$W$4:$W$690,0))="","",INDEX('🚗 BÁO GIÁ TURBO '!$E$4:$E$690,MATCH(1,'🚗 BÁO GIÁ TURBO '!$W$4:$W$690,0))),"") | E8: =IFERROR(IF(INDEX('🚗 BÁO GIÁ TURBO '!$F$4:$F$690,MATCH(1,'🚗 BÁO GIÁ TURBO '!$W$4:$W$690,0))="","",INDEX('🚗 BÁO GIÁ TURBO '!$F$4:$F$690,MATCH(1,'🚗 BÁO GIÁ TURBO '!$W$4:$W$690,0))),"") | F8: =IFERROR(IF(INDEX('🚗 BÁO GIÁ TURBO '!$G$4:$G$690,MATCH(1,'🚗 BÁO GIÁ TURBO '!$W$4:$W$690,0))="","",INDEX('🚗 BÁO GIÁ TURBO '!$G$4:$G$690,MATCH(1,'🚗 BÁO GIÁ TURBO '!$W$4:$W$690,0))),"") | G8: =IFERROR(IF(INDEX('🚗 BÁO GIÁ TURBO '!$H$4:$H$690,MATCH(1,'🚗 BÁO GIÁ TURBO '!$W$4:$W$690,0))="","",INDEX('🚗 BÁO GIÁ TURBO '!$H$4:$H$690,MATCH(1,'🚗 BÁO GIÁ TURBO '!$W$4:$W$690,0))),"") | H8: =IFERROR(IF(INDEX('🚗 BÁO GIÁ TURBO '!$I$4:$I$690,MATCH(1,'🚗 BÁO GIÁ TURBO '!$W$4:$W$690,0))="","",INDEX('🚗 BÁO GIÁ TURBO '!$I$4:$I$690,MATCH(1,'🚗 BÁO GIÁ TURBO '!$W$4:$W$690,0))),"") | I8: =IFERROR(IF(INDEX('🚗 BÁO GIÁ TURBO '!$J$4:$J$690,MATCH(1,'🚗 BÁO GIÁ TURBO '!$W$4:$W$690,0))="","",INDEX('🚗 BÁO GIÁ TURBO '!$J$4:$J$690,MATCH(1,'🚗 BÁO GIÁ TURBO '!$W$4:$W$690,0))),"")
A9: =IFERROR(IF(INDEX('🚗 BÁO GIÁ TURBO '!$A$4:$A$690,MATCH(2,'🚗 BÁO GIÁ TURBO '!$W$4:$W$690,0))="","",INDEX('🚗 BÁO GIÁ TURBO '!$A$4:$A$690,MATCH(2,'🚗 BÁO GIÁ TURBO '!$W$4:$W$690,0))),"") | B9: =IFERROR(IF(INDEX('🚗 BÁO GIÁ TURBO '!$B$4:$B$690,MATCH(2,'🚗 BÁO GIÁ TURBO '!$W$4:$W$690,0))="","",INDEX('🚗 BÁO GIÁ TURBO '!$B$4:$B$690,MATCH(2,'🚗 BÁO GIÁ TURBO '!$W$4:$W$690,0))),"") | C9: =IFERROR(IF(INDEX('🚗 BÁO GIÁ TURBO '!$D$4:$D$690,MATCH(2,'🚗 BÁO GIÁ TURBO '!$W$4:$W$690,0))="","",INDEX('🚗 BÁO GIÁ TURBO '!$D$4:$D$690,MATCH(2,'🚗 BÁO GIÁ TURBO '!$W$4:$W$690,0))),"") | D9: =IFERROR(IF(INDEX('🚗 BÁO GIÁ TURBO '!$E$4:$E$690,MATCH(2,'🚗 BÁO GIÁ TURBO '!$W$4:$W$690,0))="","",INDEX('🚗 BÁO GIÁ TURBO '!$E$4:$E$690,MATCH(2,'🚗 BÁO GIÁ TURBO '!$W$4:$W$690,0))),"") | E9: =IFERROR(IF(INDEX('🚗 BÁO GIÁ TURBO '!$F$4:$F$690,MATCH(2,'🚗 BÁO GIÁ TURBO '!$W$4:$W$690,0))="","",INDEX('🚗 BÁO GIÁ TURBO '!$F$4:$F$690,MATCH(2,'🚗 BÁO GIÁ TURBO '!$W$4:$W$690,0))),"") | F9: =IFERROR(IF(INDEX('🚗 BÁO GIÁ TURBO '!$G$4:$G$690,MATCH(2,'🚗 BÁO GIÁ TURBO '!$W$4:$W$690,0))="","",INDEX('🚗 BÁO GIÁ TURBO '!$G$4:$G$690,MATCH(2,'🚗 BÁO GIÁ TURBO '!$W$4:$W$690,0))),"") | G9: =IFERROR(IF(INDEX('🚗 BÁO GIÁ TURBO '!$H$4:$H$690,MATCH(2,'🚗 BÁO GIÁ TURBO '!$W$4:$W$690,0))="","",INDEX('🚗 BÁO GIÁ TURBO '!$H$4:$H$690,MATCH(2,'🚗 BÁO GIÁ TURBO '!$W$4:$W$690,0))),"") | H9: =IFERROR(IF(INDEX('🚗 BÁO GIÁ TURBO '!$I$4:$I$690,MATCH(2,'🚗 BÁO GIÁ TURBO '!$W$4:$W$690,0))="","",INDEX('🚗 BÁO GIÁ TURBO '!$I$4:$I$690,MATCH(2,'🚗 BÁO GIÁ TURBO '!$W$4:$W$690,0))),"") | I9: =IFERROR(IF(INDEX('🚗 BÁO GIÁ TURBO '!$J$4:$J$690,MATCH(2,'🚗 BÁO GIÁ TURBO '!$W$4:$W$690,0))="","",INDEX('🚗 BÁO GIÁ TURBO '!$J$4:$J$690,MATCH(2,'🚗 BÁO GIÁ TURBO '!$W$4:$W$690,0))),"")
A10: =IFERROR(IF(INDEX('🚗 BÁO GIÁ TURBO '!$A$4:$A$690,MATCH(3,'🚗 BÁO GIÁ TURBO '!$W$4:$W$690,0))="","",INDEX('🚗 BÁO GIÁ TURBO '!$A$4:$A$690,MATCH(3,'🚗 BÁO GIÁ TURBO '!$W$4:$W$690,0))),"") | B10: =IFERROR(IF(INDEX('🚗 BÁO GIÁ TURBO '!$B$4:$B$690,MATCH(3,'🚗 BÁO GIÁ TURBO '!$W$4:$W$690,0))="","",INDEX('🚗 BÁO GIÁ TURBO '!$B$4:$B$690,MATCH(3,'🚗 BÁO GIÁ TURBO '!$W$4:$W$690,0))),"") | C10: =IFERROR(IF(INDEX('🚗 BÁO GIÁ TURBO '!$D$4:$D$690,MATCH(3,'🚗 BÁO GIÁ TURBO '!$W$4:$W$690,0))="","",INDEX('🚗 BÁO GIÁ TURBO '!$D$4:$D$690,MATCH(3,'🚗 BÁO GIÁ TURBO '!$W$4:$W$690,0))),"") | D10: =IFERROR(IF(INDEX('🚗 BÁO GIÁ TURBO '!$E$4:$E$690,MATCH(3,'🚗 BÁO GIÁ TURBO '!$W$4:$W$690,0))="","",INDEX('🚗 BÁO GIÁ TURBO '!$E$4:$E$690,MATCH(3,'🚗 BÁO GIÁ TURBO '!$W$4:$W$690,0))),"") | E10: =IFERROR(IF(INDEX('🚗 BÁO GIÁ TURBO '!$F$4:$F$690,MATCH(3,'🚗 BÁO GIÁ TURBO '!$W$4:$W$690,0))="","",INDEX('🚗 BÁO GIÁ TURBO '!$F$4:$F$690,MATCH(3,'🚗 BÁO GIÁ TURBO '!$W$4:$W$690,0))),"") | F10: =IFERROR(IF(INDEX('🚗 BÁO GIÁ TURBO '!$G$4:$G$690,MATCH(3,'🚗 BÁO GIÁ TURBO '!$W$4:$W$690,0))="","",INDEX('🚗 BÁO GIÁ TURBO '!$G$4:$G$690,MATCH(3,'🚗 BÁO GIÁ TURBO '!$W$4:$W$690,0))),"") | G10: =IFERROR(IF(INDEX('🚗 BÁO GIÁ TURBO '!$H$4:$H$690,MATCH(3,'🚗 BÁO GIÁ TURBO '!$W$4:$W$690,0))="","",INDEX('🚗 BÁO GIÁ TURBO '!$H$4:$H$690,MATCH(3,'🚗 BÁO GIÁ TURBO '!$W$4:$W$690,0))),"") | H10: =IFERROR(IF(INDEX('🚗 BÁO GIÁ TURBO '!$I$4:$I$690,MATCH(3,'🚗 BÁO GIÁ TURBO '!$W$4:$W$690,0))="","",INDEX('🚗 BÁO GIÁ TURBO '!$I$4:$I$690,MATCH(3,'🚗 BÁO GIÁ TURBO '!$W$4:$W$690,0))),"") | I10: =IFERROR(IF(INDEX('🚗 BÁO GIÁ TURBO '!$J$4:$J$690,MATCH(3,'🚗 BÁO GIÁ TURBO '!$W$4:$W$690,0))="","",INDEX('🚗 BÁO GIÁ TURBO '!$J$4:$J$690,MATCH(3,'🚗 BÁO GIÁ TURBO '!$W$4:$W$690,0))),"")
A11: =IFERROR(IF(INDEX('🚗 BÁO GIÁ TURBO '!$A$4:$A$690,MATCH(4,'🚗 BÁO GIÁ TURBO '!$W$4:$W$690,0))="","",INDEX('🚗 BÁO GIÁ TURBO '!$A$4:$A$690,MATCH(4,'🚗 BÁO GIÁ TURBO '!$W$4:$W$690,0))),"") | B11: =IFERROR(IF(INDEX('🚗 BÁO GIÁ TURBO '!$B$4:$B$690,MATCH(4,'🚗 BÁO GIÁ TURBO '!$W$4:$W$690,0))="","",INDEX('🚗 BÁO GIÁ TURBO '!$B$4:$B$690,MATCH(4,'🚗 BÁO GIÁ TURBO '!$W$4:$W$690,0))),"") | C11: =IFERROR(IF(INDEX('🚗 BÁO GIÁ TURBO '!$D$4:$D$690,MATCH(4,'🚗 BÁO GIÁ TURBO '!$W$4:$W$690,0))="","",INDEX('🚗 BÁO GIÁ TURBO '!$D$4:$D$690,MATCH(4,'🚗 BÁO GIÁ TURBO '!$W$4:$W$690,0))),"") | D11: =IFERROR(IF(INDEX('🚗 BÁO GIÁ TURBO '!$E$4:$E$690,MATCH(4,'🚗 BÁO GIÁ TURBO '!$W$4:$W$690,0))="","",INDEX('🚗 BÁO GIÁ TURBO '!$E$4:$E$690,MATCH(4,'🚗 BÁO GIÁ TURBO '!$W$4:$W$690,0))),"") | E11: =IFERROR(IF(INDEX('🚗 BÁO GIÁ TURBO '!$F$4:$F$690,MATCH(4,'🚗 BÁO GIÁ TURBO '!$W$4:$W$690,0))="","",INDEX('🚗 BÁO GIÁ TURBO '!$F$4:$F$690,MATCH(4,'🚗 BÁO GIÁ TURBO '!$W$4:$W$690,0))),"") | F11: =IFERROR(IF(INDEX('🚗 BÁO GIÁ TURBO '!$G$4:$G$690,MATCH(4,'🚗 BÁO GIÁ TURBO '!$W$4:$W$690,0))="","",INDEX('🚗 BÁO GIÁ TURBO '!$G$4:$G$690,MATCH(4,'🚗 BÁO GIÁ TURBO '!$W$4:$W$690,0))),"") | G11: =IFERROR(IF(INDEX('🚗 BÁO GIÁ TURBO '!$H$4:$H$690,MATCH(4,'🚗 BÁO GIÁ TURBO '!$W$4:$W$690,0))="","",INDEX('🚗 BÁO GIÁ TURBO '!$H$4:$H$690,MATCH(4,'🚗 BÁO GIÁ TURBO '!$W$4:$W$690,0))),"") | H11: =IFERROR(IF(INDEX('🚗 BÁO GIÁ TURBO '!$I$4:$I$690,MATCH(4,'🚗 BÁO GIÁ TURBO '!$W$4:$W$690,0))="","",INDEX('🚗 BÁO GIÁ TURBO '!$I$4:$I$690,MATCH(4,'🚗 BÁO GIÁ TURBO '!$W$4:$W$690,0))),"") | I11: =IFERROR(IF(INDEX('🚗 BÁO GIÁ TURBO '!$J$4:$J$690,MATCH(4,'🚗 BÁO GIÁ TURBO '!$W$4:$W$690,0))="","",INDEX('🚗 BÁO GIÁ TURBO '!$J$4:$J$690,MATCH(4,'🚗 BÁO GIÁ TURBO '!$W$4:$W$690,0))),"")
A12: =IFERROR(IF(INDEX('🚗 BÁO GIÁ TURBO '!$A$4:$A$690,MATCH(5,'🚗 BÁO GIÁ TURBO '!$W$4:$W$690,0))="","",INDEX('🚗 BÁO GIÁ TURBO '!$A$4:$A$690,MATCH(5,'🚗 BÁO GIÁ TURBO '!$W$4:$W$690,0))),"") | B12: =IFERROR(IF(INDEX('🚗 BÁO GIÁ TURBO '!$B$4:$B$690,MATCH(5,'🚗 BÁO GIÁ TURBO '!$W$4:$W$690,0))="","",INDEX('🚗 BÁO GIÁ TURBO '!$B$4:$B$690,MATCH(5,'🚗 BÁO GIÁ TURBO '!$W$4:$W$690,0))),"") | C12: =IFERROR(IF(INDEX('🚗 BÁO GIÁ TURBO '!$D$4:$D$690,MATCH(5,'🚗 BÁO GIÁ TURBO '!$W$4:$W$690,0))="","",INDEX('🚗 BÁO GIÁ TURBO '!$D$4:$D$690,MATCH(5,'🚗 BÁO GIÁ TURBO '!$W$4:$W$690,0))),"") | D12: =IFERROR(IF(INDEX('🚗 BÁO GIÁ TURBO '!$E$4:$E$690,MATCH(5,'🚗 BÁO GIÁ TURBO '!$W$4:$W$690,0))="","",INDEX('🚗 BÁO GIÁ TURBO '!$E$4:$E$690,MATCH(5,'🚗 BÁO GIÁ TURBO '!$W$4:$W$690,0))),"") | E12: =IFERROR(IF(INDEX('🚗 BÁO GIÁ TURBO '!$F$4:$F$690,MATCH(5,'🚗 BÁO GIÁ TURBO '!$W$4:$W$690,0))="","",INDEX('🚗 BÁO GIÁ TURBO '!$F$4:$F$690,MATCH(5,'🚗 BÁO GIÁ TURBO '!$W$4:$W$690,0))),"") | F12: =IFERROR(IF(INDEX('🚗 BÁO GIÁ TURBO '!$G$4:$G$690,MATCH(5,'🚗 BÁO GIÁ TURBO '!$W$4:$W$690,0))="","",INDEX('🚗 BÁO GIÁ TURBO '!$G$4:$G$690,MATCH(5,'🚗 BÁO GIÁ TURBO '!$W$4:$W$690,0))),"") | G12: =IFERROR(IF(INDEX('🚗 BÁO GIÁ TURBO '!$H$4:$H$690,MATCH(5,'🚗 BÁO GIÁ TURBO '!$W$4:$W$690,0))="","",INDEX('🚗 BÁO GIÁ TURBO '!$H$4:$H$690,MATCH(5,'🚗 BÁO GIÁ TURBO '!$W$4:$W$690,0))),"") | H12: =IFERROR(IF(INDEX('🚗 BÁO GIÁ TURBO '!$I$4:$I$690,MATCH(5,'🚗 BÁO GIÁ TURBO '!$W$4:$W$690,0))="","",INDEX('🚗 BÁO GIÁ TURBO '!$I$4:$I$690,MATCH(5,'🚗 BÁO GIÁ TURBO '!$W$4:$W$690,0))),"") | I12: =IFERROR(IF(INDEX('🚗 BÁO GIÁ TURBO '!$J$4:$J$690,MATCH(5,'🚗 BÁO GIÁ TURBO '!$W$4:$W$690,0))="","",INDEX('🚗 BÁO GIÁ TURBO '!$J$4:$J$690,MATCH(5,'🚗 BÁO GIÁ TURBO '!$W$4:$W$690,0))),"")
A13: =IFERROR(IF(INDEX('🚗 BÁO GIÁ TURBO '!$A$4:$A$690,MATCH(6,'🚗 BÁO GIÁ TURBO '!$W$4:$W$690,0))="","",INDEX('🚗 BÁO GIÁ TURBO '!$A$4:$A$690,MATCH(6,'🚗 BÁO GIÁ TURBO '!$W$4:$W$690,0))),"") | B13: =IFERROR(IF(INDEX('🚗 BÁO GIÁ TURBO '!$B$4:$B$690,MATCH(6,'🚗 BÁO GIÁ TURBO '!$W$4:$W$690,0))="","",INDEX('🚗 BÁO GIÁ TURBO '!$B$4:$B$690,MATCH(6,'🚗 BÁO GIÁ TURBO '!$W$4:$W$690,0))),"") | C13: =IFERROR(IF(INDEX('🚗 BÁO GIÁ TURBO '!$D$4:$D$690,MATCH(6,'🚗 BÁO GIÁ TURBO '!$W$4:$W$690,0))="","",INDEX('🚗 BÁO GIÁ TURBO '!$D$4:$D$690,MATCH(6,'🚗 BÁO GIÁ TURBO '!$W$4:$W$690,0))),"") | D13: =IFERROR(IF(INDEX('🚗 BÁO GIÁ TURBO '!$E$4:$E$690,MATCH(6,'🚗 BÁO GIÁ TURBO '!$W$4:$W$690,0))="","",INDEX('🚗 BÁO GIÁ TURBO '!$E$4:$E$690,MATCH(6,'🚗 BÁO GIÁ TURBO '!$W$4:$W$690,0))),"") | E13: =IFERROR(IF(INDEX('🚗 BÁO GIÁ TURBO '!$F$4:$F$690,MATCH(6,'🚗 BÁO GIÁ TURBO '!$W$4:$W$690,0))="","",INDEX('🚗 BÁO GIÁ TURBO '!$F$4:$F$690,MATCH(6,'🚗 BÁO GIÁ TURBO '!$W$4:$W$690,0))),"") | F13: =IFERROR(IF(INDEX('🚗 BÁO GIÁ TURBO '!$G$4:$G$690,MATCH(6,'🚗 BÁO GIÁ TURBO '!$W$4:$W$690,0))="","",INDEX('🚗 BÁO GIÁ TURBO '!$G$4:$G$690,MATCH(6,'🚗 BÁO GIÁ TURBO '!$W$4:$W$690,0))),"") | G13: =IFERROR(IF(INDEX('🚗 BÁO GIÁ TURBO '!$H$4:$H$690,MATCH(6,'🚗 BÁO GIÁ TURBO '!$W$4:$W$690,0))="","",INDEX('🚗 BÁO GIÁ TURBO '!$H$4:$H$690,MATCH(6,'🚗 BÁO GIÁ TURBO '!$W$4:$W$690,0))),"") | H13: =IFERROR(IF(INDEX('🚗 BÁO GIÁ TURBO '!$I$4:$I$690,MATCH(6,'🚗 BÁO GIÁ TURBO '!$W$4:$W$690,0))="","",INDEX('🚗 BÁO GIÁ TURBO '!$I$4:$I$690,MATCH(6,'🚗 BÁO GIÁ TURBO '!$W$4:$W$690,0))),"") | I13: =IFERROR(IF(INDEX('🚗 BÁO GIÁ TURBO '!$J$4:$J$690,MATCH(6,'🚗 BÁO GIÁ TURBO '!$W$4:$W$690,0))="","",INDEX('🚗 BÁO GIÁ TURBO '!$J$4:$J$690,MATCH(6,'🚗 BÁO GIÁ TURBO '!$W$4:$W$690,0))),"")
A14: =IFERROR(IF(INDEX('🚗 BÁO GIÁ TURBO '!$A$4:$A$690,MATCH(7,'🚗 BÁO GIÁ TURBO '!$W$4:$W$690,0))="","",INDEX('🚗 BÁO GIÁ TURBO '!$A$4:$A$690,MATCH(7,'🚗 BÁO GIÁ TURBO '!$W$4:$W$690,0))),"") | B14: =IFERROR(IF(INDEX('🚗 BÁO GIÁ TURBO '!$B$4:$B$690,MATCH(7,'🚗 BÁO GIÁ TURBO '!$W$4:$W$690,0))="","",INDEX('🚗 BÁO GIÁ TURBO '!$B$4:$B$690,MATCH(7,'🚗 BÁO GIÁ TURBO '!$W$4:$W$690,0))),"") | C14: =IFERROR(IF(INDEX('🚗 BÁO GIÁ TURBO '!$D$4:$D$690,MATCH(7,'🚗 BÁO GIÁ TURBO '!$W$4:$W$690,0))="","",INDEX('🚗 BÁO GIÁ TURBO '!$D$4:$D$690,MATCH(7,'🚗 BÁO GIÁ TURBO '!$W$4:$W$690,0))),"") | D14: =IFERROR(IF(INDEX('🚗 BÁO GIÁ TURBO '!$E$4:$E$690,MATCH(7,'🚗 BÁO GIÁ TURBO '!$W$4:$W$690,0))="","",INDEX('🚗 BÁO GIÁ TURBO '!$E$4:$E$690,MATCH(7,'🚗 BÁO GIÁ TURBO '!$W$4:$W$690,0))),"") | E14: =IFERROR(IF(INDEX('🚗 BÁO GIÁ TURBO '!$F$4:$F$690,MATCH(7,'🚗 BÁO GIÁ TURBO '!$W$4:$W$690,0))="","",INDEX('🚗 BÁO GIÁ TURBO '!$F$4:$F$690,MATCH(7,'🚗 BÁO GIÁ TURBO '!$W$4:$W$690,0))),"") | F14: =IFERROR(IF(INDEX('🚗 BÁO GIÁ TURBO '!$G$4:$G$690,MATCH(7,'🚗 BÁO GIÁ TURBO '!$W$4:$W$690,0))="","",INDEX('🚗 BÁO GIÁ TURBO '!$G$4:$G$690,MATCH(7,'🚗 BÁO GIÁ TURBO '!$W$4:$W$690,0))),"") | G14: =IFERROR(IF(INDEX('🚗 BÁO GIÁ TURBO '!$H$4:$H$690,MATCH(7,'🚗 BÁO GIÁ TURBO '!$W$4:$W$690,0))="","",INDEX('🚗 BÁO GIÁ TURBO '!$H$4:$H$690,MATCH(7,'🚗 BÁO GIÁ TURBO '!$W$4:$W$690,0))),"") | H14: =IFERROR(IF(INDEX('🚗 BÁO GIÁ TURBO '!$I$4:$I$690,MATCH(7,'🚗 BÁO GIÁ TURBO '!$W$4:$W$690,0))="","",INDEX('🚗 BÁO GIÁ TURBO '!$I$4:$I$690,MATCH(7,'🚗 BÁO GIÁ TURBO '!$W$4:$W$690,0))),"") | I14: =IFERROR(IF(INDEX('🚗 BÁO GIÁ TURBO '!$J$4:$J$690,MATCH(7,'🚗 BÁO GIÁ TURBO '!$W$4:$W$690,0))="","",INDEX('🚗 BÁO GIÁ TURBO '!$J$4:$J$690,MATCH(7,'🚗 BÁO GIÁ TURBO '!$W$4:$W$690,0))),"")
A15: =IFERROR(IF(INDEX('🚗 BÁO GIÁ TURBO '!$A$4:$A$690,MATCH(8,'🚗 BÁO GIÁ TURBO '!$W$4:$W$690,0))="","",INDEX('🚗 BÁO GIÁ TURBO '!$A$4:$A$690,MATCH(8,'🚗 BÁO GIÁ TURBO '!$W$4:$W$690,0))),"") | B15: =IFERROR(IF(INDEX('🚗 BÁO GIÁ TURBO '!$B$4:$B$690,MATCH(8,'🚗 BÁO GIÁ TURBO '!$W$4:$W$690,0))="","",INDEX('🚗 BÁO GIÁ TURBO '!$B$4:$B$690,MATCH(8,'🚗 BÁO GIÁ TURBO '!$W$4:$W$690,0))),"") | C15: =IFERROR(IF(INDEX('🚗 BÁO GIÁ TURBO '!$D$4:$D$690,MATCH(8,'🚗 BÁO GIÁ TURBO '!$W$4:$W$690,0))="","",INDEX('🚗 BÁO GIÁ TURBO '!$D$4:$D$690,MATCH(8,'🚗 BÁO GIÁ TURBO '!$W$4:$W$690,0))),"") | D15: =IFERROR(IF(INDEX('🚗 BÁO GIÁ TURBO '!$E$4:$E$690,MATCH(8,'🚗 BÁO GIÁ TURBO '!$W$4:$W$690,0))="","",INDEX('🚗 BÁO GIÁ TURBO '!$E$4:$E$690,MATCH(8,'🚗 BÁO GIÁ TURBO '!$W$4:$W$690,0))),"") | E15: =IFERROR(IF(INDEX('🚗 BÁO GIÁ TURBO '!$F$4:$F$690,MATCH(8,'🚗 BÁO GIÁ TURBO '!$W$4:$W$690,0))="","",INDEX('🚗 BÁO GIÁ TURBO '!$F$4:$F$690,MATCH(8,'🚗 BÁO GIÁ TURBO '!$W$4:$W$690,0))),"") | F15: =IFERROR(IF(INDEX('🚗 BÁO GIÁ TURBO '!$G$4:$G$690,MATCH(8,'🚗 BÁO GIÁ TURBO '!$W$4:$W$690,0))="","",INDEX('🚗 BÁO GIÁ TURBO '!$G$4:$G$690,MATCH(8,'🚗 BÁO GIÁ TURBO '!$W$4:$W$690,0))),"") | G15: =IFERROR(IF(INDEX('🚗 BÁO GIÁ TURBO '!$H$4:$H$690,MATCH(8,'🚗 BÁO GIÁ TURBO '!$W$4:$W$690,0))="","",INDEX('🚗 BÁO GIÁ TURBO '!$H$4:$H$690,MATCH(8,'🚗 BÁO GIÁ TURBO '!$W$4:$W$690,0))),"") | H15: =IFERROR(IF(INDEX('🚗 BÁO GIÁ TURBO '!$I$4:$I$690,MATCH(8,'🚗 BÁO GIÁ TURBO '!$W$4:$W$690,0))="","",INDEX('🚗 BÁO GIÁ TURBO '!$I$4:$I$690,MATCH(8,'🚗 BÁO GIÁ TURBO '!$W$4:$W$690,0))),"") | I15: =IFERROR(IF(INDEX('🚗 BÁO GIÁ TURBO '!$J$4:$J$690,MATCH(8,'🚗 BÁO GIÁ TURBO '!$W$4:$W$690,0))="","",INDEX('🚗 BÁO GIÁ TURBO '!$J$4:$J$690,MATCH(8,'🚗 BÁO GIÁ TURBO '!$W$4:$W$690,0))),"")
A16: =IFERROR(IF(INDEX('🚗 BÁO GIÁ TURBO '!$A$4:$A$690,MATCH(9,'🚗 BÁO GIÁ TURBO '!$W$4:$W$690,0))="","",INDEX('🚗 BÁO GIÁ TURBO '!$A$4:$A$690,MATCH(9,'🚗 BÁO GIÁ TURBO '!$W$4:$W$690,0))),"") | B16: =IFERROR(IF(INDEX('🚗 BÁO GIÁ TURBO '!$B$4:$B$690,MATCH(9,'🚗 BÁO GIÁ TURBO '!$W$4:$W$690,0))="","",INDEX('🚗 BÁO GIÁ TURBO '!$B$4:$B$690,MATCH(9,'🚗 BÁO GIÁ TURBO '!$W$4:$W$690,0))),"") | C16: =IFERROR(IF(INDEX('🚗 BÁO GIÁ TURBO '!$D$4:$D$690,MATCH(9,'🚗 BÁO GIÁ TURBO '!$W$4:$W$690,0))="","",INDEX('🚗 BÁO GIÁ TURBO '!$D$4:$D$690,MATCH(9,'🚗 BÁO GIÁ TURBO '!$W$4:$W$690,0))),"") | D16: =IFERROR(IF(INDEX('🚗 BÁO GIÁ TURBO '!$E$4:$E$690,MATCH(9,'🚗 BÁO GIÁ TURBO '!$W$4:$W$690,0))="","",INDEX('🚗 BÁO GIÁ TURBO '!$E$4:$E$690,MATCH(9,'🚗 BÁO GIÁ TURBO '!$W$4:$W$690,0))),"") | E16: =IFERROR(IF(INDEX('🚗 BÁO GIÁ TURBO '!$F$4:$F$690,MATCH(9,'🚗 BÁO GIÁ TURBO '!$W$4:$W$690,0))="","",INDEX('🚗 BÁO GIÁ TURBO '!$F$4:$F$690,MATCH(9,'🚗 BÁO GIÁ TURBO '!$W$4:$W$690,0))),"") | F16: =IFERROR(IF(INDEX('🚗 BÁO GIÁ TURBO '!$G$4:$G$690,MATCH(9,'🚗 BÁO GIÁ TURBO '!$W$4:$W$690,0))="","",INDEX('🚗 BÁO GIÁ TURBO '!$G$4:$G$690,MATCH(9,'🚗 BÁO GIÁ TURBO '!$W$4:$W$690,0))),"") | G16: =IFERROR(IF(INDEX('🚗 BÁO GIÁ TURBO '!$H$4:$H$690,MATCH(9,'🚗 BÁO GIÁ TURBO '!$W$4:$W$690,0))="","",INDEX('🚗 BÁO GIÁ TURBO '!$H$4:$H$690,MATCH(9,'🚗 BÁO GIÁ TURBO '!$W$4:$W$690,0))),"") | H16: =IFERROR(IF(INDEX('🚗 BÁO GIÁ TURBO '!$I$4:$I$690,MATCH(9,'🚗 BÁO GIÁ TURBO '!$W$4:$W$690,0))="","",INDEX('🚗 BÁO GIÁ TURBO '!$I$4:$I$690,MATCH(9,'🚗 BÁO GIÁ TURBO '!$W$4:$W$690,0))),"") | I16: =IFERROR(IF(INDEX('🚗 BÁO GIÁ TURBO '!$J$4:$J$690,MATCH(9,'🚗 BÁO GIÁ TURBO '!$W$4:$W$690,0))="","",INDEX('🚗 BÁO GIÁ TURBO '!$J$4:$J$690,MATCH(9,'🚗 BÁO GIÁ TURBO '!$W$4:$W$690,0))),"")
A17: =IFERROR(IF(INDEX('🚗 BÁO GIÁ TURBO '!$A$4:$A$690,MATCH(10,'🚗 BÁO GIÁ TURBO '!$W$4:$W$690,0))="","",INDEX('🚗 BÁO GIÁ TURBO '!$A$4:$A$690,MATCH(10,'🚗 BÁO GIÁ TURBO '!$W$4:$W$690,0))),"") | B17: =IFERROR(IF(INDEX('🚗 BÁO GIÁ TURBO '!$B$4:$B$690,MATCH(10,'🚗 BÁO GIÁ TURBO '!$W$4:$W$690,0))="","",INDEX('🚗 BÁO GIÁ TURBO '!$B$4:$B$690,MATCH(10,'🚗 BÁO GIÁ TURBO '!$W$4:$W$690,0))),"") | C17: =IFERROR(IF(INDEX('🚗 BÁO GIÁ TURBO '!$D$4:$D$690,MATCH(10,'🚗 BÁO GIÁ TURBO '!$W$4:$W$690,0))="","",INDEX('🚗 BÁO GIÁ TURBO '!$D$4:$D$690,MATCH(10,'🚗 BÁO GIÁ TURBO '!$W$4:$W$690,0))),"") | D17: =IFERROR(IF(INDEX('🚗 BÁO GIÁ TURBO '!$E$4:$E$690,MATCH(10,'🚗 BÁO GIÁ TURBO '!$W$4:$W$690,0))="","",INDEX('🚗 BÁO GIÁ TURBO '!$E$4:$E$690,MATCH(10,'🚗 BÁO GIÁ TURBO '!$W$4:$W$690,0))),"") | E17: =IFERROR(IF(INDEX('🚗 BÁO GIÁ TURBO '!$F$4:$F$690,MATCH(10,'🚗 BÁO GIÁ TURBO '!$W$4:$W$690,0))="","",INDEX('🚗 BÁO GIÁ TURBO '!$F$4:$F$690,MATCH(10,'🚗 BÁO GIÁ TURBO '!$W$4:$W$690,0))),"") | F17: =IFERROR(IF(INDEX('🚗 BÁO GIÁ TURBO '!$G$4:$G$690,MATCH(10,'🚗 BÁO GIÁ TURBO '!$W$4:$W$690,0))="","",INDEX('🚗 BÁO GIÁ TURBO '!$G$4:$G$690,MATCH(10,'🚗 BÁO GIÁ TURBO '!$W$4:$W$690,0))),"") | G17: =IFERROR(IF(INDEX('🚗 BÁO GIÁ TURBO '!$H$4:$H$690,MATCH(10,'🚗 BÁO GIÁ TURBO '!$W$4:$W$690,0))="","",INDEX('🚗 BÁO GIÁ TURBO '!$H$4:$H$690,MATCH(10,'🚗 BÁO GIÁ TURBO '!$W$4:$W$690,0))),"") | H17: =IFERROR(IF(INDEX('🚗 BÁO GIÁ TURBO '!$I$4:$I$690,MATCH(10,'🚗 BÁO GIÁ TURBO '!$W$4:$W$690,0))="","",INDEX('🚗 BÁO GIÁ TURBO '!$I$4:$I$690,MATCH(10,'🚗 BÁO GIÁ TURBO '!$W$4:$W$690,0))),"") | I17: =IFERROR(IF(INDEX('🚗 BÁO GIÁ TURBO '!$J$4:$J$690,MATCH(10,'🚗 BÁO GIÁ TURBO '!$W$4:$W$690,0))="","",INDEX('🚗 BÁO GIÁ TURBO '!$J$4:$J$690,MATCH(10,'🚗 BÁO GIÁ TURBO '!$W$4:$W$690,0))),"")
A18: =IFERROR(IF(INDEX('🚗 BÁO GIÁ TURBO '!$A$4:$A$690,MATCH(11,'🚗 BÁO GIÁ TURBO '!$W$4:$W$690,0))="","",INDEX('🚗 BÁO GIÁ TURBO '!$A$4:$A$690,MATCH(11,'🚗 BÁO GIÁ TURBO '!$W$4:$W$690,0))),"") | B18: =IFERROR(IF(INDEX('🚗 BÁO GIÁ TURBO '!$B$4:$B$690,MATCH(11,'🚗 BÁO GIÁ TURBO '!$W$4:$W$690,0))="","",INDEX('🚗 BÁO GIÁ TURBO '!$B$4:$B$690,MATCH(11,'🚗 BÁO GIÁ TURBO '!$W$4:$W$690,0))),"") | C18: =IFERROR(IF(INDEX('🚗 BÁO GIÁ TURBO '!$D$4:$D$690,MATCH(11,'🚗 BÁO GIÁ TURBO '!$W$4:$W$690,0))="","",INDEX('🚗 BÁO GIÁ TURBO '!$D$4:$D$690,MATCH(11,'🚗 BÁO GIÁ TURBO '!$W$4:$W$690,0))),"") | D18: =IFERROR(IF(INDEX('🚗 BÁO GIÁ TURBO '!$E$4:$E$690,MATCH(11,'🚗 BÁO GIÁ TURBO '!$W$4:$W$690,0))="","",INDEX('🚗 BÁO GIÁ TURBO '!$E$4:$E$690,MATCH(11,'🚗 BÁO GIÁ TURBO '!$W$4:$W$690,0))),"") | E18: =IFERROR(IF(INDEX('🚗 BÁO GIÁ TURBO '!$F$4:$F$690,MATCH(11,'🚗 BÁO GIÁ TURBO '!$W$4:$W$690,0))="","",INDEX('🚗 BÁO GIÁ TURBO '!$F$4:$F$690,MATCH(11,'🚗 BÁO GIÁ TURBO '!$W$4:$W$690,0))),"") | F18: =IFERROR(IF(INDEX('🚗 BÁO GIÁ TURBO '!$G$4:$G$690,MATCH(11,'🚗 BÁO GIÁ TURBO '!$W$4:$W$690,0))="","",INDEX('🚗 BÁO GIÁ TURBO '!$G$4:$G$690,MATCH(11,'🚗 BÁO GIÁ TURBO '!$W$4:$W$690,0))),"") | G18: =IFERROR(IF(INDEX('🚗 BÁO GIÁ TURBO '!$H$4:$H$690,MATCH(11,'🚗 BÁO GIÁ TURBO '!$W$4:$W$690,0))="","",INDEX('🚗 BÁO GIÁ TURBO '!$H$4:$H$690,MATCH(11,'🚗 BÁO GIÁ TURBO '!$W$4:$W$690,0))),"") | H18: =IFERROR(IF(INDEX('🚗 BÁO GIÁ TURBO '!$I$4:$I$690,MATCH(11,'🚗 BÁO GIÁ TURBO '!$W$4:$W$690,0))="","",INDEX('🚗 BÁO GIÁ TURBO '!$I$4:$I$690,MATCH(11,'🚗 BÁO GIÁ TURBO '!$W$4:$W$690,0))),"") | I18: =IFERROR(IF(INDEX('🚗 BÁO GIÁ TURBO '!$J$4:$J$690,MATCH(11,'🚗 BÁO GIÁ TURBO '!$W$4:$W$690,0))="","",INDEX('🚗 BÁO GIÁ TURBO '!$J$4:$J$690,MATCH(11,'🚗 BÁO GIÁ TURBO '!$W$4:$W$690,0))),"")
A19: =IFERROR(IF(INDEX('🚗 BÁO GIÁ TURBO '!$A$4:$A$690,MATCH(12,'🚗 BÁO GIÁ TURBO '!$W$4:$W$690,0))="","",INDEX('🚗 BÁO GIÁ TURBO '!$A$4:$A$690,MATCH(12,'🚗 BÁO GIÁ TURBO '!$W$4:$W$690,0))),"") | B19: =IFERROR(IF(INDEX('🚗 BÁO GIÁ TURBO '!$B$4:$B$690,MATCH(12,'🚗 BÁO GIÁ TURBO '!$W$4:$W$690,0))="","",INDEX('🚗 BÁO GIÁ TURBO '!$B$4:$B$690,MATCH(12,'🚗 BÁO GIÁ TURBO '!$W$4:$W$690,0))),"") | C19: =IFERROR(IF(INDEX('🚗 BÁO GIÁ TURBO '!$D$4:$D$690,MATCH(12,'🚗 BÁO GIÁ TURBO '!$W$4:$W$690,0))="","",INDEX('🚗 BÁO GIÁ TURBO '!$D$4:$D$690,MATCH(12,'🚗 BÁO GIÁ TURBO '!$W$4:$W$690,0))),"") | D19: =IFERROR(IF(INDEX('🚗 BÁO GIÁ TURBO '!$E$4:$E$690,MATCH(12,'🚗 BÁO GIÁ TURBO '!$W$4:$W$690,0))="","",INDEX('🚗 BÁO GIÁ TURBO '!$E$4:$E$690,MATCH(12,'🚗 BÁO GIÁ TURBO '!$W$4:$W$690,0))),"") | E19: =IFERROR(IF(INDEX('🚗 BÁO GIÁ TURBO '!$F$4:$F$690,MATCH(12,'🚗 BÁO GIÁ TURBO '!$W$4:$W$690,0))="","",INDEX('🚗 BÁO GIÁ TURBO '!$F$4:$F$690,MATCH(12,'🚗 BÁO GIÁ TURBO '!$W$4:$W$690,0))),"") | F19: =IFERROR(IF(INDEX('🚗 BÁO GIÁ TURBO '!$G$4:$G$690,MATCH(12,'🚗 BÁO GIÁ TURBO '!$W$4:$W$690,0))="","",INDEX('🚗 BÁO GIÁ TURBO '!$G$4:$G$690,MATCH(12,'🚗 BÁO GIÁ TURBO '!$W$4:$W$690,0))),"") | G19: =IFERROR(IF(INDEX('🚗 BÁO GIÁ TURBO '!$H$4:$H$690,MATCH(12,'🚗 BÁO GIÁ TURBO '!$W$4:$W$690,0))="","",INDEX('🚗 BÁO GIÁ TURBO '!$H$4:$H$690,MATCH(12,'🚗 BÁO GIÁ TURBO '!$W$4:$W$690,0))),"") | H19: =IFERROR(IF(INDEX('🚗 BÁO GIÁ TURBO '!$I$4:$I$690,MATCH(12,'🚗 BÁO GIÁ TURBO '!$W$4:$W$690,0))="","",INDEX('🚗 BÁO GIÁ TURBO '!$I$4:$I$690,MATCH(12,'🚗 BÁO GIÁ TURBO '!$W$4:$W$690,0))),"") | I19: =IFERROR(IF(INDEX('🚗 BÁO GIÁ TURBO '!$J$4:$J$690,MATCH(12,'🚗 BÁO GIÁ TURBO '!$W$4:$W$690,0))="","",INDEX('🚗 BÁO GIÁ TURBO '!$J$4:$J$690,MATCH(12,'🚗 BÁO GIÁ TURBO '!$W$4:$W$690,0))),"")
A20: =IFERROR(IF(INDEX('🚗 BÁO GIÁ TURBO '!$A$4:$A$690,MATCH(13,'🚗 BÁO GIÁ TURBO '!$W$4:$W$690,0))="","",INDEX('🚗 BÁO GIÁ TURBO '!$A$4:$A$690,MATCH(13,'🚗 BÁO GIÁ TURBO '!$W$4:$W$690,0))),"") | B20: =IFERROR(IF(INDEX('🚗 BÁO GIÁ TURBO '!$B$4:$B$690,MATCH(13,'🚗 BÁO GIÁ TURBO '!$W$4:$W$690,0))="","",INDEX('🚗 BÁO GIÁ TURBO '!$B$4:$B$690,MATCH(13,'🚗 BÁO GIÁ TURBO '!$W$4:$W$690,0))),"") | C20: =IFERROR(IF(INDEX('🚗 BÁO GIÁ TURBO '!$D$4:$D$690,MATCH(13,'🚗 BÁO GIÁ TURBO '!$W$4:$W$690,0))="","",INDEX('🚗 BÁO GIÁ TURBO '!$D$4:$D$690,MATCH(13,'🚗 BÁO GIÁ TURBO '!$W$4:$W$690,0))),"") | D20: =IFERROR(IF(INDEX('🚗 BÁO GIÁ TURBO '!$E$4:$E$690,MATCH(13,'🚗 BÁO GIÁ TURBO '!$W$4:$W$690,0))="","",INDEX('🚗 BÁO GIÁ TURBO '!$E$4:$E$690,MATCH(13,'🚗 BÁO GIÁ TURBO '!$W$4:$W$690,0))),"") | E20: =IFERROR(IF(INDEX('🚗 BÁO GIÁ TURBO '!$F$4:$F$690,MATCH(13,'🚗 BÁO GIÁ TURBO '!$W$4:$W$690,0))="","",INDEX('🚗 BÁO GIÁ TURBO '!$F$4:$F$690,MATCH(13,'🚗 BÁO GIÁ TURBO '!$W$4:$W$690,0))),"") | F20: =IFERROR(IF(INDEX('🚗 BÁO GIÁ TURBO '!$G$4:$G$690,MATCH(13,'🚗 BÁO GIÁ TURBO '!$W$4:$W$690,0))="","",INDEX('🚗 BÁO GIÁ TURBO '!$G$4:$G$690,MATCH(13,'🚗 BÁO GIÁ TURBO '!$W$4:$W$690,0))),"") | G20: =IFERROR(IF(INDEX('🚗 BÁO GIÁ TURBO '!$H$4:$H$690,MATCH(13,'🚗 BÁO GIÁ TURBO '!$W$4:$W$690,0))="","",INDEX('🚗 BÁO GIÁ TURBO '!$H$4:$H$690,MATCH(13,'🚗 BÁO GIÁ TURBO '!$W$4:$W$690,0))),"") | H20: =IFERROR(IF(INDEX('🚗 BÁO GIÁ TURBO '!$I$4:$I$690,MATCH(13,'🚗 BÁO GIÁ TURBO '!$W$4:$W$690,0))="","",INDEX('🚗 BÁO GIÁ TURBO '!$I$4:$I$690,MATCH(13,'🚗 BÁO GIÁ TURBO '!$W$4:$W$690,0))),"") | I20: =IFERROR(IF(INDEX('🚗 BÁO GIÁ TURBO '!$J$4:$J$690,MATCH(13,'🚗 BÁO GIÁ TURBO '!$W$4:$W$690,0))="","",INDEX('🚗 BÁO GIÁ TURBO '!$J$4:$J$690,MATCH(13,'🚗 BÁO GIÁ TURBO '!$W$4:$W$690,0))),"")
A21: =IFERROR(IF(INDEX('🚗 BÁO GIÁ TURBO '!$A$4:$A$690,MATCH(14,'🚗 BÁO GIÁ TURBO '!$W$4:$W$690,0))="","",INDEX('🚗 BÁO GIÁ TURBO '!$A$4:$A$690,MATCH(14,'🚗 BÁO GIÁ TURBO '!$W$4:$W$690,0))),"") | B21: =IFERROR(IF(INDEX('🚗 BÁO GIÁ TURBO '!$B$4:$B$690,MATCH(14,'🚗 BÁO GIÁ TURBO '!$W$4:$W$690,0))="","",INDEX('🚗 BÁO GIÁ TURBO '!$B$4:$B$690,MATCH(14,'🚗 BÁO GIÁ TURBO '!$W$4:$W$690,0))),"") | C21: =IFERROR(IF(INDEX('🚗 BÁO GIÁ TURBO '!$D$4:$D$690,MATCH(14,'🚗 BÁO GIÁ TURBO '!$W$4:$W$690,0))="","",INDEX('🚗 BÁO GIÁ TURBO '!$D$4:$D$690,MATCH(14,'🚗 BÁO GIÁ TURBO '!$W$4:$W$690,0))),"") | D21: =IFERROR(IF(INDEX('🚗 BÁO GIÁ TURBO '!$E$4:$E$690,MATCH(14,'🚗 BÁO GIÁ TURBO '!$W$4:$W$690,0))="","",INDEX('🚗 BÁO GIÁ TURBO '!$E$4:$E$690,MATCH(14,'🚗 BÁO GIÁ TURBO '!$W$4:$W$690,0))),"") | E21: =IFERROR(IF(INDEX('🚗 BÁO GIÁ TURBO '!$F$4:$F$690,MATCH(14,'🚗 BÁO GIÁ TURBO '!$W$4:$W$690,0))="","",INDEX('🚗 BÁO GIÁ TURBO '!$F$4:$F$690,MATCH(14,'🚗 BÁO GIÁ TURBO '!$W$4:$W$690,0))),"") | F21: =IFERROR(IF(INDEX('🚗 BÁO GIÁ TURBO '!$G$4:$G$690,MATCH(14,'🚗 BÁO GIÁ TURBO '!$W$4:$W$690,0))="","",INDEX('🚗 BÁO GIÁ TURBO '!$G$4:$G$690,MATCH(14,'🚗 BÁO GIÁ TURBO '!$W$4:$W$690,0))),"") | G21: =IFERROR(IF(INDEX('🚗 BÁO GIÁ TURBO '!$H$4:$H$690,MATCH(14,'🚗 BÁO GIÁ TURBO '!$W$4:$W$690,0))="","",INDEX('🚗 BÁO GIÁ TURBO '!$H$4:$H$690,MATCH(14,'🚗 BÁO GIÁ TURBO '!$W$4:$W$690,0))),"") | H21: =IFERROR(IF(INDEX('🚗 BÁO GIÁ TURBO '!$I$4:$I$690,MATCH(14,'🚗 BÁO GIÁ TURBO '!$W$4:$W$690,0))="","",INDEX('🚗 BÁO GIÁ TURBO '!$I$4:$I$690,MATCH(14,'🚗 BÁO GIÁ TURBO '!$W$4:$W$690,0))),"") | I21: =IFERROR(IF(INDEX('🚗 BÁO GIÁ TURBO '!$J$4:$J$690,MATCH(14,'🚗 BÁO GIÁ TURBO '!$W$4:$W$690,0))="","",INDEX('🚗 BÁO GIÁ TURBO '!$J$4:$J$690,MATCH(14,'🚗 BÁO GIÁ TURBO '!$W$4:$W$690,0))),"")
A22: =IFERROR(IF(INDEX('🚗 BÁO GIÁ TURBO '!$A$4:$A$690,MATCH(15,'🚗 BÁO GIÁ TURBO '!$W$4:$W$690,0))="","",INDEX('🚗 BÁO GIÁ TURBO '!$A$4:$A$690,MATCH(15,'🚗 BÁO GIÁ TURBO '!$W$4:$W$690,0))),"") | B22: =IFERROR(IF(INDEX('🚗 BÁO GIÁ TURBO '!$B$4:$B$690,MATCH(15,'🚗 BÁO GIÁ TURBO '!$W$4:$W$690,0))="","",INDEX('🚗 BÁO GIÁ TURBO '!$B$4:$B$690,MATCH(15,'🚗 BÁO GIÁ TURBO '!$W$4:$W$690,0))),"") | C22: =IFERROR(IF(INDEX('🚗 BÁO GIÁ TURBO '!$D$4:$D$690,MATCH(15,'🚗 BÁO GIÁ TURBO '!$W$4:$W$690,0))="","",INDEX('🚗 BÁO GIÁ TURBO '!$D$4:$D$690,MATCH(15,'🚗 BÁO GIÁ TURBO '!$W$4:$W$690,0))),"") | D22: =IFERROR(IF(INDEX('🚗 BÁO GIÁ TURBO '!$E$4:$E$690,MATCH(15,'🚗 BÁO GIÁ TURBO '!$W$4:$W$690,0))="","",INDEX('🚗 BÁO GIÁ TURBO '!$E$4:$E$690,MATCH(15,'🚗 BÁO GIÁ TURBO '!$W$4:$W$690,0))),"") | E22: =IFERROR(IF(INDEX('🚗 BÁO GIÁ TURBO '!$F$4:$F$690,MATCH(15,'🚗 BÁO GIÁ TURBO '!$W$4:$W$690,0))="","",INDEX('🚗 BÁO GIÁ TURBO '!$F$4:$F$690,MATCH(15,'🚗 BÁO GIÁ TURBO '!$W$4:$W$690,0))),"") | F22: =IFERROR(IF(INDEX('🚗 BÁO GIÁ TURBO '!$G$4:$G$690,MATCH(15,'🚗 BÁO GIÁ TURBO '!$W$4:$W$690,0))="","",INDEX('🚗 BÁO GIÁ TURBO '!$G$4:$G$690,MATCH(15,'🚗 BÁO GIÁ TURBO '!$W$4:$W$690,0))),"") | G22: =IFERROR(IF(INDEX('🚗 BÁO GIÁ TURBO '!$H$4:$H$690,MATCH(15,'🚗 BÁO GIÁ TURBO '!$W$4:$W$690,0))="","",INDEX('🚗 BÁO GIÁ TURBO '!$H$4:$H$690,MATCH(15,'🚗 BÁO GIÁ TURBO '!$W$4:$W$690,0))),"") | H22: =IFERROR(IF(INDEX('🚗 BÁO GIÁ TURBO '!$I$4:$I$690,MATCH(15,'🚗 BÁO GIÁ TURBO '!$W$4:$W$690,0))="","",INDEX('🚗 BÁO GIÁ TURBO '!$I$4:$I$690,MATCH(15,'🚗 BÁO GIÁ TURBO '!$W$4:$W$690,0))),"") | I22: =IFERROR(IF(INDEX('🚗 BÁO GIÁ TURBO '!$J$4:$J$690,MATCH(15,'🚗 BÁO GIÁ TURBO '!$W$4:$W$690,0))="","",INDEX('🚗 BÁO GIÁ TURBO '!$J$4:$J$690,MATCH(15,'🚗 BÁO GIÁ TURBO '!$W$4:$W$690,0))),"")
A23: =IFERROR(IF(INDEX('🚗 BÁO GIÁ TURBO '!$A$4:$A$690,MATCH(16,'🚗 BÁO GIÁ TURBO '!$W$4:$W$690,0))="","",INDEX('🚗 BÁO GIÁ TURBO '!$A$4:$A$690,MATCH(16,'🚗 BÁO GIÁ TURBO '!$W$4:$W$690,0))),"") | B23: =IFERROR(IF(INDEX('🚗 BÁO GIÁ TURBO '!$B$4:$B$690,MATCH(16,'🚗 BÁO GIÁ TURBO '!$W$4:$W$690,0))="","",INDEX('🚗 BÁO GIÁ TURBO '!$B$4:$B$690,MATCH(16,'🚗 BÁO GIÁ TURBO '!$W$4:$W$690,0))),"") | C23: =IFERROR(IF(INDEX('🚗 BÁO GIÁ TURBO '!$D$4:$D$690,MATCH(16,'🚗 BÁO GIÁ TURBO '!$W$4:$W$690,0))="","",INDEX('🚗 BÁO GIÁ TURBO '!$D$4:$D$690,MATCH(16,'🚗 BÁO GIÁ TURBO '!$W$4:$W$690,0))),"") | D23: =IFERROR(IF(INDEX('🚗 BÁO GIÁ TURBO '!$E$4:$E$690,MATCH(16,'🚗 BÁO GIÁ TURBO '!$W$4:$W$690,0))="","",INDEX('🚗 BÁO GIÁ TURBO '!$E$4:$E$690,MATCH(16,'🚗 BÁO GIÁ TURBO '!$W$4:$W$690,0))),"") | E23: =IFERROR(IF(INDEX('🚗 BÁO GIÁ TURBO '!$F$4:$F$690,MATCH(16,'🚗 BÁO GIÁ TURBO '!$W$4:$W$690,0))="","",INDEX('🚗 BÁO GIÁ TURBO '!$F$4:$F$690,MATCH(16,'🚗 BÁO GIÁ TURBO '!$W$4:$W$690,0))),"") | F23: =IFERROR(IF(INDEX('🚗 BÁO GIÁ TURBO '!$G$4:$G$690,MATCH(16,'🚗 BÁO GIÁ TURBO '!$W$4:$W$690,0))="","",INDEX('🚗 BÁO GIÁ TURBO '!$G$4:$G$690,MATCH(16,'🚗 BÁO GIÁ TURBO '!$W$4:$W$690,0))),"") | G23: =IFERROR(IF(INDEX('🚗 BÁO GIÁ TURBO '!$H$4:$H$690,MATCH(16,'🚗 BÁO GIÁ TURBO '!$W$4:$W$690,0))="","",INDEX('🚗 BÁO GIÁ TURBO '!$H$4:$H$690,MATCH(16,'🚗 BÁO GIÁ TURBO '!$W$4:$W$690,0))),"") | H23: =IFERROR(IF(INDEX('🚗 BÁO GIÁ TURBO '!$I$4:$I$690,MATCH(16,'🚗 BÁO GIÁ TURBO '!$W$4:$W$690,0))="","",INDEX('🚗 BÁO GIÁ TURBO '!$I$4:$I$690,MATCH(16,'🚗 BÁO GIÁ TURBO '!$W$4:$W$690,0))),"") | I23: =IFERROR(IF(INDEX('🚗 BÁO GIÁ TURBO '!$J$4:$J$690,MATCH(16,'🚗 BÁO GIÁ TURBO '!$W$4:$W$690,0))="","",INDEX('🚗 BÁO GIÁ TURBO '!$J$4:$J$690,MATCH(16,'🚗 BÁO GIÁ TURBO '!$W$4:$W$690,0))),"")
A24: =IFERROR(IF(INDEX('🚗 BÁO GIÁ TURBO '!$A$4:$A$690,MATCH(17,'🚗 BÁO GIÁ TURBO '!$W$4:$W$690,0))="","",INDEX('🚗 BÁO GIÁ TURBO '!$A$4:$A$690,MATCH(17,'🚗 BÁO GIÁ TURBO '!$W$4:$W$690,0))),"") | B24: =IFERROR(IF(INDEX('🚗 BÁO GIÁ TURBO '!$B$4:$B$690,MATCH(17,'🚗 BÁO GIÁ TURBO '!$W$4:$W$690,0))="","",INDEX('🚗 BÁO GIÁ TURBO '!$B$4:$B$690,MATCH(17,'🚗 BÁO GIÁ TURBO '!$W$4:$W$690,0))),"") | C24: =IFERROR(IF(INDEX('🚗 BÁO GIÁ TURBO '!$D$4:$D$690,MATCH(17,'🚗 BÁO GIÁ TURBO '!$W$4:$W$690,0))="","",INDEX('🚗 BÁO GIÁ TURBO '!$D$4:$D$690,MATCH(17,'🚗 BÁO GIÁ TURBO '!$W$4:$W$690,0))),"") | D24: =IFERROR(IF(INDEX('🚗 BÁO GIÁ TURBO '!$E$4:$E$690,MATCH(17,'🚗 BÁO GIÁ TURBO '!$W$4:$W$690,0))="","",INDEX('🚗 BÁO GIÁ TURBO '!$E$4:$E$690,MATCH(17,'🚗 BÁO GIÁ TURBO '!$W$4:$W$690,0))),"") | E24: =IFERROR(IF(INDEX('🚗 BÁO GIÁ TURBO '!$F$4:$F$690,MATCH(17,'🚗 BÁO GIÁ TURBO '!$W$4:$W$690,0))="","",INDEX('🚗 BÁO GIÁ TURBO '!$F$4:$F$690,MATCH(17,'🚗 BÁO GIÁ TURBO '!$W$4:$W$690,0))),"") | F24: =IFERROR(IF(INDEX('🚗 BÁO GIÁ TURBO '!$G$4:$G$690,MATCH(17,'🚗 BÁO GIÁ TURBO '!$W$4:$W$690,0))="","",INDEX('🚗 BÁO GIÁ TURBO '!$G$4:$G$690,MATCH(17,'🚗 BÁO GIÁ TURBO '!$W$4:$W$690,0))),"") | G24: =IFERROR(IF(INDEX('🚗 BÁO GIÁ TURBO '!$H$4:$H$690,MATCH(17,'🚗 BÁO GIÁ TURBO '!$W$4:$W$690,0))="","",INDEX('🚗 BÁO GIÁ TURBO '!$H$4:$H$690,MATCH(17,'🚗 BÁO GIÁ TURBO '!$W$4:$W$690,0))),"") | H24: =IFERROR(IF(INDEX('🚗 BÁO GIÁ TURBO '!$I$4:$I$690,MATCH(17,'🚗 BÁO GIÁ TURBO '!$W$4:$W$690,0))="","",INDEX('🚗 BÁO GIÁ TURBO '!$I$4:$I$690,MATCH(17,'🚗 BÁO GIÁ TURBO '!$W$4:$W$690,0))),"") | I24: =IFERROR(IF(INDEX('🚗 BÁO GIÁ TURBO '!$J$4:$J$690,MATCH(17,'🚗 BÁO GIÁ TURBO '!$W$4:$W$690,0))="","",INDEX('🚗 BÁO GIÁ TURBO '!$J$4:$J$690,MATCH(17,'🚗 BÁO GIÁ TURBO '!$W$4:$W$690,0))),"")
A25: =IFERROR(IF(INDEX('🚗 BÁO GIÁ TURBO '!$A$4:$A$690,MATCH(18,'🚗 BÁO GIÁ TURBO '!$W$4:$W$690,0))="","",INDEX('🚗 BÁO GIÁ TURBO '!$A$4:$A$690,MATCH(18,'🚗 BÁO GIÁ TURBO '!$W$4:$W$690,0))),"") | B25: =IFERROR(IF(INDEX('🚗 BÁO GIÁ TURBO '!$B$4:$B$690,MATCH(18,'🚗 BÁO GIÁ TURBO '!$W$4:$W$690,0))="","",INDEX('🚗 BÁO GIÁ TURBO '!$B$4:$B$690,MATCH(18,'🚗 BÁO GIÁ TURBO '!$W$4:$W$690,0))),"") | C25: =IFERROR(IF(INDEX('🚗 BÁO GIÁ TURBO '!$D$4:$D$690,MATCH(18,'🚗 BÁO GIÁ TURBO '!$W$4:$W$690,0))="","",INDEX('🚗 BÁO GIÁ TURBO '!$D$4:$D$690,MATCH(18,'🚗 BÁO GIÁ TURBO '!$W$4:$W$690,0))),"") | D25: =IFERROR(IF(INDEX('🚗 BÁO GIÁ TURBO '!$E$4:$E$690,MATCH(18,'🚗 BÁO GIÁ TURBO '!$W$4:$W$690,0))="","",INDEX('🚗 BÁO GIÁ TURBO '!$E$4:$E$690,MATCH(18,'🚗 BÁO GIÁ TURBO '!$W$4:$W$690,0))),"") | E25: =IFERROR(IF(INDEX('🚗 BÁO GIÁ TURBO '!$F$4:$F$690,MATCH(18,'🚗 BÁO GIÁ TURBO '!$W$4:$W$690,0))="","",INDEX('🚗 BÁO GIÁ TURBO '!$F$4:$F$690,MATCH(18,'🚗 BÁO GIÁ TURBO '!$W$4:$W$690,0))),"") | F25: =IFERROR(IF(INDEX('🚗 BÁO GIÁ TURBO '!$G$4:$G$690,MATCH(18,'🚗 BÁO GIÁ TURBO '!$W$4:$W$690,0))="","",INDEX('🚗 BÁO GIÁ TURBO '!$G$4:$G$690,MATCH(18,'🚗 BÁO GIÁ TURBO '!$W$4:$W$690,0))),"") | G25: =IFERROR(IF(INDEX('🚗 BÁO GIÁ TURBO '!$H$4:$H$690,MATCH(18,'🚗 BÁO GIÁ TURBO '!$W$4:$W$690,0))="","",INDEX('🚗 BÁO GIÁ TURBO '!$H$4:$H$690,MATCH(18,'🚗 BÁO GIÁ TURBO '!$W$4:$W$690,0))),"") | H25: =IFERROR(IF(INDEX('🚗 BÁO GIÁ TURBO '!$I$4:$I$690,MATCH(18,'🚗 BÁO GIÁ TURBO '!$W$4:$W$690,0))="","",INDEX('🚗 BÁO GIÁ TURBO '!$I$4:$I$690,MATCH(18,'🚗 BÁO GIÁ TURBO '!$W$4:$W$690,0))),"") | I25: =IFERROR(IF(INDEX('🚗 BÁO GIÁ TURBO '!$J$4:$J$690,MATCH(18,'🚗 BÁO GIÁ TURBO '!$W$4:$W$690,0))="","",INDEX('🚗 BÁO GIÁ TURBO '!$J$4:$J$690,MATCH(18,'🚗 BÁO GIÁ TURBO '!$W$4:$W$690,0))),"")
A26: =IFERROR(IF(INDEX('🚗 BÁO GIÁ TURBO '!$A$4:$A$690,MATCH(19,'🚗 BÁO GIÁ TURBO '!$W$4:$W$690,0))="","",INDEX('🚗 BÁO GIÁ TURBO '!$A$4:$A$690,MATCH(19,'🚗 BÁO GIÁ TURBO '!$W$4:$W$690,0))),"") | B26: =IFERROR(IF(INDEX('🚗 BÁO GIÁ TURBO '!$B$4:$B$690,MATCH(19,'🚗 BÁO GIÁ TURBO '!$W$4:$W$690,0))="","",INDEX('🚗 BÁO GIÁ TURBO '!$B$4:$B$690,MATCH(19,'🚗 BÁO GIÁ TURBO '!$W$4:$W$690,0))),"") | C26: =IFERROR(IF(INDEX('🚗 BÁO GIÁ TURBO '!$D$4:$D$690,MATCH(19,'🚗 BÁO GIÁ TURBO '!$W$4:$W$690,0))="","",INDEX('🚗 BÁO GIÁ TURBO '!$D$4:$D$690,MATCH(19,'🚗 BÁO GIÁ TURBO '!$W$4:$W$690,0))),"") | D26: =IFERROR(IF(INDEX('🚗 BÁO GIÁ TURBO '!$E$4:$E$690,MATCH(19,'🚗 BÁO GIÁ TURBO '!$W$4:$W$690,0))="","",INDEX('🚗 BÁO GIÁ TURBO '!$E$4:$E$690,MATCH(19,'🚗 BÁO GIÁ TURBO '!$W$4:$W$690,0))),"") | E26: =IFERROR(IF(INDEX('🚗 BÁO GIÁ TURBO '!$F$4:$F$690,MATCH(19,'🚗 BÁO GIÁ TURBO '!$W$4:$W$690,0))="","",INDEX('🚗 BÁO GIÁ TURBO '!$F$4:$F$690,MATCH(19,'🚗 BÁO GIÁ TURBO '!$W$4:$W$690,0))),"") | F26: =IFERROR(IF(INDEX('🚗 BÁO GIÁ TURBO '!$G$4:$G$690,MATCH(19,'🚗 BÁO GIÁ TURBO '!$W$4:$W$690,0))="","",INDEX('🚗 BÁO GIÁ TURBO '!$G$4:$G$690,MATCH(19,'🚗 BÁO GIÁ TURBO '!$W$4:$W$690,0))),"") | G26: =IFERROR(IF(INDEX('🚗 BÁO GIÁ TURBO '!$H$4:$H$690,MATCH(19,'🚗 BÁO GIÁ TURBO '!$W$4:$W$690,0))="","",INDEX('🚗 BÁO GIÁ TURBO '!$H$4:$H$690,MATCH(19,'🚗 BÁO GIÁ TURBO '!$W$4:$W$690,0))),"") | H26: =IFERROR(IF(INDEX('🚗 BÁO GIÁ TURBO '!$I$4:$I$690,MATCH(19,'🚗 BÁO GIÁ TURBO '!$W$4:$W$690,0))="","",INDEX('🚗 BÁO GIÁ TURBO '!$I$4:$I$690,MATCH(19,'🚗 BÁO GIÁ TURBO '!$W$4:$W$690,0))),"") | I26: =IFERROR(IF(INDEX('🚗 BÁO GIÁ TURBO '!$J$4:$J$690,MATCH(19,'🚗 BÁO GIÁ TURBO '!$W$4:$W$690,0))="","",INDEX('🚗 BÁO GIÁ TURBO '!$J$4:$J$690,MATCH(19,'🚗 BÁO GIÁ TURBO '!$W$4:$W$690,0))),"")
A27: =IFERROR(IF(INDEX('🚗 BÁO GIÁ TURBO '!$A$4:$A$690,MATCH(20,'🚗 BÁO GIÁ TURBO '!$W$4:$W$690,0))="","",INDEX('🚗 BÁO GIÁ TURBO '!$A$4:$A$690,MATCH(20,'🚗 BÁO GIÁ TURBO '!$W$4:$W$690,0))),"") | B27: =IFERROR(IF(INDEX('🚗 BÁO GIÁ TURBO '!$B$4:$B$690,MATCH(20,'🚗 BÁO GIÁ TURBO '!$W$4:$W$690,0))="","",INDEX('🚗 BÁO GIÁ TURBO '!$B$4:$B$690,MATCH(20,'🚗 BÁO GIÁ TURBO '!$W$4:$W$690,0))),"") | C27: =IFERROR(IF(INDEX('🚗 BÁO GIÁ TURBO '!$D$4:$D$690,MATCH(20,'🚗 BÁO GIÁ TURBO '!$W$4:$W$690,0))="","",INDEX('🚗 BÁO GIÁ TURBO '!$D$4:$D$690,MATCH(20,'🚗 BÁO GIÁ TURBO '!$W$4:$W$690,0))),"") | D27: =IFERROR(IF(INDEX('🚗 BÁO GIÁ TURBO '!$E$4:$E$690,MATCH(20,'🚗 BÁO GIÁ TURBO '!$W$4:$W$690,0))="","",INDEX('🚗 BÁO GIÁ TURBO '!$E$4:$E$690,MATCH(20,'🚗 BÁO GIÁ TURBO '!$W$4:$W$690,0))),"") | E27: =IFERROR(IF(INDEX('🚗 BÁO GIÁ TURBO '!$F$4:$F$690,MATCH(20,'🚗 BÁO GIÁ TURBO '!$W$4:$W$690,0))="","",INDEX('🚗 BÁO GIÁ TURBO '!$F$4:$F$690,MATCH(20,'🚗 BÁO GIÁ TURBO '!$W$4:$W$690,0))),"") | F27: =IFERROR(IF(INDEX('🚗 BÁO GIÁ TURBO '!$G$4:$G$690,MATCH(20,'🚗 BÁO GIÁ TURBO '!$W$4:$W$690,0))="","",INDEX('🚗 BÁO GIÁ TURBO '!$G$4:$G$690,MATCH(20,'🚗 BÁO GIÁ TURBO '!$W$4:$W$690,0))),"") | G27: =IFERROR(IF(INDEX('🚗 BÁO GIÁ TURBO '!$H$4:$H$690,MATCH(20,'🚗 BÁO GIÁ TURBO '!$W$4:$W$690,0))="","",INDEX('🚗 BÁO GIÁ TURBO '!$H$4:$H$690,MATCH(20,'🚗 BÁO GIÁ TURBO '!$W$4:$W$690,0))),"") | H27: =IFERROR(IF(INDEX('🚗 BÁO GIÁ TURBO '!$I$4:$I$690,MATCH(20,'🚗 BÁO GIÁ TURBO '!$W$4:$W$690,0))="","",INDEX('🚗 BÁO GIÁ TURBO '!$I$4:$I$690,MATCH(20,'🚗 BÁO GIÁ TURBO '!$W$4:$W$690,0))),"") | I27: =IFERROR(IF(INDEX('🚗 BÁO GIÁ TURBO '!$J$4:$J$690,MATCH(20,'🚗 BÁO GIÁ TURBO '!$W$4:$W$690,0))="","",INDEX('🚗 BÁO GIÁ TURBO '!$J$4:$J$690,MATCH(20,'🚗 BÁO GIÁ TURBO '!$W$4:$W$690,0))),"")
A30: 🔧 RUỘT TURBO (kết quả tra cứu — tối đa 20 dòng)
A31: HÃNG MÁY | B31: MÃ VT | C31: MODEL TURBO | D31: MÃ ĐỘNG CƠ | E31: OEM PART NO | F31: ĐẶC ĐIỂM | G31: ỨNG DỤNG | H31: GHI CHÚ | I31: THƯƠNG HIỆU
A32: =IFERROR(IF(INDEX('RUỘT TURBO'!$A$4:$A$892,MATCH(1,'RUỘT TURBO'!$U$4:$U$892,0))="","",INDEX('RUỘT TURBO'!$A$4:$A$892,MATCH(1,'RUỘT TURBO'!$U$4:$U$892,0))),"") | B32: =IFERROR(IF(INDEX('RUỘT TURBO'!$B$4:$B$892,MATCH(1,'RUỘT TURBO'!$U$4:$U$892,0))="","",INDEX('RUỘT TURBO'!$B$4:$B$892,MATCH(1,'RUỘT TURBO'!$U$4:$U$892,0))),"") | C32: =IFERROR(IF(INDEX('RUỘT TURBO'!$D$4:$D$892,MATCH(1,'RUỘT TURBO'!$U$4:$U$892,0))="","",INDEX('RUỘT TURBO'!$D$4:$D$892,MATCH(1,'RUỘT TURBO'!$U$4:$U$892,0))),"") | D32: =IFERROR(IF(INDEX('RUỘT TURBO'!$E$4:$E$892,MATCH(1,'RUỘT TURBO'!$U$4:$U$892,0))="","",INDEX('RUỘT TURBO'!$E$4:$E$892,MATCH(1,'RUỘT TURBO'!$U$4:$U$892,0))),"") | E32: =IFERROR(IF(INDEX('RUỘT TURBO'!$F$4:$F$892,MATCH(1,'RUỘT TURBO'!$U$4:$U$892,0))="","",INDEX('RUỘT TURBO'!$F$4:$F$892,MATCH(1,'RUỘT TURBO'!$U$4:$U$892,0))),"") | H32: =IFERROR(IF(INDEX('RUỘT TURBO'!$G$4:$G$892,MATCH(1,'RUỘT TURBO'!$U$4:$U$892,0))="","",INDEX('RUỘT TURBO'!$G$4:$G$892,MATCH(1,'RUỘT TURBO'!$U$4:$U$892,0))),"") | I32: =IFERROR(IF(INDEX('RUỘT TURBO'!$H$4:$H$892,MATCH(1,'RUỘT TURBO'!$U$4:$U$892,0))="","",INDEX('RUỘT TURBO'!$H$4:$H$892,MATCH(1,'RUỘT TURBO'!$U$4:$U$892,0))),"")
A33: =IFERROR(IF(INDEX('RUỘT TURBO'!$A$4:$A$892,MATCH(2,'RUỘT TURBO'!$U$4:$U$892,0))="","",INDEX('RUỘT TURBO'!$A$4:$A$892,MATCH(2,'RUỘT TURBO'!$U$4:$U$892,0))),"") | B33: =IFERROR(IF(INDEX('RUỘT TURBO'!$B$4:$B$892,MATCH(2,'RUỘT TURBO'!$U$4:$U$892,0))="","",INDEX('RUỘT TURBO'!$B$4:$B$892,MATCH(2,'RUỘT TURBO'!$U$4:$U$892,0))),"") | C33: =IFERROR(IF(INDEX('RUỘT TURBO'!$D$4:$D$892,MATCH(2,'RUỘT TURBO'!$U$4:$U$892,0))="","",INDEX('RUỘT TURBO'!$D$4:$D$892,MATCH(2,'RUỘT TURBO'!$U$4:$U$892,0))),"") | D33: =IFERROR(IF(INDEX('RUỘT TURBO'!$E$4:$E$892,MATCH(2,'RUỘT TURBO'!$U$4:$U$892,0))="","",INDEX('RUỘT TURBO'!$E$4:$E$892,MATCH(2,'RUỘT TURBO'!$U$4:$U$892,0))),"") | E33: =IFERROR(IF(INDEX('RUỘT TURBO'!$F$4:$F$892,MATCH(2,'RUỘT TURBO'!$U$4:$U$892,0))="","",INDEX('RUỘT TURBO'!$F$4:$F$892,MATCH(2,'RUỘT TURBO'!$U$4:$U$892,0))),"") | H33: =IFERROR(IF(INDEX('RUỘT TURBO'!$G$4:$G$892,MATCH(2,'RUỘT TURBO'!$U$4:$U$892,0))="","",INDEX('RUỘT TURBO'!$G$4:$G$892,MATCH(2,'RUỘT TURBO'!$U$4:$U$892,0))),"") | I33: =IFERROR(IF(INDEX('RUỘT TURBO'!$H$4:$H$892,MATCH(2,'RUỘT TURBO'!$U$4:$U$892,0))="","",INDEX('RUỘT TURBO'!$H$4:$H$892,MATCH(2,'RUỘT TURBO'!$U$4:$U$892,0))),"")
A34: =IFERROR(IF(INDEX('RUỘT TURBO'!$A$4:$A$892,MATCH(3,'RUỘT TURBO'!$U$4:$U$892,0))="","",INDEX('RUỘT TURBO'!$A$4:$A$892,MATCH(3,'RUỘT TURBO'!$U$4:$U$892,0))),"") | B34: =IFERROR(IF(INDEX('RUỘT TURBO'!$B$4:$B$892,MATCH(3,'RUỘT TURBO'!$U$4:$U$892,0))="","",INDEX('RUỘT TURBO'!$B$4:$B$892,MATCH(3,'RUỘT TURBO'!$U$4:$U$892,0))),"") | C34: =IFERROR(IF(INDEX('RUỘT TURBO'!$D$4:$D$892,MATCH(3,'RUỘT TURBO'!$U$4:$U$892,0))="","",INDEX('RUỘT TURBO'!$D$4:$D$892,MATCH(3,'RUỘT TURBO'!$U$4:$U$892,0))),"") | D34: =IFERROR(IF(INDEX('RUỘT TURBO'!$E$4:$E$892,MATCH(3,'RUỘT TURBO'!$U$4:$U$892,0))="","",INDEX('RUỘT TURBO'!$E$4:$E$892,MATCH(3,'RUỘT TURBO'!$U$4:$U$892,0))),"") | E34: =IFERROR(IF(INDEX('RUỘT TURBO'!$F$4:$F$892,MATCH(3,'RUỘT TURBO'!$U$4:$U$892,0))="","",INDEX('RUỘT TURBO'!$F$4:$F$892,MATCH(3,'RUỘT TURBO'!$U$4:$U$892,0))),"") | H34: =IFERROR(IF(INDEX('RUỘT TURBO'!$G$4:$G$892,MATCH(3,'RUỘT TURBO'!$U$4:$U$892,0))="","",INDEX('RUỘT TURBO'!$G$4:$G$892,MATCH(3,'RUỘT TURBO'!$U$4:$U$892,0))),"") | I34: =IFERROR(IF(INDEX('RUỘT TURBO'!$H$4:$H$892,MATCH(3,'RUỘT TURBO'!$U$4:$U$892,0))="","",INDEX('RUỘT TURBO'!$H$4:$H$892,MATCH(3,'RUỘT TURBO'!$U$4:$U$892,0))),"")
A35: =IFERROR(IF(INDEX('RUỘT TURBO'!$A$4:$A$892,MATCH(4,'RUỘT TURBO'!$U$4:$U$892,0))="","",INDEX('RUỘT TURBO'!$A$4:$A$892,MATCH(4,'RUỘT TURBO'!$U$4:$U$892,0))),"") | B35: =IFERROR(IF(INDEX('RUỘT TURBO'!$B$4:$B$892,MATCH(4,'RUỘT TURBO'!$U$4:$U$892,0))="","",INDEX('RUỘT TURBO'!$B$4:$B$892,MATCH(4,'RUỘT TURBO'!$U$4:$U$892,0))),"") | C35: =IFERROR(IF(INDEX('RUỘT TURBO'!$D$4:$D$892,MATCH(4,'RUỘT TURBO'!$U$4:$U$892,0))="","",INDEX('RUỘT TURBO'!$D$4:$D$892,MATCH(4,'RUỘT TURBO'!$U$4:$U$892,0))),"") | D35: =IFERROR(IF(INDEX('RUỘT TURBO'!$E$4:$E$892,MATCH(4,'RUỘT TURBO'!$U$4:$U$892,0))="","",INDEX('RUỘT TURBO'!$E$4:$E$892,MATCH(4,'RUỘT TURBO'!$U$4:$U$892,0))),"") | E35: =IFERROR(IF(INDEX('RUỘT TURBO'!$F$4:$F$892,MATCH(4,'RUỘT TURBO'!$U$4:$U$892,0))="","",INDEX('RUỘT TURBO'!$F$4:$F$892,MATCH(4,'RUỘT TURBO'!$U$4:$U$892,0))),"") | H35: =IFERROR(IF(INDEX('RUỘT TURBO'!$G$4:$G$892,MATCH(4,'RUỘT TURBO'!$U$4:$U$892,0))="","",INDEX('RUỘT TURBO'!$G$4:$G$892,MATCH(4,'RUỘT TURBO'!$U$4:$U$892,0))),"") | I35: =IFERROR(IF(INDEX('RUỘT TURBO'!$H$4:$H$892,MATCH(4,'RUỘT TURBO'!$U$4:$U$892,0))="","",INDEX('RUỘT TURBO'!$H$4:$H$892,MATCH(4,'RUỘT TURBO'!$U$4:$U$892,0))),"")
A36: =IFERROR(IF(INDEX('RUỘT TURBO'!$A$4:$A$892,MATCH(5,'RUỘT TURBO'!$U$4:$U$892,0))="","",INDEX('RUỘT TURBO'!$A$4:$A$892,MATCH(5,'RUỘT TURBO'!$U$4:$U$892,0))),"") | B36: =IFERROR(IF(INDEX('RUỘT TURBO'!$B$4:$B$892,MATCH(5,'RUỘT TURBO'!$U$4:$U$892,0))="","",INDEX('RUỘT TURBO'!$B$4:$B$892,MATCH(5,'RUỘT TURBO'!$U$4:$U$892,0))),"") | C36: =IFERROR(IF(INDEX('RUỘT TURBO'!$D$4:$D$892,MATCH(5,'RUỘT TURBO'!$U$4:$U$892,0))="","",INDEX('RUỘT TURBO'!$D$4:$D$892,MATCH(5,'RUỘT TURBO'!$U$4:$U$892,0))),"") | D36: =IFERROR(IF(INDEX('RUỘT TURBO'!$E$4:$E$892,MATCH(5,'RUỘT TURBO'!$U$4:$U$892,0))="","",INDEX('RUỘT TURBO'!$E$4:$E$892,MATCH(5,'RUỘT TURBO'!$U$4:$U$892,0))),"") | E36: =IFERROR(IF(INDEX('RUỘT TURBO'!$F$4:$F$892,MATCH(5,'RUỘT TURBO'!$U$4:$U$892,0))="","",INDEX('RUỘT TURBO'!$F$4:$F$892,MATCH(5,'RUỘT TURBO'!$U$4:$U$892,0))),"") | H36: =IFERROR(IF(INDEX('RUỘT TURBO'!$G$4:$G$892,MATCH(5,'RUỘT TURBO'!$U$4:$U$892,0))="","",INDEX('RUỘT TURBO'!$G$4:$G$892,MATCH(5,'RUỘT TURBO'!$U$4:$U$892,0))),"") | I36: =IFERROR(IF(INDEX('RUỘT TURBO'!$H$4:$H$892,MATCH(5,'RUỘT TURBO'!$U$4:$U$892,0))="","",INDEX('RUỘT TURBO'!$H$4:$H$892,MATCH(5,'RUỘT TURBO'!$U$4:$U$892,0))),"")
A37: =IFERROR(IF(INDEX('RUỘT TURBO'!$A$4:$A$892,MATCH(6,'RUỘT TURBO'!$U$4:$U$892,0))="","",INDEX('RUỘT TURBO'!$A$4:$A$892,MATCH(6,'RUỘT TURBO'!$U$4:$U$892,0))),"") | B37: =IFERROR(IF(INDEX('RUỘT TURBO'!$B$4:$B$892,MATCH(6,'RUỘT TURBO'!$U$4:$U$892,0))="","",INDEX('RUỘT TURBO'!$B$4:$B$892,MATCH(6,'RUỘT TURBO'!$U$4:$U$892,0))),"") | C37: =IFERROR(IF(INDEX('RUỘT TURBO'!$D$4:$D$892,MATCH(6,'RUỘT TURBO'!$U$4:$U$892,0))="","",INDEX('RUỘT TURBO'!$D$4:$D$892,MATCH(6,'RUỘT TURBO'!$U$4:$U$892,0))),"") | D37: =IFERROR(IF(INDEX('RUỘT TURBO'!$E$4:$E$892,MATCH(6,'RUỘT TURBO'!$U$4:$U$892,0))="","",INDEX('RUỘT TURBO'!$E$4:$E$892,MATCH(6,'RUỘT TURBO'!$U$4:$U$892,0))),"") | E37: =IFERROR(IF(INDEX('RUỘT TURBO'!$F$4:$F$892,MATCH(6,'RUỘT TURBO'!$U$4:$U$892,0))="","",INDEX('RUỘT TURBO'!$F$4:$F$892,MATCH(6,'RUỘT TURBO'!$U$4:$U$892,0))),"") | H37: =IFERROR(IF(INDEX('RUỘT TURBO'!$G$4:$G$892,MATCH(6,'RUỘT TURBO'!$U$4:$U$892,0))="","",INDEX('RUỘT TURBO'!$G$4:$G$892,MATCH(6,'RUỘT TURBO'!$U$4:$U$892,0))),"") | I37: =IFERROR(IF(INDEX('RUỘT TURBO'!$H$4:$H$892,MATCH(6,'RUỘT TURBO'!$U$4:$U$892,0))="","",INDEX('RUỘT TURBO'!$H$4:$H$892,MATCH(6,'RUỘT TURBO'!$U$4:$U$892,0))),"")
A38: =IFERROR(IF(INDEX('RUỘT TURBO'!$A$4:$A$892,MATCH(7,'RUỘT TURBO'!$U$4:$U$892,0))="","",INDEX('RUỘT TURBO'!$A$4:$A$892,MATCH(7,'RUỘT TURBO'!$U$4:$U$892,0))),"") | B38: =IFERROR(IF(INDEX('RUỘT TURBO'!$B$4:$B$892,MATCH(7,'RUỘT TURBO'!$U$4:$U$892,0))="","",INDEX('RUỘT TURBO'!$B$4:$B$892,MATCH(7,'RUỘT TURBO'!$U$4:$U$892,0))),"") | C38: =IFERROR(IF(INDEX('RUỘT TURBO'!$D$4:$D$892,MATCH(7,'RUỘT TURBO'!$U$4:$U$892,0))="","",INDEX('RUỘT TURBO'!$D$4:$D$892,MATCH(7,'RUỘT TURBO'!$U$4:$U$892,0))),"") | D38: =IFERROR(IF(INDEX('RUỘT TURBO'!$E$4:$E$892,MATCH(7,'RUỘT TURBO'!$U$4:$U$892,0))="","",INDEX('RUỘT TURBO'!$E$4:$E$892,MATCH(7,'RUỘT TURBO'!$U$4:$U$892,0))),"") | E38: =IFERROR(IF(INDEX('RUỘT TURBO'!$F$4:$F$892,MATCH(7,'RUỘT TURBO'!$U$4:$U$892,0))="","",INDEX('RUỘT TURBO'!$F$4:$F$892,MATCH(7,'RUỘT TURBO'!$U$4:$U$892,0))),"") | H38: =IFERROR(IF(INDEX('RUỘT TURBO'!$G$4:$G$892,MATCH(7,'RUỘT TURBO'!$U$4:$U$892,0))="","",INDEX('RUỘT TURBO'!$G$4:$G$892,MATCH(7,'RUỘT TURBO'!$U$4:$U$892,0))),"") | I38: =IFERROR(IF(INDEX('RUỘT TURBO'!$H$4:$H$892,MATCH(7,'RUỘT TURBO'!$U$4:$U$892,0))="","",INDEX('RUỘT TURBO'!$H$4:$H$892,MATCH(7,'RUỘT TURBO'!$U$4:$U$892,0))),"")
A39: =IFERROR(IF(INDEX('RUỘT TURBO'!$A$4:$A$892,MATCH(8,'RUỘT TURBO'!$U$4:$U$892,0))="","",INDEX('RUỘT TURBO'!$A$4:$A$892,MATCH(8,'RUỘT TURBO'!$U$4:$U$892,0))),"") | B39: =IFERROR(IF(INDEX('RUỘT TURBO'!$B$4:$B$892,MATCH(8,'RUỘT TURBO'!$U$4:$U$892,0))="","",INDEX('RUỘT TURBO'!$B$4:$B$892,MATCH(8,'RUỘT TURBO'!$U$4:$U$892,0))),"") | C39: =IFERROR(IF(INDEX('RUỘT TURBO'!$D$4:$D$892,MATCH(8,'RUỘT TURBO'!$U$4:$U$892,0))="","",INDEX('RUỘT TURBO'!$D$4:$D$892,MATCH(8,'RUỘT TURBO'!$U$4:$U$892,0))),"") | D39: =IFERROR(IF(INDEX('RUỘT TURBO'!$E$4:$E$892,MATCH(8,'RUỘT TURBO'!$U$4:$U$892,0))="","",INDEX('RUỘT TURBO'!$E$4:$E$892,MATCH(8,'RUỘT TURBO'!$U$4:$U$892,0))),"") | E39: =IFERROR(IF(INDEX('RUỘT TURBO'!$F$4:$F$892,MATCH(8,'RUỘT TURBO'!$U$4:$U$892,0))="","",INDEX('RUỘT TURBO'!$F$4:$F$892,MATCH(8,'RUỘT TURBO'!$U$4:$U$892,0))),"") | H39: =IFERROR(IF(INDEX('RUỘT TURBO'!$G$4:$G$892,MATCH(8,'RUỘT TURBO'!$U$4:$U$892,0))="","",INDEX('RUỘT TURBO'!$G$4:$G$892,MATCH(8,'RUỘT TURBO'!$U$4:$U$892,0))),"") | I39: =IFERROR(IF(INDEX('RUỘT TURBO'!$H$4:$H$892,MATCH(8,'RUỘT TURBO'!$U$4:$U$892,0))="","",INDEX('RUỘT TURBO'!$H$4:$H$892,MATCH(8,'RUỘT TURBO'!$U$4:$U$892,0))),"")
A40: =IFERROR(IF(INDEX('RUỘT TURBO'!$A$4:$A$892,MATCH(9,'RUỘT TURBO'!$U$4:$U$892,0))="","",INDEX('RUỘT TURBO'!$A$4:$A$892,MATCH(9,'RUỘT TURBO'!$U$4:$U$892,0))),"") | B40: =IFERROR(IF(INDEX('RUỘT TURBO'!$B$4:$B$892,MATCH(9,'RUỘT TURBO'!$U$4:$U$892,0))="","",INDEX('RUỘT TURBO'!$B$4:$B$892,MATCH(9,'RUỘT TURBO'!$U$4:$U$892,0))),"") | C40: =IFERROR(IF(INDEX('RUỘT TURBO'!$D$4:$D$892,MATCH(9,'RUỘT TURBO'!$U$4:$U$892,0))="","",INDEX('RUỘT TURBO'!$D$4:$D$892,MATCH(9,'RUỘT TURBO'!$U$4:$U$892,0))),"") | D40: =IFERROR(IF(INDEX('RUỘT TURBO'!$E$4:$E$892,MATCH(9,'RUỘT TURBO'!$U$4:$U$892,0))="","",INDEX('RUỘT TURBO'!$E$4:$E$892,MATCH(9,'RUỘT TURBO'!$U$4:$U$892,0))),"") | E40: =IFERROR(IF(INDEX('RUỘT TURBO'!$F$4:$F$892,MATCH(9,'RUỘT TURBO'!$U$4:$U$892,0))="","",INDEX('RUỘT TURBO'!$F$4:$F$892,MATCH(9,'RUỘT TURBO'!$U$4:$U$892,0))),"") | H40: =IFERROR(IF(INDEX('RUỘT TURBO'!$G$4:$G$892,MATCH(9,'RUỘT TURBO'!$U$4:$U$892,0))="","",INDEX('RUỘT TURBO'!$G$4:$G$892,MATCH(9,'RUỘT TURBO'!$U$4:$U$892,0))),"") | I40: =IFERROR(IF(INDEX('RUỘT TURBO'!$H$4:$H$892,MATCH(9,'RUỘT TURBO'!$U$4:$U$892,0))="","",INDEX('RUỘT TURBO'!$H$4:$H$892,MATCH(9,'RUỘT TURBO'!$U$4:$U$892,0))),"")
A41: =IFERROR(IF(INDEX('RUỘT TURBO'!$A$4:$A$892,MATCH(10,'RUỘT TURBO'!$U$4:$U$892,0))="","",INDEX('RUỘT TURBO'!$A$4:$A$892,MATCH(10,'RUỘT TURBO'!$U$4:$U$892,0))),"") | B41: =IFERROR(IF(INDEX('RUỘT TURBO'!$B$4:$B$892,MATCH(10,'RUỘT TURBO'!$U$4:$U$892,0))="","",INDEX('RUỘT TURBO'!$B$4:$B$892,MATCH(10,'RUỘT TURBO'!$U$4:$U$892,0))),"") | C41: =IFERROR(IF(INDEX('RUỘT TURBO'!$D$4:$D$892,MATCH(10,'RUỘT TURBO'!$U$4:$U$892,0))="","",INDEX('RUỘT TURBO'!$D$4:$D$892,MATCH(10,'RUỘT TURBO'!$U$4:$U$892,0))),"") | D41: =IFERROR(IF(INDEX('RUỘT TURBO'!$E$4:$E$892,MATCH(10,'RUỘT TURBO'!$U$4:$U$892,0))="","",INDEX('RUỘT TURBO'!$E$4:$E$892,MATCH(10,'RUỘT TURBO'!$U$4:$U$892,0))),"") | E41: =IFERROR(IF(INDEX('RUỘT TURBO'!$F$4:$F$892,MATCH(10,'RUỘT TURBO'!$U$4:$U$892,0))="","",INDEX('RUỘT TURBO'!$F$4:$F$892,MATCH(10,'RUỘT TURBO'!$U$4:$U$892,0))),"") | H41: =IFERROR(IF(INDEX('RUỘT TURBO'!$G$4:$G$892,MATCH(10,'RUỘT TURBO'!$U$4:$U$892,0))="","",INDEX('RUỘT TURBO'!$G$4:$G$892,MATCH(10,'RUỘT TURBO'!$U$4:$U$892,0))),"") | I41: =IFERROR(IF(INDEX('RUỘT TURBO'!$H$4:$H$892,MATCH(10,'RUỘT TURBO'!$U$4:$U$892,0))="","",INDEX('RUỘT TURBO'!$H$4:$H$892,MATCH(10,'RUỘT TURBO'!$U$4:$U$892,0))),"")
A42: =IFERROR(IF(INDEX('RUỘT TURBO'!$A$4:$A$892,MATCH(11,'RUỘT TURBO'!$U$4:$U$892,0))="","",INDEX('RUỘT TURBO'!$A$4:$A$892,MATCH(11,'RUỘT TURBO'!$U$4:$U$892,0))),"") | B42: =IFERROR(IF(INDEX('RUỘT TURBO'!$B$4:$B$892,MATCH(11,'RUỘT TURBO'!$U$4:$U$892,0))="","",INDEX('RUỘT TURBO'!$B$4:$B$892,MATCH(11,'RUỘT TURBO'!$U$4:$U$892,0))),"") | C42: =IFERROR(IF(INDEX('RUỘT TURBO'!$D$4:$D$892,MATCH(11,'RUỘT TURBO'!$U$4:$U$892,0))="","",INDEX('RUỘT TURBO'!$D$4:$D$892,MATCH(11,'RUỘT TURBO'!$U$4:$U$892,0))),"") | D42: =IFERROR(IF(INDEX('RUỘT TURBO'!$E$4:$E$892,MATCH(11,'RUỘT TURBO'!$U$4:$U$892,0))="","",INDEX('RUỘT TURBO'!$E$4:$E$892,MATCH(11,'RUỘT TURBO'!$U$4:$U$892,0))),"") | E42: =IFERROR(IF(INDEX('RUỘT TURBO'!$F$4:$F$892,MATCH(11,'RUỘT TURBO'!$U$4:$U$892,0))="","",INDEX('RUỘT TURBO'!$F$4:$F$892,MATCH(11,'RUỘT TURBO'!$U$4:$U$892,0))),"") | H42: =IFERROR(IF(INDEX('RUỘT TURBO'!$G$4:$G$892,MATCH(11,'RUỘT TURBO'!$U$4:$U$892,0))="","",INDEX('RUỘT TURBO'!$G$4:$G$892,MATCH(11,'RUỘT TURBO'!$U$4:$U$892,0))),"") | I42: =IFERROR(IF(INDEX('RUỘT TURBO'!$H$4:$H$892,MATCH(11,'RUỘT TURBO'!$U$4:$U$892,0))="","",INDEX('RUỘT TURBO'!$H$4:$H$892,MATCH(11,'RUỘT TURBO'!$U$4:$U$892,0))),"")
A43: =IFERROR(IF(INDEX('RUỘT TURBO'!$A$4:$A$892,MATCH(12,'RUỘT TURBO'!$U$4:$U$892,0))="","",INDEX('RUỘT TURBO'!$A$4:$A$892,MATCH(12,'RUỘT TURBO'!$U$4:$U$892,0))),"") | B43: =IFERROR(IF(INDEX('RUỘT TURBO'!$B$4:$B$892,MATCH(12,'RUỘT TURBO'!$U$4:$U$892,0))="","",INDEX('RUỘT TURBO'!$B$4:$B$892,MATCH(12,'RUỘT TURBO'!$U$4:$U$892,0))),"") | C43: =IFERROR(IF(INDEX('RUỘT TURBO'!$D$4:$D$892,MATCH(12,'RUỘT TURBO'!$U$4:$U$892,0))="","",INDEX('RUỘT TURBO'!$D$4:$D$892,MATCH(12,'RUỘT TURBO'!$U$4:$U$892,0))),"") | D43: =IFERROR(IF(INDEX('RUỘT TURBO'!$E$4:$E$892,MATCH(12,'RUỘT TURBO'!$U$4:$U$892,0))="","",INDEX('RUỘT TURBO'!$E$4:$E$892,MATCH(12,'RUỘT TURBO'!$U$4:$U$892,0))),"") | E43: =IFERROR(IF(INDEX('RUỘT TURBO'!$F$4:$F$892,MATCH(12,'RUỘT TURBO'!$U$4:$U$892,0))="","",INDEX('RUỘT TURBO'!$F$4:$F$892,MATCH(12,'RUỘT TURBO'!$U$4:$U$892,0))),"") | H43: =IFERROR(IF(INDEX('RUỘT TURBO'!$G$4:$G$892,MATCH(12,'RUỘT TURBO'!$U$4:$U$892,0))="","",INDEX('RUỘT TURBO'!$G$4:$G$892,MATCH(12,'RUỘT TURBO'!$U$4:$U$892,0))),"") | I43: =IFERROR(IF(INDEX('RUỘT TURBO'!$H$4:$H$892,MATCH(12,'RUỘT TURBO'!$U$4:$U$892,0))="","",INDEX('RUỘT TURBO'!$H$4:$H$892,MATCH(12,'RUỘT TURBO'!$U$4:$U$892,0))),"")
A44: =IFERROR(IF(INDEX('RUỘT TURBO'!$A$4:$A$892,MATCH(13,'RUỘT TURBO'!$U$4:$U$892,0))="","",INDEX('RUỘT TURBO'!$A$4:$A$892,MATCH(13,'RUỘT TURBO'!$U$4:$U$892,0))),"") | B44: =IFERROR(IF(INDEX('RUỘT TURBO'!$B$4:$B$892,MATCH(13,'RUỘT TURBO'!$U$4:$U$892,0))="","",INDEX('RUỘT TURBO'!$B$4:$B$892,MATCH(13,'RUỘT TURBO'!$U$4:$U$892,0))),"") | C44: =IFERROR(IF(INDEX('RUỘT TURBO'!$D$4:$D$892,MATCH(13,'RUỘT TURBO'!$U$4:$U$892,0))="","",INDEX('RUỘT TURBO'!$D$4:$D$892,MATCH(13,'RUỘT TURBO'!$U$4:$U$892,0))),"") | D44: =IFERROR(IF(INDEX('RUỘT TURBO'!$E$4:$E$892,MATCH(13,'RUỘT TURBO'!$U$4:$U$892,0))="","",INDEX('RUỘT TURBO'!$E$4:$E$892,MATCH(13,'RUỘT TURBO'!$U$4:$U$892,0))),"") | E44: =IFERROR(IF(INDEX('RUỘT TURBO'!$F$4:$F$892,MATCH(13,'RUỘT TURBO'!$U$4:$U$892,0))="","",INDEX('RUỘT TURBO'!$F$4:$F$892,MATCH(13,'RUỘT TURBO'!$U$4:$U$892,0))),"") | H44: =IFERROR(IF(INDEX('RUỘT TURBO'!$G$4:$G$892,MATCH(13,'RUỘT TURBO'!$U$4:$U$892,0))="","",INDEX('RUỘT TURBO'!$G$4:$G$892,MATCH(13,'RUỘT TURBO'!$U$4:$U$892,0))),"") | I44: =IFERROR(IF(INDEX('RUỘT TURBO'!$H$4:$H$892,MATCH(13,'RUỘT TURBO'!$U$4:$U$892,0))="","",INDEX('RUỘT TURBO'!$H$4:$H$892,MATCH(13,'RUỘT TURBO'!$U$4:$U$892,0))),"")
...

Sheet 🚗 BÁO GIÁ TURBO 
A1: 🚗 BÁO GIÁ TURBO — TRA CỨU THEO HÃNG MÁY · Gom mã cùng PARNO
A2: 🟡 Vàng = mã gốc có biến thể cùng PARNO · 🟠 Cam = mã khác thương hiệu (cùng PARNO) · 🟢 Xanh = MÃ VT vừa điền
A3: HÃNG MÁY | B3: MÃ VT | C3: HÃNG SX | D3: MODEL TURBO | E3: MÃ ĐỘNG CƠ | F3: OEM PART NO | G3: ĐẶC ĐIỂM | H3: ỨNG DỤNG | I3: GHI CHÚ | J3: THƯƠNG HIỆU | K3: GIÁ VIP | L3: GIÁ ƯU ĐÃI | M3: GIÁ ĐẠI LÝ | N3: GIÁ ĐL +10% | O3: CG Ø DƯỚI | P3: CG Ø ĐỈNH | Q3: CG SỐ | R3: CL Ø DƯỚI | S3: CL Ø ĐỈNH | T3: CL SỐ | V3: _BLOB | W3: 0
A4: 🏭 CAT · 34 loại turbo | W4: =IF(AND('TRA CỨU TỔNG HỢP'!$B$3<>"",ISNUMBER(SEARCH('TRA CỨU TỔNG HỢP'!$B$3,V4))),MAX($W$3:W3)+1,"")
A5: CAT | B5: HH077147 | D5: Cat E320D/C6.4/ TD06H | F5: 49179-02910 8M06-100-E63 | J5: JRONE | N5: =IF(M5="","",M5*1.1) | V5: =UPPER(A5&" "&B5&" "&D5&" "&E5&" "&F5&" "&G5&" "&H5&" "&I5&" "&J5) | W5: =IF(AND('TRA CỨU TỔNG HỢP'!$B$3<>"",ISNUMBER(SEARCH('TRA CỨU TỔNG HỢP'!$B$3,V5))),MAX($W$3:W4)+1,"")
A6: └─ CAT | B6: HH081913 | D6: Cat E320D/C6.4/ TD06H | F6: 49179-02910 8M06-100-E63 | J6: VIDARIR | N6: =IF(M6="","",M6*1.1) | V6: =UPPER(A6&" "&B6&" "&D6&" "&E6&" "&F6&" "&G6&" "&H6&" "&I6&" "&J6) | W6: =IF(AND('TRA CỨU TỔNG HỢP'!$B$3<>"",ISNUMBER(SEARCH('TRA CỨU TỔNG HỢP'!$B$3,V6))),MAX($W$3:W5)+1,"")
A7: CAT | B7: HH075291 | C7: Mitsubishi | D7: TD06H-16M | E7: 3066/S6KT | F7: 49179-02820 8M06-100-E68 | G7: Tâm lỗ bu lông 44 x 86 | H7: E320C | J7: JRONE | N7: =IF(M7="","",M7*1.1) | V7: =UPPER(A7&" "&B7&" "&D7&" "&E7&" "&F7&" "&G7&" "&H7&" "&I7&" "&J7) | W7: =IF(AND('TRA CỨU TỔNG HỢP'!$B$3<>"",ISNUMBER(SEARCH('TRA CỨU TỔNG HỢP'!$B$3,V7))),MAX($W$3:W6)+1,"")
A8: CAT | B8: HH070130 | C8: BorgWarner | D8: S2A | E8: 3114 | F8: 317817/ 8S03-100-J37 | I8: 8S03-100-J37 | J8: JRONE | N8: =IF(M8="","",M8*1.1) | V8: =UPPER(A8&" "&B8&" "&D8&" "&E8&" "&F8&" "&G8&" "&H8&" "&I8&" "&J8) | W8: =IF(AND('TRA CỨU TỔNG HỢP'!$B$3<>"",ISNUMBER(SEARCH('TRA CỨU TỔNG HỢP'!$B$3,V8))),MAX($W$3:W7)+1,"")
A9: CAT | B9: HH071812 | C9: Mitsubishi | D9: TD06H-16M | E9: 3066/S6KT | F9: 49179-02300 5I8018/2797860 49179-08600 | G9: Tâm lỗ bu lông 44 x 86 | H9: E320C | J9: SL | N9: =IF(M9="","",M9*1.1) | V9: =UPPER(A9&" "&B9&" "&D9&" "&E9&" "&F9&" "&G9&" "&H9&" "&I9&" "&J9) | W9: =IF(AND('TRA CỨU TỔNG HỢP'!$B$3<>"",ISNUMBER(SEARCH('TRA CỨU TỔNG HỢP'!$B$3,V9))),MAX($W$3:W8)+1,"")
A10: CAT | B10: HH075289 | C10: Mitsubishi | D10: TE06H-16M | E10: S6KT | F10: 49179-02230 8M06-100-235 | G10: Tâm lỗ bu lông 44 x 86 | H10: E320B | J10: JRONE | N10: =IF(M10="","",M10*1.1) | V10: =UPPER(A10&" "&B10&" "&D10&" "&E10&" "&F10&" "&G10&" "&H10&" "&I10&" "&J10) | W10: =IF(AND('TRA CỨU TỔNG HỢP'!$B$3<>"",ISNUMBER(SEARCH('TRA CỨU TỔNG HỢP'!$B$3,V10))),MAX($W$3:W9)+1,"")
A11: └─ CAT | B11: HH071811 | C11: Mitsubishi | D11: TE06H-16M | E11: S6KT | F11: 49179-02230 8M06-100-235 | G11: Tâm lỗ bu lông 44 x 86 | H11: E320B | J11: SL | N11: =IF(M11="","",M11*1.1) | V11: =UPPER(A11&" "&B11&" "&D11&" "&E11&" "&F11&" "&G11&" "&H11&" "&I11&" "&J11) | W11: =IF(AND('TRA CỨU TỔNG HỢP'!$B$3<>"",ISNUMBER(SEARCH('TRA CỨU TỔNG HỢP'!$B$3,V11))),MAX($W$3:W10)+1,"")
A12: └─ CAT | B12: HH079980 | C12: Mitsubishi | D12: TE06H-16M | E12: S6KT | F12: 49179-02230 8M06-100-235 | G12: Tâm lỗ bu lông 44 x 86 | H12: E320B | N12: =IF(M12="","",M12*1.1) | V12: =UPPER(A12&" "&B12&" "&D12&" "&E12&" "&F12&" "&G12&" "&H12&" "&I12&" "&J12) | W12: =IF(AND('TRA CỨU TỔNG HỢP'!$B$3<>"",ISNUMBER(SEARCH('TRA CỨU TỔNG HỢP'!$B$3,V12))),MAX($W$3:W11)+1,"")
A13: CAT | B13: HH081733 | C13: Mitsubishi | D13: TD06H-14C | E13: S6KT/S4KT | F13: 49179-00451/49179-00451 | 49179-00450 | 4917900451 | 4917900450 | 5I-5015 | 5I5015 8M06-100-056/49179-00450 5I501549179-09830/49179-00451/4917900451/317013/49179-00450/4917900450/49S79-00451/49S7900451 (ruột) | G13: Tâm lỗ bu lông 44 x 86 | H13: E200B/E120B | J13: TBS | N13: =IF(M13="","",M13*1.1) | V13: =UPPER(A13&" "&B13&" "&D13&" "&E13&" "&F13&" "&G13&" "&H13&" "&I13&" "&J13) | W13: =IF(AND('TRA CỨU TỔNG HỢP'!$B$3<>"",ISNUMBER(SEARCH('TRA CỨU TỔNG HỢP'!$B$3,V13))),MAX($W$3:W12)+1,"")
A14: └─ CAT | B14: HH075110 | C14: Mitsubishi | D14: TD06H-14C | E14: S6KT/S4KT | F14: 49179-00451/49179-00451 | 49179-00450 | 4917900451 | 4917900450 | 5I-5015 | 5I5015 8M06-100-056/49179-00450 5I501549179-09830/49179-00451/4917900451/317013/49179-00450/4917900450/49S79-00451/49S7900451 (ruột) | G14: Tâm lỗ bu lông 44 x 86 | H14: E200B/E120B | J14: JRONE | N14: =IF(M14="","",M14*1.1) | V14: =UPPER(A14&" "&B14&" "&D14&" "&E14&" "&F14&" "&G14&" "&H14&" "&I14&" "&J14) | W14: =IF(AND('TRA CỨU TỔNG HỢP'!$B$3<>"",ISNUMBER(SEARCH('TRA CỨU TỔNG HỢP'!$B$3,V14))),MAX($W$3:W13)+1,"")
A15: └─ CAT | B15: HH079979 | C15: Mitsubishi | D15: TD06H-14C | E15: S6KT/S4KT | F15: 49179-00451/49179-00451 | 49179-00450 | 4917900451 | 4917900450 | 5I-5015 | 5I5015 8M06-100-056/49179-00450 5I501549179-09830/49179-00451/4917900451/317013/49179-00450/4917900450/49S79-00451/49S7900451 (ruột) | G15: Tâm lỗ bu lông 44 x 86 | H15: E200B/E120B | J15: SL | N15: =IF(M15="","",M15*1.1) | V15: =UPPER(A15&" "&B15&" "&D15&" "&E15&" "&F15&" "&G15&" "&H15&" "&I15&" "&J15) | W15: =IF(AND('TRA CỨU TỔNG HỢP'!$B$3<>"",ISNUMBER(SEARCH('TRA CỨU TỔNG HỢP'!$B$3,V15))),MAX($W$3:W14)+1,"")
A16: CAT | B16: HH075397 | C16: BorgWarner | D16: S410G | E16: CAT 3406/ C15 | F16: 177148 169227 704604-0007/466445-0018 471142-0005/471142-0003 466445-0015/466445-0021 170354 137-4832/OR7152 167-9271/196-5951 OR6989/124-3035 141-8939/146-4328/136-6390 8S04-200-B71 | J16: JRONE | N16: =IF(M16="","",M16*1.1) | O16: 105.4 | P16: 74.6 | Q16: 7/7 | R16: 91.5 | S16: 81.7 | T16: 10 | V16: =UPPER(A16&" "&B16&" "&D16&" "&E16&" "&F16&" "&G16&" "&H16&" "&I16&" "&J16) | W16: =IF(AND('TRA CỨU TỔNG HỢP'!$B$3<>"",ISNUMBER(SEARCH('TRA CỨU TỔNG HỢP'!$B$3,V16))),MAX($W$3:W15)+1,"")
A17: CAT | C17: Mitsubishi | D17: TF035 | E17: 4M40-T | F17: 49135-03320 49135-03301 03300/8M35-200-J12 | G17: Có điều tốc(Chân tam giác) | H17: CAT mini excavator | V17: =UPPER(A17&" "&B17&" "&D17&" "&E17&" "&F17&" "&G17&" "&H17&" "&I17&" "&J17) | W17: =IF(AND('TRA CỨU TỔNG HỢP'!$B$3<>"",ISNUMBER(SEARCH('TRA CỨU TỔNG HỢP'!$B$3,V17))),MAX($W$3:W16)+1,"")
A18: CAT | B18: HH080116 | C18: IHI | D18: RHF4 | E18: VT10 | F18: VA420088 1515A029/1515A030/VT11 VA420101/VB420088 VB420101/VC420088 VC420101/F41CAT-S0088B F41CAT-S0088G/VF420088 VG420088A1/49179-08540 | H18: L200 2.5D | J18: SL | N18: =IF(M18="","",M18*1.1) | O18: 50 | P18: 37.4 | Q18: 5/5 | R18: 45.2 | S18: 36.6 | T18: 9 | V18: =UPPER(A18&" "&B18&" "&D18&" "&E18&" "&F18&" "&G18&" "&H18&" "&I18&" "&J18) | W18: =IF(AND('TRA CỨU TỔNG HỢP'!$B$3<>"",ISNUMBER(SEARCH('TRA CỨU TỔNG HỢP'!$B$3,V18))),MAX($W$3:W17)+1,"")
A19: └─ CAT | B19: HH080117 | C19: IHI | D19: RHF4 | E19: VT10 | F19: VA420088 1515A029/1515A030/VT11 VA420101/VB420088 VB420101/VC420088 VC420101/F41CAT-S0088B F41CAT-S0088G/VF420088 VG420088A1/49179-08540 | H19: L200 2.5D | J19: SL | N19: =IF(M19="","",M19*1.1) | O19: 50 | P19: 37.4 | Q19: 5/5 | R19: 45.2 | S19: 36.6 | T19: 9 | V19: =UPPER(A19&" "&B19&" "&D19&" "&E19&" "&F19&" "&G19&" "&H19&" "&I19&" "&J19) | W19: =IF(AND('TRA CỨU TỔNG HỢP'!$B$3<>"",ISNUMBER(SEARCH('TRA CỨU TỔNG HỢP'!$B$3,V19))),MAX($W$3:W18)+1,"")
